Workbook
Name kr: #REF!

Sheet keşif
A1: F VE G BLOK MEKANİK VE ELEKTRİK İŞLERİ TEKLİF TABLOSU
B2: G BLOK TUTARI | D2: F BLOK TUTARI | F2: TOPLAM TUTAR | H2: GENEL TOPLAM
B3: MALZEME | C3: İŞÇİLİK | D3: MALZEME | E3: İŞÇİLİK | F3: MALZEME | G3: İŞÇİLİK
A4: MEKANİK TESİSATI İŞLERİ | B4: ='mekanik G BLOK'!H3 -> 0 | C4: ='mekanik G BLOK'!I3 -> 0 | D4: ='mekanik F BLOK'!H3 -> 0 | E4: ='mekanik F BLOK'!I3 -> 0 | F4: =B4+D4 -> 0 | G4: =E4+C4 -> 0 | H4: =SUM(F4:G4) -> 0
A5: ELEKTRİK TESİSATI İŞLERİ | B5: ='elektrik G BLOK'!H3 -> 0 | C5: ='elektrik G BLOK'!I3 -> 0 | D5: ='elektrik F BLOK'!H3 -> 0 | E5: ='elektrik F BLOK'!I3 -> 0 | F5: =B5+D5 -> 0 | G5: =E5+C5 -> 0 | H5: =SUM(F5:G5) -> 0
F6: =SUM(F4:F5) -> 0 | G6: =SUM(G4:G5) -> 0 | H6: =SUM(H4:H5) -> 0

Sheet mekanik G BLOK
B1: G BLOK MEKANİK KEŞİF
A2: Sıra No | B2: İşin Tanımı | C2: Açıklama/Marka | D2: Birim | E2: Miktar | F2: Malzeme Birim Fiyat | G2: İşçilik Birim Fiyat | H2: Malzeme Tutar | I2: İşçilik Tutar | J2: Toplam Tutar
H3: =H4+H110+H154+H173 -> 0 | I3: =I4+I110+I154+I173 -> 0 | J3: =J4+J110+J154+J173 -> 0
A4: 1 | B4: SIHHI TESİSAT İŞLERİ | H4: =SUM(H5:H109) -> 0 | I4: =SUM(I5:I109) -> 0 | J4: =SUM(J5:J109) -> 0
B5: TEMİZ SU HİDROFORU
B6: 2x9,36 m³/h | C6: MASDAF-ETNA VEYA MUADİLİ | D6: adet | E6: 1
B7: TEMİZ SU BORULARI
B8: DN 20 | C8: HAKAN VEYA MUADİLİ | D8: metre | E8: 313
B9: DN 25 | C9: HAKAN VEYA MUADİLİ | D9: metre | E9: 380
B10: DN 32 | C10: HAKAN VEYA MUADİLİ | D10: metre | E10: 150
B11: DN 40 | C11: HAKAN VEYA MUADİLİ | D11: metre | E11: 110
B12: DN 50 | C12: HAKAN VEYA MUADİLİ | D12: metre | E12: 16
B13: DN 63 | C13: HAKAN VEYA MUADİLİ | D13: metre | E13: 33
B14: FİTTİNGS ORANI | C14: HAKAN VEYA MUADİLİ | E14: 0.5
B15: 9MM ALUMİNYUM FOLYO KAUÇUK BORU İZOLASYONU
B16: DN 20 | C16: ODE VEYA MUADİLİ | D16: metre | E16: 313
B17: DN 25 | C17: ODE VEYA MUADİLİ | D17: metre | E17: 380
B18: DN 32 | C18: ODE VEYA MUADİLİ | D18: metre | E18: 150
B19: DN 40 | C19: ODE VEYA MUADİLİ | D19: metre | E19: 110
B20: DN 50 | C20: ODE VEYA MUADİLİ | D20: metre | E20: 16
B21: DN 63 | C21: ODE VEYA MUADİLİ | D21: metre | E21: 33
B22: VİTİRİFİYE MALZEMELERİ
B23: KLOZET | D23: adet | E23: 27
B24: LAVABO | D24: adet | E24: 27
B25: LAVABO BATARYASI | D25: adet | E25: 49
B26: DUŞ BATARYASI | D26: adet | E26: 22
B27: HAVLULUK | D27: adet | E27: 27
B28: TUVALET KAĞITLIK | D28: adet | E28: 27
B29: SABUNLUK | D29: adet | E29: 27
B30: 500 W ELEKTRİKLİ BANYO RADYATÖRÜ | D30: adet | E30: 22
B31: MUSLUKLAR
B32: KROM ARA MUSLUK | C32: ECA VEYA MUADİLİ | D32: adet | E32: 27
B33: ÇAMAŞIR-BULAŞIK MAKİNESİ MUSLUĞU | C33: ECA VEYA MUADİLİ | D33: adet | E33: 22
B34: PRİNÇ KÜRESEL VANA
B35: DN 15 | C35: DUYAR VEYA MUADİLİ | D35: adet | E35: 142
B36: PP KÜRESEL VANALAR
B37: DN 20 | C37: DUYAR VEYA MUADİLİ | D37: adet | E37: 108
B38: DN 25 | C38: DUYAR VEYA MUADİLİ | D38: adet | E38: 54
B39: DN 32 | C39: DUYAR VEYA MUADİLİ | D39: adet | E39: 27
B40: DN 40 | C40: DUYAR VEYA MUADİLİ | D40: adet | E40: 3
...

Sheet mekanik F BLOK
B1: F BLOK MEKANİK KEŞİF
A2: Sıra No | B2: İşin Tanımı | C2: Açıklama/Marka | D2: Birim | E2: Miktar | F2: Malzeme Birim Fiyat | G2: İşçilik Birim Fiyat | H2: Malzeme Tutar | I2: İşçilik Tutar | J2: Toplam Tutar
H3: =H4+H122+H186+H205 -> 0 | I3: =I4+I122+I186+I205 -> 0 | J3: =J4+J122+J186+J205 -> 0
A4: 1 | B4: SIHHI TESİSAT İŞLERİ | H4: =SUM(H6:H121) -> 0 | I4: =SUM(I6:I121) -> 0 | J4: =SUM(J6:J121) -> 0
B5: TEMİZ SU HİDROFORU
B6: 2x12,6 m³/h | C6: MASDAF-ETNA VEYA MUADİLİ | D6: adet | E6: 1
B7: TEMİZ SU BORULARI
B8: DN 20 | C8: HAKAN VEYA MUADİLİ | D8: metre | E8: 496
B9: DN 25 | C9: HAKAN VEYA MUADİLİ | D9: metre | E9: 374
B10: DN 32 | C10: HAKAN VEYA MUADİLİ | D10: metre | E10: 251
B11: DN 40 | C11: HAKAN VEYA MUADİLİ | D11: metre | E11: 162
B12: DN 50 | C12: HAKAN VEYA MUADİLİ | D12: metre | E12: 126
B13: DN 63 | C13: HAKAN VEYA MUADİLİ | D13: metre | E13: 56
B14: DN 75 | C14: HAKAN VEYA MUADİLİ | D14: metre | E14: 29
B15: FİTTİNGS ORANI | C15: HAKAN VEYA MUADİLİ | E15: 0.5
B16: 9MM ALUMİNYUM FOLYO KAUÇUK BORU İZOLASYONU
B17: DN 20 | C17: ODE VEYA MUADİLİ | D17: metre | E17: 496
B18: DN 25 | C18: ODE VEYA MUADİLİ | D18: metre | E18: 374
B19: DN 32 | C19: ODE VEYA MUADİLİ | D19: metre | E19: 251
B20: DN 40 | C20: ODE VEYA MUADİLİ | D20: metre | E20: 162
B21: DN 50 | C21: ODE VEYA MUADİLİ | D21: metre | E21: 126
B22: DN 63 | C22: ODE VEYA MUADİLİ | D22: metre | E22: 56
B23: DN 75 | C23: ODE VEYA MUADİLİ | D23: metre | E23: 29
B24: VİTİRİFİYE MALZEMELERİ
B25: KLOZET | D25: adet | E25: 43
B26: PİSUAR | D26: adet | E26: 1
B27: LAVABO | D27: adet | E27: 43
B28: LAVABO BATARYASI | D28: adet | E28: 70
B29: DUŞ BATARYASI | D29: adet | E29: 36
B30: HAVLULUK | D30: adet | E30: 43
B31: TUVALET KAĞITLIK | D31: adet | E31: 43
B32: SABUNLUK | D32: adet | E32: 43
B33: 500 W ELEKTRİKLİ BANYO RADYATÖRÜ | D33: adet | E33: 29
B34: 700 W ELEKTRİKLİ BANYO RADYATÖRÜ | D34: adet | E34: 4
B35: MUSLUKLAR
B36: KROM ARA MUSLUK | C36: ECA VEYA MUADİLİ | D36: adet | E36: 43
B37: ÇAMAŞIR-BULAŞIK MAKİNESİ MUSLUĞU | C37: ECA VEYA MUADİLİ | D37: adet | E37: 25
B38: PRİNÇ KÜRESEL VANA
B39: DN 15 | C39: DUYAR VEYA MUADİLİ | D39: adet | E39: 174
B40: PP KÜRESEL VANALAR
...

Sheet elektrik G BLOK
B1: G BLOK ELEKTRİK KEŞİF
A2: Sıra No | B2: İşin Tanımı | C2: Açıklama/Marka | D2: Birim | E2: Miktar | F2: Malzeme Birim Fiyat | G2: İşçilik Birim Fiyat | H2: Malzeme Tutar | I2: İşçilik Tutar | J2: Toplam Tutar
H3: =H4+H8+H16+H28+H37+H47+H52+H62+H64+H71+H79+H84+H97 -> 0 | I3: =I4+I8+I16+I28+I37+I47+I52+I62+I64+I71+I79+I84+I97 -> 0 | J3: =J4+J8+J16+J28+J37+J47+J52+J62+J64+J71+J79+J84+J97 -> 0
A4: 1 | B4: PANOLAR | H4: =SUM(H5:H7) -> 0 | I4: =SUM(I5:I7) -> 0 | J4: =SUM(J5:J7) -> 0
B5: GMRO_G | C5: EAE-SCHNEİDER VEYA MUADİLİ | D5: set | E5: 1
B6: RO_ZP_G | C6: EAE-SCHNEİDER VEYA MUADİLİ | D6: set | E6: 1
B7: RT-A | C7: EAE-SCHNEİDER VEYA MUADİLİ | D7: set | E7: 22
A8: 2 | B8: KUVVETLİ AKIM KABLOLARI | H8: =SUM(H9:H15) -> 0 | I8: =SUM(I9:I15) -> 0 | J8: =SUM(J9:J15) -> 0
B9: 3x1,5 NHXMH | C9: GÖLDAĞ VEYA MUADİLİ | D9: metre | E9: 5200
B10: 3x2,5 NHXMH | C10: GÖLDAĞ VEYA MUADİLİ | D10: metre | E10: 7100
B11: 5x2,5 NHXMH | C11: GÖLDAĞ VEYA MUADİLİ | D11: metre | E11: 220
B12: 5x6 N2XH | C12: GÖLDAĞ VEYA MUADİLİ | D12: metre | E12: 210
B13: 5x10 N2XH | C13: GÖLDAĞ VEYA MUADİLİ | D13: metre | E13: 680
B14: 5x95 N2XH | C14: GÖLDAĞ VEYA MUADİLİ | D14: metre | E14: 10
B15: 1x240 NYAF | C15: GÖLDAĞ VEYA MUADİLİ | D15: metre | E15: 10
A16: 3 | B16: AYDINLATMA ARMATÜRLERİ | H16: =SUM(H17:H27) -> 0 | I16: =SUM(I17:I27) -> 0 | J16: =SUM(J17:J27) -> 0
B17: 11 W SIVA ALTI LED SPOT | C17: EAE VEYA MUADİLİ | D17: adet | E17: 414
B18: 10 W SIVA ALTI LED SPOT | C18: EAE VEYA MUADİLİ | D18: adet | E18: 200
B19: 10 W SIVA ALTI LED SPOT KİTLİ | C19: EAE VEYA MUADİLİ | D19: adet | E19: 14
B20: 8,8 W TAVAN APLİK | C20: EAE VEYA MUADİLİ | D20: adet | E20: 17
B21: 8,8 W DUVAR APLİK | C21: EAE VEYA MUADİLİ | D21: adet | E21: 5
B22: 16 W SIVA ÜSTÜ SENSÖRLÜ LED ARMATÜR | C22: EAE VEYA MUADİLİ | D22: adet | E22: 9
B23: 16 W SIVA ÜSTÜ SENSÖRLÜ LED ARMATÜR KİTLİ | C23: EAE VEYA MUADİLİ | D23: adet | E23: 9
B24: 28 W ETANJ LED ARMATÜR | C24: EAE VEYA MUADİLİ | D24: adet | E24: 13
B25: 28 W ETANJ LED ARMATÜR KİTLİ | C25: EAE VEYA MUADİLİ | D25: adet | E25: 3
B26: ACİL YÖNLENDİRME ARMATÜRÜ | C26: EAE VEYA MUADİLİ | D26: adet | E26: 14
B27: KOMODİN ÜSTÜ DUVAR APLİK | D27: adet | E27: 44
A28: 4 | B28: ANAHTAR PRİZ | H28: =SUM(H29:H36) -> 0 | I28: =SUM(I29:I36) -> 0 | J28: =SUM(J29:J36) -> 0
B29: 2M MODÜLER KASA-KASKAT-ÇERÇEVE | C29: PANASONİC VEYA MUADİLİ | D29: adet | E29: 154
B30: 3M MODÜLER KASA-KASKAT-ÇERÇEVE | C30: PANASONİC VEYA MUADİLİ | D30: adet | E30: 66
B31: 4M MODÜLER KASA-KASKAT-ÇERÇEVE | C31: PANASONİC VEYA MUADİLİ | D31: adet | E31: 198
B32: 2M TOPRAKLI PRİZ | C32: PANASONİC VEYA MUADİLİ | D32: adet | E32: 440
B33: 2M KAPAKLI TOPRAKLI PRİZ | C33: PANASONİC VEYA MUADİLİ | D33: adet | E33: 88
B34: 5x16 A MAKİNE PRİZİ | C34: BEMİS VEYA MUADİLİ | D34: adet | E34: 22
B35: SIVA ALTI KAPAKLI PRİZ | C35: PANASONİC VEYA MUADİLİ | D35: adet | E35: 16
B36: SIVA ALTI TEKLİ ANAHTAR | C36: PANASONİC VEYA MUADİLİ | D36: adet | E36: 16
A37: 5 | B37: OTOMASYON | H37: =SUM(H38:H46) -> 0 | I37: =SUM(I38:I46) -> 0 | J37: =SUM(J38:J46) -> 0
B38: 2M 1 GANG OTOMASYON ANAHTARI | C38: EAE VEYA MUADİLİ | D38: adet | E38: 28
B39: 2M 2 GANG OTOMASYON ANAHTARI | C39: EAE VEYA MUADİLİ | D39: adet | E39: 50
B40: 2M 4 GANG OTOMASYON ANAHTARI | C40: EAE VEYA MUADİLİ | D40: adet | E40: 126
...

Sheet elektrik F BLOK
B1: F BLOK ELEKTRİK KEŞİF
A2: Sıra No | B2: İşin Tanımı | C2: Açıklama/Marka | D2: Birim | E2: Miktar | F2: Malzeme Birim Fiyat | G2: İşçilik Birim Fiyat | H2: Malzeme Tutar | I2: İşçilik Tutar | J2: Toplam Tutar
H3: =H4+H15+H25+H41+H51+H61+H66+H77+H80+H91+H99+H104+H122 -> 0 | I3: =I4+I15+I25+I41+I51+I61+I66+I77+I80+I91+I99+I104+I122 -> 0 | J3: =J4+J15+J25+J41+J51+J61+J66+J77+J80+J91+J99+J104+J122 -> 0
A4: 1 | B4: PANOLAR | H4: =SUM(H5:H14) -> 0 | I4: =SUM(I5:I14) -> 0 | J4: =SUM(J5:J14) -> 0
B5: GMRO_F | C5: EAE-SCHNEİDER VEYA MUADİLİ | D5: set | E5: 1
B6: RO_ZP_F | C6: EAE-SCHNEİDER VEYA MUADİLİ | D6: set | E6: 1
B7: RO_G | C7: EAE-SCHNEİDER VEYA MUADİLİ | D7: set | E7: 1
B8: RT_A1 | C8: EAE-SCHNEİDER VEYA MUADİLİ | D8: set | E8: 1
B9: RT_A2 | C9: EAE-SCHNEİDER VEYA MUADİLİ | D9: set | E9: 5
B10: RT_A3 | C10: EAE-SCHNEİDER VEYA MUADİLİ | D10: set | E10: 6
B11: RT_A4 | C11: EAE-SCHNEİDER VEYA MUADİLİ | D11: set | E11: 5
B12: RT_A5 | C12: EAE-SCHNEİDER VEYA MUADİLİ | D12: set | E12: 2
B13: RT_A6 | C13: EAE-SCHNEİDER VEYA MUADİLİ | D13: set | E13: 1
B14: RT_A7 | C14: EAE-SCHNEİDER VEYA MUADİLİ | D14: set | E14: 1
A15: 2 | B15: KUVVETLİ AKIM KABLOLARI
B16: 3x1,5 NHXMH | C16: GÖLDAĞ VEYA MUADİLİ | D16: metre | E16: 7800
B17: 3x2,5 NHXMH | C17: GÖLDAĞ VEYA MUADİLİ | D17: metre | E17: 10650
B18: 5x2,5 NHXMH | C18: GÖLDAĞ VEYA MUADİLİ | D18: metre | E18: 260
B19: 5x6 N2XH | C19: GÖLDAĞ VEYA MUADİLİ | D19: metre | E19: 280
B20: 5x10 N2XH | C20: GÖLDAĞ VEYA MUADİLİ | D20: metre | E20: 760
B21: 5x95 N2XH | C21: GÖLDAĞ VEYA MUADİLİ | D21: metre | E21: 10
B22: 4x2,5 N2XH FE180/E90 | C22: GÖLDAĞ VEYA MUADİLİ | D22: metre | E22: 500
B23: 5x10 N2XH FE180/E90 | C23: GÖLDAĞ VEYA MUADİLİ | D23: metre | E23: 200
B24: 1x240 NYAF | C24: GÖLDAĞ VEYA MUADİLİ | D24: metre | E24: 10
A25: 3 | B25: AYDINLATMA ARMATÜRLERİ
B26: 11 W SIVA ALTI LED SPOT | C26: EAE VEYA MUADİLİ | D26: adet | E26: 628
B27: 10 W SIVA ALTI LED SPOT | C27: EAE VEYA MUADİLİ | D27: adet | E27: 319
B28: 10 W SIVA ALTI LED SPOT KİTLİ | C28: EAE VEYA MUADİLİ | D28: adet | E28: 24
B29: 15 W SIVA ALTI LED SPOT | C29: EAE VEYA MUADİLİ | D29: adet | E29: 16
B30: 15 W SIVA ALTI LED SPOT KİTLİ | C30: EAE VEYA MUADİLİ | D30: adet | E30: 4
B31: 8,8 W TAVAN APLİK | C31: EAE VEYA MUADİLİ | D31: adet | E31: 35
B32: 8,8 W DUVAR APLİK | C32: EAE VEYA MUADİLİ | D32: adet | E32: 29
B33: 16 W SIVA ÜSTÜ SENSÖRLÜ LED ARMATÜR | C33: EAE VEYA MUADİLİ | D33: adet | E33: 20
B34: 16 W SIVA ÜSTÜ SENSÖRLÜ LED ARMATÜR KİTLİ | C34: EAE VEYA MUADİLİ | D34: adet | E34: 9
B35: 28 W ETANJ LED ARMATÜR | C35: EAE VEYA MUADİLİ | D35: adet | E35: 28
B36: 28 W ETANJ LED ARMATÜR KİTLİ | C36: EAE VEYA MUADİLİ | D36: adet | E36: 10
B37: 10,1 W DUVAR ARMATÜR | C37: EAE VEYA MUADİLİ | D37: adet | E37: 18
... B39: 360 DERECE HAREKET DEDEKTÖRÜ | C39: EAE VEYA MUADİLİ | D39: adet | E39: 5
B40: KOMODİN ÜSTÜ DUVAR APLİK | D40: adet | E40: 59
A41: 4 | B41: ANAHTAR PRİZ
...
