Workbook

Sheet İCMAL
B2: 45999 | D2: FİRMA BİLGİLERİ, ADRES, İLGİLİ KİŞİ ,TELEFON , EMAİL BİLGİLERİ GİRİLECEK... TEKLİF EKİ OLARAK AŞAĞIDAKİ BELGELER TEMİN EDİLECEK: -Ticaret Odası Faaliyet Belgesi (6 aydan eski tarihli olmayacak) - Ticari Sicil Gazetesi - İmza Sirküleri - Güncel Vergi Levhası Fotokopisi - SGK ve Vergi Dairesi borç durumu yazıları (güncel tarihli)
B3: FIRMA-I BURSA SAHA-BIR OSB FABRİKA BİNASI İnşaat İşleri
B4: NO | C4: AÇIKLAMA | D4: MALZEME TUTAR | F4: İŞÇİLİK TUTAR | H4: TOPLAM TUTAR
B5: 1 | C5: İNŞAAAT İŞLERİ (BİNA) | D5: {=+'İnşai işler BİNA'!L221:M221} -> 0 | E5: 0 | F5: {=+'İnşai işler BİNA'!L222:M222} -> 0 | G5: 0 | H5: =+D5+F5 -> 0
B6: 2 | C6: İNŞAAT İŞLERİ (SAHA&PEYZAJ) | D6: {=+'İnşai işler SAHA'!L61:M61} -> 0 | E6: 0 | F6: {=+'İnşai işler SAHA'!L62:M62} -> 0 | G6: 0 | H6: =+D6+F6 -> 0
B7: 3 | C7: MEKANİK İŞLER | D7: =+Mekanik!L654 -> 48228317 | F7: =+Mekanik!L655 -> 13460588 | H7: =+D7+F7 -> 61688905
B8: 4 | C8: ELEKTRİK İŞLERİ | D8: =+Elektrik!AT712 -> 0 | F8: =+Elektrik!AT713 -> 0 | H8: =+D8+F8 -> 0
B9: 5 | C9: ENERJİ TEMİNİ VE ORTA GERİLİM İŞLERİ | D9: {=+'Enerji temini'!L7:M7} -> 0 | E9: 0 | F9: {=+'Enerji temini'!L8:M8} -> 0 | G9: 0 | H9: =+D9+F9 -> 0
B10: 6 | C10: ASANSÖR | D10: =+Asansör!L6 -> 0 | F10: =+Asansör!L7 -> 0 | H10: =+D10+F10 -> 0
D11: =+D5+D6+D7+D8+D9+D10 -> 48228317 | E11: =+E5+E6+E7+E8 -> 0 | F11: =+F5+F6+F7+F8+F9+F10 -> 13460588 | G11: =+G5+G6+G7+G8 -> 0 | H11: =+H5+H6+H7+H8+H9+H10 -> 61688905
B13: - Aylık hakedişlere istinaden düzenlenecek fatura bedeli, fatura tarihinden itibaren 45/60 gün içerisinde hesaba EFT/HAVALE olarak yapılır. - Taep edilecek avans tutarı karşılığı, geçici kabulde iade etmek üzere, işverenin formatına uygun banka teminat mektubu alınır. - Kesin kabulden 1 sene sonra iade etmek üzere 10% kesin teminat alınır. - İş birim fiyat usulüdür.
B14: TEKLİF VEREN FİRMA KAŞE İMZA

Sheet İnşai işler BİNA
A1: ANA BİNA İNŞAİ İŞLER | F1: KEŞİF | H1: MALZEME | J1: İŞÇİLİK | L1: Satış Br. Fiyat | M1: Satış Tutar
A2: Şartname No | B2: Poz No | C2: İmalatlar | F2: Birim | G2: Metraj | H2: Malzeme Br. Fiyat | I2: Malzeme Tutar | J2: İşçilik Br. Fiyat | K2: İşçilik Tutar
B3: 1 | C3: TOPRAK İŞLERİ | I3: =SUM(I4:I5) -> 0 | K3: =SUM(K4:K5) -> 0 | M3: =SUM(M4:M5) -> 0
B4: 1.1 | C4: KAZI İŞLERİ 134.20 (0.00) kotu ile projede gösterilen (temel altı katmanlaşmalar dikkate alınarak) hafriyat alt kotları arasında bina kazısı yapılması ve saha dışına dökümü (geoteknik rapordaki şev tanımlarına uygun olarak şevlerin yapılması, projede gösterilen asansör-pis su vb çukurların açılması ) | F4: m3 | G4: 8735 | I4: =+H4*G4 -> 0 | K4: =+J4*G4 -> 0 | L4: =+H4+J4 -> 0 | M4: =L4*G4 -> 0
B5: 1.2 | C5: DOLGU İŞLERİ Geoteknik raporunda belirtildiği gibi Temel altına 30 cm yüksekliğinde sıkıştırılmış seçme granüler malzeme (kum-çakıl) ile capping şilte tabakası oluşturulması (GW-SW tipi malzeme kullanılacaktır, granüler tabaka içinde kil+silt oranının %5 ile sınırlandırılması gerekecektir.Max. dane boyutu 10 cm geçmemelidir) | F5: m3 | G5: 939.6 | I5: =+H5*G5 -> 0 | K5: =+J5*G5 -> 0 | L5: =+H5+J5 -> 0 | M5: =L5*G5 -> 0
A6: 03 31 00 | B6: 2 | C6: BETONARME STRÜKTÜR İŞLERİ | I6: =SUM(I7:I13) -> 0 | K6: =SUM(K7:K13) -> 0 | M6: =SUM(M7:M13) -> 0
B7: 2.1 | C7: Düz yüzeyli beton ve betonarme kalıbı yapılması (Temel ve bağ kirişleri dolgu altında kalan imalatlar) | F7: m² | G7: 1723.57 | I7: =+H7*G7 -> 0 | K7: =+J7*G7 -> 0 | L7: =+H7+J7 -> 0 | M7: =L7*G7 -> 0
B8: 2.2 | C8: Düz yüzeyli kontrplaktan (plywood) beton ve betonarme kalıbı yapılması (kiriş, kolon, döşeme, perde vb görünen yüzeyler) | F8: m² | G8: 9681.78 | I8: =+H8*G8 -> 0 | K8: =+J8*G8 -> 0 | L8: =+H8+J8 -> 0 | M8: =L8*G8 -> 0
B9: 2.3 | C9: C 20 Betonu (Grobeton-koruma betonu) demirsiz | F9: m3 | G9: 1260.17 | I9: =+H9*G9 -> 0 | K9: =+J9*G9 -> 0 | L9: =+H9+J9 -> 0 | M9: =L9*G9 -> 0
B10: 2.4 | C10: C 35 Betonarme Betonu (Temel, bağ kirişi, kaide ve sokl) | F10: m3 | G10: 3202.17 | I10: =+H10*G10 -> 0 | K10: =+J10*G10 -> 0 | L10: =+H10+J10 -> 0 | M10: =L10*G10 -> 0
B11: 2.5 | C11: C 35 Üst yapı betonarme betonu (Temel, bağ kirişi, kaide ve sokl) | F11: m3 | G11: 1920.1 | I11: =+H11*G11 -> 0 | K11: =+J11*G11 -> 0 | L11: =+H11+J11 -> 0 | M11: =L11*G11 -> 0
B12: 2.6 | C12: Nervürlü Ø8 ve Ø12 çaplı (ince) tor çeliğin betonarme projesine göre bükülmesi ve yerine konması | F12: Kg | G12: 137597.12 | I12: =+H12*G12 -> 0 | K12: =+J12*G12 -> 0 | L12: =+H12+J12 -> 0 | M12: =L12*G12 -> 0
B13: 2.7 | C13: Nervürlü Ø14 ve Ø26 çaplı (kalın) tor çeliğin betonarme projesine göre bükülmesi ve yerine konması | F13: Kg | G13: 462152.52 | I13: =+H13*G13 -> 0 | K13: =+J13*G13 -> 0 | L13: =+H13+J13 -> 0 | M13: =L13*G13 -> 0
A14: 05 12 00 | B14: 3 | C14: ÇELİK İMALAT VE MONTAJ İŞLERİ | I14: =SUM(I15:I19) -> 0 | K14: =SUM(K15:K19) -> 0 | M14: =SUM(M15:M19) -> 0
B15: 3.1 | C15: S235 kalite yapı çeliğinden kiriş, kolon, aşık vb yapılması (bağlantı elemanları dahil) | F15: Kg | G15: 62199.77 | I15: =+H15*G15 -> 0 | K15: =+J15*G15 -> 0 | L15: =+H15+J15 -> 0 | M15: =L15*G15 -> 0
B16: 3.2 | C16: S275 kalite yapı çeliğinden kiriş, kolon, aşık vb yapılması (bağlantı elemanları dahil) | F16: Kg | G16: 13158.92 | I16: =+H16*G16 -> 0 | K16: =+J16*G16 -> 0 | L16: =+H16+J16 -> 0 | M16: =L16*G16 -> 0
B17: 3.3 | C17: S235 kalite sacdan kiriş - kolon ve her türlü birleşim plakası yapılması | F17: Kg | G17: 29933.05 | I17: =+H17*G17 -> 0 | K17: =+J17*G17 -> 0 | L17: =+H17+J17 -> 0 | M17: =L17*G17 -> 0
B18: 3.4 | C18: Çelik imalatın kumlanarak 2 kat antipas 2 kat yağlı boya ile boyanması | F18: m² | G18: 2367.56 | I18: =+H18*G18 -> 0 | K18: =+J18*G18 -> 0 | L18: =+H18+J18 -> 0 | M18: =L18*G18 -> 0
B19: 3.5 | C19: 5.6 Yapı çeliğinden ankraj bulonu yapılması (cıvata somun vb.dahil) | F19: ad | G19: 50 | I19: =+H19*G19 -> 0 | K19: =+J19*G19 -> 0 | L19: =+H19+J19 -> 0 | M19: =L19*G19 -> 0
A20: 07 52 16 07 21 13.3 | B20: 4 | C20: MUHTELİF ISI VE SU YALITIMI İŞLERİ | I20: =+I21+I29+I35 -> 0 | K20: =+K21+K29+K35 -> 0 | M20: =+M21+M29+M35 -> 0
B21: 4.1 | C21: Temel altı altı yalıtımları | I21: =SUM(I22:I28) -> 0 | K21: =SUM(K22:K28) -> 0 | M21: =SUM(M22:M28) -> 0
B22: 4.1.1 | C22: 200 μ polyetilen örtü ile rutubete karşı veya ayırıcı tabaka yapılması (temel altında) | F22: m² | G22: 3046 | I22: =+H22*G22 -> 0 | K22: =+J22*G22 -> 0 | L22: =+H22+J22 -> 0 | M22: =L22*G22 -> 0
C23: Grobeton (10 cm) (Metraji Betonarme işlerde verilmiştir) | F23: m3 | G23: 0 | I23: =+H23*G23 -> 0 | K23: =+J23*G23 -> 0 | L23: =+H23+J23 -> 0 | M23: =L23*G23 -> 0
B24: 4.1.2 | C24: Bitüm esaslı astar | F24: m² | G24: 4069 | I24: =+H24*G24 -> 0 | K24: =+J24*G24 -> 0 | L24: =+H24+J24 -> 0 | M24: =L24*G24 -> 0
B25: 4.1.3 | C25: 2 kat 3mm kalınlıkta Polyester donatılı esnek SBS bitümlü su yalıtım membranı ile su yalıtımı yapılması | F25: m² | G25: 4069 | I25: =+H25*G25 -> 0 | K25: =+J25*G25 -> 0 | L25: =+H25+J25 -> 0 | M25: =L25*G25 -> 0
B26: 4.1.4 | C26: 50 mm kalınlıkta, minimum yoğunluğu 30 kg/m³, minimum 500kPa basma mukavemetine sahip XPS levhalar | F26: m² | G26: 4069 | I26: =+H26*G26 -> 0 | K26: =+J26*G26 -> 0 | L26: =+H26+J26 -> 0 | M26: =L26*G26 -> 0
B27: 4.1.5 | C27: Ayırıcı filtre tabakası (Geotekstil keçe 500gr/m²) serilmesi | F27: m² | G27: 4069 | I27: =+H27*G27 -> 0 | K27: =+J27*G27 -> 0 | L27: =+H27+J27 -> 0 | M27: =L27*G27 -> 0
C28: Koruma betonu (10 cm) (Metraji Betonarme işlerde verilmiştir) | F28: m3 | G28: 0 | I28: =+H28*G28 -> 0 | K28: =+J28*G28 -> 0 | L28: =+H28+J28 -> 0 | M28: =L28*G28 -> 0
B29: 4.2 | C29: Perde duvar yalıtımları - ısı ve su yalıtımı | I29: =SUM(I30:I34) -> 0 | K29: =SUM(K30:K34) -> 0 | M29: =SUM(M30:M34) -> 0
B30: 4.2.1 | C30: Bitüm esaslı astar | F30: m² | G30: 441.5 | I30: =+H30*G30 -> 0 | K30: =+J30*G30 -> 0 | L30: =+H30+J30 -> 0 | M30: =L30*G30 -> 0
B31: 4.2.2 | C31: 2 kat 3mm kalınlıkta Polyester donatılı esnek SBS bitümlü su yalıtım membranı ile su yalıtımı yapılması | F31: m² | G31: 441.5 | I31: =+H31*G31 -> 0 | K31: =+J31*G31 -> 0 | L31: =+H31+J31 -> 0 | M31: =L31*G31 -> 0
B32: 4.2.3 | C32: 50 mm kalınlıkta, minimum yoğunluğu 30 kg/m³, minimum 300kPa basma mukavemetine sahip XPS levhalar | F32: m² | G32: 441.5 | I32: =+H32*G32 -> 0 | K32: =+J32*G32 -> 0 | L32: =+H32+J32 -> 0 | M32: =L32*G32 -> 0
B33: 4.2.4 | C33: Drenaj sağlayıcı, koruyucu kabarcıklı levha (8 mm) (bodrum kat perde duvarlar ve temel düşey yüzeyler | F33: m² | G33: 621.5 | I33: =+H33*G33 -> 0 | K33: =+J33*G33 -> 0 | L33: =+H33+J33 -> 0 | M33: =L33*G33 -> 0
B34: 4.2.5 | C34: Çevre drenajı (Fransiz drenajı) için Q 200 Delikli boru (Projesine uygun geotkstil ve serbest drenaj malzemesi dahil) | F34: mt | G34: 340 | I34: =+H34*G34 -> 0 | K34: =+J34*G34 -> 0 | L34: =+H34+J34 -> 0 | M34: =L34*G34 -> 0
B35: 4.3 | C35: Sürme esaslı su yalıtımı yapılması | I35: =SUM(I36:I37) -> 0 | K35: =SUM(K36:K37) -> 0 | M35: =SUM(M36:M37) -> 0
A36: 07 16 13 | B36: 4.3.1 | C36: Çimento katkılı akrilik esaslı, çift komponentli su yalıtım malzemesi ile su yalıtımı yapılması (ıslak ve yarı-ıslak hacimler yalıtım 30 cm duvarlara dönecektir. Montaj Holündeki döşeme kanallarının döşeme ve duvarlarının yalıtıtımı) | F36: m² | G36: 488.73 | I36: =+H36*G36 -> 0 | K36: =+J36*G36 -> 0 | L36: =+H36+J36 -> 0 | M36: =L36*G36 -> 0
A37: 07 16 16 | B37: 4.3.2 | C37: Kristalize su yalıtımı yapılması (Su deposu-Pompa dairesi zemin, duvar ve tavanında) | F37: m² | G37: 711.54 | I37: =+H37*G37 -> 0 | K37: =+J37*G37 -> 0 | L37: =+H37+J37 -> 0 | M37: =L37*G37 -> 0
B38: 5 | C38: ÇATI VE CEPHE KAPLAMA İŞLERİ | I38: =+I39+I41+I43+I46+I50+I53+I55+I62 -> 0 | K38: =+K39+K41+K43+K46+K50+K53+K55+K62 -> 0 | M38: =+M39+M41+M43+M46+M50+M53+M55+M62 -> 0
A39: 07 42 43 | B39: 5.1 | C39: Taşyünü dolgulu sandviç panel cephe kaplaması (CK-01) | I39: =SUM(I40) -> 0 | K39: =SUM(K40) -> 0 | M39: =SUM(M40) -> 0
B40: 5.1.1 | C40: Proje ve detaylarına uygun Dış yüzü; 0,70 mm kalınlıkta, 100 mm dalga boyu ve 20 mm dip-tepe dalga yüksekliğine sahip sinüzoidal formda, 275 gr/m² galvanizli, 5 mikron astar üzeri 20 mikron son kat coil coating sistem ral 9006 Pvdf boyalı,sacın taşyünü gören yüzeyi 12 mikron çift kat astar kaplı, boyalı galvanizli DX51 kalite sac; üstünde 100 mm kalınlıkta 100 kg/m³ yoğunluğunda kesintisiz taşyünü; İc yüzü; 0,50 mm kalınlıkta, 100 gr/m² galvanizli, 5 mikron astar üzeri 20 mikron son kat coil coating sistem ral 9002 Polyester boyalı, sacın taşyünü gören yüzeyi 12 mikron çift kat astar kaplı, boyalı galvanizli DX51 kalite sac; 1000 mm faydalı eninde sandviç panel (TEKİZ SPD 1000 TİP 60 TAŞYÜNÜ YALITIMLI SİNÜS DESENLİ GİZLİ VİDALI CEPHE PANELİ veya muadili) ( Tüm ic köşe, dış köse, etek profili, damlalik profili, kapama profili vb. tüm aksesuarlar 1 mm olacak olup birim fiyata dahildir.) | F40: m² | G40: 1587 | I40: =+H40*G40 -> 0 | K40: =+J40*G40 -> 0 | L40: =+H40+J40 -> 0 | M40: =L40*G40 -> 0
...

Sheet İnşai işler SAHA
A1: SAHA İNŞAİ İŞLER | F1: KEŞİF | H1: MALZEME | J1: İŞÇİLİK | L1: Satış Br. Fiyat | M1: Satış Tutar
A2: Şartname No | B2: Poz No | C2: İmalatlar | F2: Birim | G2: Metraj | H2: Malzeme Br. Fiyat | I2: Malzeme Tutar | J2: İşçilik Br. Fiyat | K2: İşçilik Tutar
B3: 1 | C3: SERT PEYZAJ İŞLERİ | I3: =+I4+I8+I12+I17+I21 -> 0 | K3: =+K4+K8+K12+K17+K21 -> 0 | M3: =+M4+M8+M12+M17+M21 -> 0
B4: 1.1 | C4: Zemin Kaplamaları | I4: =SUM(I5:I7) -> 0 | K4: =SUM(K5:K7) -> 0 | M4: =SUM(M5:M7) -> 0
A5: 03 31 00 | B5: 1.1.1 | C5: P1-Yüzeyi taraklı beton kaplama yapılması (10cm tek kat hasır çelikli beton, bitiş kaplaması,derzli) | F5: m² | G5: 5986 | I5: =+H5*G5 -> 0 | K5: =+J5*G5 -> 0 | L5: =+H5+J5 -> 0 | M5: =L5*G5 -> 0
A6: 32 14 00 | B6: 1.1.2 | C6: P2-Bazalt plak taş kaplaması yapılması, 30x100x3cm, Kumlu/Fırçalı, yüzey kaymazlık işlemi ve 4cm harç dahil | F6: m² | G6: 605 | I6: =+H6*G6 -> 0 | K6: =+J6*G6 -> 0 | L6: =+H6+J6 -> 0 | M6: =L6*G6 -> 0
A7: 32 14 40 | B7: 1.1.3 | C7: P3-Bazalt merdiven basamak taşı ve rıht yapılması (basamak 33x100x3cm / rıht 17x100x2cm) Kumlu/Fırçalı, kenar pahlı, yüzey kaymazlık işlemi ve 4cm harç dahil | F7: mt | G7: 36 | I7: =+H7*G7 -> 0 | K7: =+J7*G7 -> 0 | L7: =+H7+J7 -> 0 | M7: =L7*G7 -> 0
B8: 1.2 | C8: Bordürler | I8: =SUM(I9:I11) -> 0 | K8: =SUM(K9:K11) -> 0 | M8: =SUM(M9:M11) -> 0
A9: 32 14 13 | B9: 1.2.1 | C9: B1-Beton bordür yapılması (10x20x50mm, Doğal Yüzey,Gri) | F9: mt | G9: 694 | I9: =+H9*G9 -> 0 | K9: =+J9*G9 -> 0 | L9: =+H9+J9 -> 0 | M9: =L9*G9 -> 0
A10: 32 14 13 | B10: 1.2.2 | C10: B2-Beton oluk taşı yapılması (en:20cmxboy:30cm,h:6cm Doğal Yüzey,Gri) | F10: mt | G10: 240 | I10: =+H10*G10 -> 0 | K10: =+J10*G10 -> 0 | L10: =+H10+J10 -> 0 | M10: =L10*G10 -> 0
A11: 32 14 13 | B11: 1.2.3 | C11: B3-Bazalt bordür yapılması (10x20x50mm, Doğal Yüzey,Gri) | F11: mt | G11: 275 | I11: =+H11*G11 -> 0 | K11: =+J11*G11 -> 0 | L11: =+H11+J11 -> 0 | M11: =L11*G11 -> 0
B12: 1.3 | C12: Sinyalizasyon | I12: =SUM(I13:I16) -> 0 | K12: =SUM(K13:K16) -> 0 | M12: =SUM(M13:M16) -> 0
A13: Sinyalizasyon İşleri | B13: 1.3.1 | C13: S1-Otopark çizgilerinin akrilik yol boyası ile 2mm kalınlığında 10cm genişliğinde projesine uygun olarak boyanması (engelli/şarjlı araç işaretlemesinin şablonlu boyanması dahil) | F13: mt | G13: 879 | I13: =+H13*G13 -> 0 | K13: =+J13*G13 -> 0 | L13: =+H13+J13 -> 0 | M13: =L13*G13 -> 0
A14: Sinyalizasyon İşleri | B14: 1.3.2 | C14: S2-Araç stoperi 150x15cm boyutlarında 60mm boru profilden beyaz elektrostatik toz boya ile boyanmış stopper temini ve montajının yapılması | F14: adet | G14: 12 | I14: =+H14*G14 -> 0 | K14: =+J14*G14 -> 0 | L14: =+H14+J14 -> 0 | M14: =L14*G14 -> 0
A15: Sinyalizasyon İşleri | B15: 1.3.3 | C15: S3-Otomatik bariyer yapılması (Araç giriş&çıkışında, Renk: Standard, Ölçü: 7m uzunluğunda) | F15: adet | G15: 2 | I15: =+H15*G15 -> 0 | K15: =+J15*G15 -> 0 | L15: =+H15+J15 -> 0 | M15: =L15*G15 -> 0
A16: Sinyalizasyon İşleri | B16: 1.3.4 | C16: S4-Otomatik sürgülü metal kapı temin edilmesi ve tüm montaj işlerinin yapılması (Araç giriş&çıkışında, Renk: Gri, Ölçü: 15m ve 5m açıklık için gereken ölçüde / h:150cm olmak üzere 2 adet) | F16: set | G16: 1 | I16: =+H16*G16 -> 0 | K16: =+J16*G16 -> 0 | L16: =+H16+J16 -> 0 | M16: =L16*G16 -> 0
B17: 1.4 | C17: Metal İşleri | I17: =SUM(I18:I20) -> 0 | K17: =SUM(K18:K20) -> 0 | M17: =SUM(M18:M20) -> 0
A18: Dekoratif Metal İşleri | B18: 1.4.1 | C18: M1-Galvaniz metal 3mm h:25cm detaya uygun boyalı levha imal edilmesi ve zeminden h:15cm olacak şekilde yeşil alan sınırına montajının yapılması (bağlantı için gerekli her türlü çelik konstrüksiyon, tüm aksesuar ve ankraj dahildir) | F18: mt | G18: 27 | I18: =+H18*G18 -> 0 | K18: =+J18*G18 -> 0 | L18: =+H18+J18 -> 0 | M18: =L18*G18 -> 0
A19: Dekoratif Metal İşleri | B19: 1.4.2 | C19: M2-Galvaniz boyalı çelik metal ızgara temin edilmesi ve montajının yapılması, bağlantı için gerekli her türlü çelik konstrüksiyon, tüm aksesuar ve ankraj dahildir (yürüme yolundaki mekanik kuranglezlerin üzerinde70x140cm ve 100x240cm ebatlarında 2 adet) | F19: m² | G19: 4 | I19: =+H19*G19 -> 0 | K19: =+J19*G19 -> 0 | L19: =+H19+J19 -> 0 | M19: =L19*G19 -> 0
A20: 32 31 10 | B20: 1.4.3 | C20: M3-Çevre çiti yapılması (çevre duvarı üzerine kutu profil dikmeli, h:1.00mt yüksekliğinde, renk RAL7039 gri, proje detayına uygun çit yapılması) | F20: mt | G20: 275 | I20: =+H20*G20 -> 0 | K20: =+J20*G20 -> 0 | L20: =+H20+J20 -> 0 | M20: =L20*G20 -> 0
B21: 1.5 | C21: Boya İşleri | I21: =SUM(I22) -> 0 | K21: =SUM(K22) -> 0 | M21: =SUM(M22) -> 0
A22: 09 91 00 | B22: 1.5.1 | C22: D1-Dış cephe boyası yapılması, yüzeyi dokulu (çevre duvarının betonarme yüzeylerine, renk projesine göre) | F22: m² | G22: 374 | I22: =+H22*G22 -> 0 | K22: =+J22*G22 -> 0 | L22: =+H22+J22 -> 0 | M22: =L22*G22 -> 0
B23: 2 | C23: DIŞ SAHA KAPLAMA ALTI İMALATLAR | I23: =SUM(I24:I26) -> 0 | K23: =SUM(K24:K26) -> 0 | M23: =SUM(M24:M26) -> 0
A24: 03 31 00 | B24: 2.1 | C24: Döşeme betonu yapılması (20cm çift kat hasır çelikli beton) - Araç Yolu & Otopark | F24: m² | G24: 5873 | I24: =+H24*G24 -> 0 | K24: =+J24*G24 -> 0 | L24: =+H24+J24 -> 0 | M24: =L24*G24 -> 0
A25: 03 31 00 | B25: 2.2 | C25: Döşeme betonu yapılması (10cm tek kat hasır çelikli beton) - Kaldırım & Yürüme Yolu | F25: m² | G25: 710 | I25: =+H25*G25 -> 0 | K25: =+J25*G25 -> 0 | L25: =+H25+J25 -> 0 | M25: =L25*G25 -> 0
A26: 03 31 00 | B26: 2.3 | C26: Polietilen örtü (200 μ) serilmesi (zemine oturan döşeme betonu altında) | F26: m² | G26: 6583 | I26: =+H26*G26 -> 0 | K26: =+J26*G26 -> 0 | L26: =+H26+J26 -> 0 | M26: =L26*G26 -> 0
B27: 3 | C27: ÇEVRE DUVARI İŞLERİ | I27: =SUM(I28:I29) -> 0 | K27: =SUM(K28:K29) -> 0 | M27: =SUM(M28:M29) -> 0
A28: 03 31 00 | B28: 3.1 | C28: Çevre duvarının betonarme imalatları İnşaii İşler Keşfi kapsamında fiyatlandırılacaktır. | I28: =+H28*G28 -> 0 | K28: =+J28*G28 -> 0 | L28: =+H28+J28 -> 0 | M28: =L28*G28 -> 0
A29: 05 12 00 | B29: 3.2 | C29: Çevre duvarının boyası 1.5.1 pozunda ve çit imalatları 1.4.3 pozunda fiyatlandırılacaktır. | I29: =+H29*G29 -> 0 | K29: =+J29*G29 -> 0 | L29: =+H29+J29 -> 0 | M29: =L29*G29 -> 0
B30: 4 | C30: SULAMA SİSTEM (İşçilik, malzeme, ekipman, nakliye ve tüm gerekli hizmetler dahildir.) | I30: =SUM(I31:I31) -> 0 | K30: =SUM(K31:K31) -> 0 | M30: =SUM(M31:M31) -> 0
B31: 4.1 | C31: Yeşil alanlar için bitkilendirme projesi ve sulama altyapısı bilgileri verilmiş olan 1.500m² yeşil alana uygun otomatik sulama sistemi projelendirme ve imalatının yapılması (İş için gerekli sistem gereksinimleri Yüklenici tarafından hesaplanıp bu kapsama dahil edilecektir.) Otomatik sulama sisteminin pilli kontrol üniteleri ile kumanda edilmesi, ağaç-çalı alanlarının damlama hattından, çim alanların sprinkler sulama yöntemiyle sulanması öngörülmüştür. Bahçede bırakılan altyapıdan beslenip sahada gerekli çıkış noktalarına yerleştirilen vana grupları ile dağıtımı sağlanacaktır. Vana grupları, sprinkler açıları, cansuyu vanası ve bunun gibi sistem gereksinimlerinin ölçü, adet ve yerleşimleri Yüklenici tarafından hesaplanıp projelendirilecektir. | F31: SET | G31: 1 | I31: =+H31*G31 -> 0 | K31: =+J31*G31 -> 0 | L31: =+H31+J31 -> 0 | M31: =L31*G31 -> 0
B32: 5 | C32: BİTKİLENDİRME İŞLERİ | I32: =+I33+I37+I42 -> 0 | K32: =+K33+K37+K42 -> 0 | M32: =+M33+M37+M42 -> 0
B33: 5.1 | C33: Ağaçlar (Tüm ağaçlarda fidan kazığı-herek ve ağaç bağı ile sabitleme yapılması dahildir.) | I33: =SUM(I34:I36) -> 0 | K33: =SUM(K34:K36) -> 0 | M33: =SUM(M34:M36) -> 0
A34: 32 93 00 | B34: 5.1.1 | C34: Acer platanoides / Çınar Yapraklı Akçaağaç, Ø20-25, Boy:350-400cm, CLT50 | F34: adet | G34: 12 | I34: =+H34*G34 -> 0 | K34: =+J34*G34 -> 0 | L34: =+H34+J34 -> 0 | M34: =L34*G34 -> 0
A35: 32 93 00 | B35: 5.1.2 | C35: Betula alba / Huş Ağacı, Ø20-25, Boy:350-400cm, CLT50 | F35: adet | G35: 2 | I35: =+H35*G35 -> 0 | K35: =+J35*G35 -> 0 | L35: =+H35+J35 -> 0 | M35: =L35*G35 -> 0
A36: 32 93 00 | B36: 5.1.3 | C36: Ligustrum japonicum / Kurtbağrı (tijli olursa formu hacimli ve dalların dağılımı düzgün olanı veya alttan dalı çok gövdeli olanı seçilmelidir) Ø20-25, Boy:350-400cm, CLT50 | F36: adet | G36: 4 | I36: =+H36*G36 -> 0 | K36: =+J36*G36 -> 0 | L36: =+H36+J36 -> 0 | M36: =L36*G36 -> 0
B37: 5.2 | C37: Çalılar & Çim | I37: =SUM(I38:I41) -> 0 | K37: =SUM(K38:K41) -> 0 | M37: =SUM(M38:M41) -> 0
A38: 32 93 00 | B38: 5.2.1 | C38: Abelia grandiflora / Güzellik çalısı, Boy:30-40cm, CLT5 | F38: adet | G38: 324 | I38: =+H38*G38 -> 0 | K38: =+J38*G38 -> 0 | L38: =+H38+J38 -> 0 | M38: =L38*G38 -> 0
A39: 32 93 00 | B39: 5.2.2 | C39: Pittosporum tobira "Nana" / Pitos çalısı, Boy:30-40cm, CLT5 | F39: adet | G39: 360 | I39: =+H39*G39 -> 0 | K39: =+J39*G39 -> 0 | L39: =+H39+J39 -> 0 | M39: =L39*G39 -> 0
A40: 32 93 00 | B40: 5.2.3 | C40: Viburnum lucidum / Kartopu çalısı, Boy:80-100cm, CLT5 | F40: adet | G40: 410 | I40: =+H40*G40 -> 0 | K40: =+J40*G40 -> 0 | L40: =+H40+J40 -> 0 | M40: =L40*G40 -> 0
...

Sheet Mekanik
A1: MEKANİK İŞLER | F1: KEŞİF | H1: MALZEME | J1: İŞÇİLİK | L1: Satış Br. Fiyat | M1: Satış Tutar
A2: Şartname No | B2: Poz No | C2: İmalatlar | E2: Marka Listesi | F2: Birim | G2: Metraj | H2: Malzeme Br. Fiyat | I2: Malzeme Tutar | J2: İşçilik Br. Fiyat | K2: İşçilik Tutar
B3: H | C3: HVAC TESİSATI | I3: =+I4+I47+I60+I176+I184+I203+I210+I212+I221+I228+I234+I242+I244+I246+I248+I250+I252++I254+I256 -> 9276879.1 | K3: =+K4+K47+K60+K176+K184+K203+K210+K212+K221+K228+K234+K242+K244+K246+K248+K250+K252++K254+K256 -> 2802807.2 | M3: =+M4+M47+M60+M176+M184+M203+M210+M212+M221+M228+M234+M242+M244+M246+M248+M250+M252++M254+M256 -> 12079686
B4: H-01 | C4: FANLAR | E4: SYSTEMAIR-AFS-ATC | I4: =SUM(I5:I46) -> 1027379 | K4: =SUM(K5:K46) -> 55124 | M4: =SUM(M5:M46) -> 1082503
C5: Cihaz Kodu: SF-01/B1 | F5: adet | G5: 1 | H5: 192244.5 | I5: =+H5*G5 -> 192244.5 | J5: 5890.5 | K5: =+J5*G5 -> 5890.5 | L5: =+H5+J5 -> 198135 | M5: =+L5*G5 -> 198135
C6: Tip :Kanal Tipİ Taze Hava Fanı
C7: Hizmet Alanı : SIĞINAK
C8: Hava Debisi (m3/h): 1000
C9: Dış Statik Basınç(Pa): 300
C10: G4 FİLTRE | F10: adet | G10: 1 | H10: 3250 | I10: =+H10*G10 -> 3250 | J10: 1250 | K10: =+J10*G10 -> 1250 | L10: =+J10+H10 -> 4500 | M10: =+L10*G10 -> 4500
C11: RADYOAKTİF FILTRE | F11: adet | G11: 1 | H11: 7500 | I11: =+H11*G11 -> 7500 | J11: 1250 | K11: =+J11*G11 -> 1250 | L11: =+J11+H11 -> 8750 | M11: =+L11*G11 -> 8750
C12: A.KARBON FILTRE | F12: adet | G12: 1 | H12: 115000 | I12: =+H12*G12 -> 115000 | J12: 5500 | K12: =+J12*G12 -> 5500 | L12: =+J12+H12 -> 120500 | M12: =+L12*G12 -> 120500
C13: Cihaz Kodu: EF-01/B1 | F13: adet | G13: 1 | H13: 28611 | I13: =+H13*G13 -> 28611 | J13: 5890.5 | K13: =+J13*G13 -> 5890.5 | L13: =+H13+J13 -> 34501.5 | M13: =+L13*G13 -> 34501.5
C14: Tip :Kanal Tipİ Aksiyal Egzoz Fan
C15: Hava Debisi (m3/h): 1000
C16: Dış Statik Basınç(Pa): 150
C17: Cihaz Kodu: EF-02/B1 | F17: adet | G17: 1 | H17: 79713 | I17: =+H17*G17 -> 79713 | J17: 5890.5 | K17: =+J17*G17 -> 5890.5 | L17: =+H17+J17 -> 85603.5 | M17: =+L17*G17 -> 85603.5
C18: Ekipman Yeri :POMPA ODASI
C19: Hava Debisi (m3/h): 2000
C20: Dış Statik Basınç(Pa): 200
C21: Tip :Kanal Tipİ Aksiyal Egzoz Fan
C22: E.B: 1,50 kW /3/380/50
C23: Cihaz Kodu: EF-01/GF (EXPROOF) | F23: adet | G23: 1 | H23: 121711.5 | I23: =+H23*G23 -> 121711.5 | J23: 5890.5 | K23: =+J23*G23 -> 5890.5 | L23: =+H23+J23 -> 127602 | M23: =+L23*G23 -> 127602
C24: Ekipman Yeri :DEPO
C25: Hava Debisi (m3/h): 1500
C26: Dış Statik Basınç(Pa): 200
C27: Tip :Kanal Tipİ Egzoz Fan
C28: Cihaz Kodu: EF-02/GF | F28: adet | G28: 1 | H28: 116280 | I28: =+H28*G28 -> 116280 | J28: 5890.5 | K28: =+J28*G28 -> 5890.5 | L28: =+H28+J28 -> 122170.5 | M28: =+L28*G28 -> 122170.5
C29: Ekipman Yeri :Elektrik-Eloktronik Oda
C30: Hava Debisi (m3/h): 3500
C31: Dış Statik Basınç(Pa): 200
C32: Tip :Kanal Tipİ Egzoz Fan
C33: Cihaz Kodu: EF-03/GF | F33: adet | G33: 1 | H33: 162103.5 | I33: =+H33*G33 -> 162103.5 | J33: 5890.5 | K33: =+J33*G33 -> 5890.5 | L33: =+H33+J33 -> 167994 | M33: =+L33*G33 -> 167994
C34: Hava Debisi (m3/h): 12000
C35: Dış Statik Basınç(Pa): 300
C36: Tip :Kanal Tipİ Aksiyal Egzoz Fan
C37: Cihaz Kodu: KEF-01/RF | F37: adet | G37: 1 | H37: 117121.5 | I37: =+H37*G37 -> 117121.5 | J37: 5890.5 | K37: =+J37*G37 -> 5890.5 | L37: =+H37+J37 -> 123012 | M37: =+L37*G37 -> 123012
C38: Ekipman Yeri :ÇATI
C39: Hava Debisi (m3/h): 3000
C40: Dış Statik Basınç(Pa): 250
...

Sheet Elektrik
A1: ELEKTRİK İŞLERİ | G1: KAPSAM | I1: KEŞİF | AP1: MALZEME | AR1: İŞÇİLİK | AT1: Satış Br. Fiyat | AU1: Satış Tutar
I2: Birim | J2: MİKTAR | AO2: TOPLAM
A3: Şartname No | B3: Poz No | C3: İmalatlar | E3: Açıklama | F3: Marka Listesi | G3: TEMİN | H3: MONTAJ | J3: BİNA İÇİ | M3: BEKÇİ KULÜBESİ | N3: VAZİYET PLANI | O3: ADP | P3: KOMP | Q3: TR | R3: SP | S3: MCC-K | T3: MCC-P | U3: AP-B | V3: AP-Z | W3: AT-1 | X3: AT-2 | Y3: PYP | Z3: GP | AA3: MP | AB3: AP-A | AC3: ASP | AD3: BP | AE3: EAS-1 | AF3: EAS-2 | AG3: UADP | AH3: UP-Z | AI3: UP-1 | AJ3: UP-2 | AK3: GUP | AL3: UP-A | AM3: UP-S | AN3: UP-BK
J4: BODRUM KAT | K4: ZEMİN KAT | L4: ASNA KAT | AP4: Malzeme Br. Fiyat | AQ4: Malzeme Tutar | AR4: İşçilik Br. Fiyat | AS4: İşçilik Tutar
C5: ALÇAK GERİLİM SİSTEMLERİ | AQ5: =+AQ6+AQ8+AQ10+AQ37+AQ43+AQ57+AQ201+AQ238+AQ277+AQ314+AQ347+AQ412+AQ443 -> 0 | AS5: =+AS6+AS8+AS10+AS37+AS43+AS57+AS201+AS238+AS277+AS314+AS347+AS412+AS443 -> 0 | AU5: =+AU6+AU8+AU10+AU37+AU43+AU57+AU201+AU238+AU277+AU314+AU347+AU412+AU443 -> 0
B6: 1 | C6: JENERATÖRLER | AQ6: =SUM(AQ7) -> 0 | AS6: =SUM(AS7) -> 0 | AU6: =SUM(AU7) -> 0
C7: 550 kVA Stand-By Jeneratör (Min. 8 saat kapasiteli günlük yakıt tankı ve en az 15cm yükseklikte taşma tepsisi dahil) | E7: Jeneratör, ana ve günlük yakıt tanklarının temini ve montajı İşveren kapsamındadır | G7: İŞVEREN | H7: YÜKLENİCİ | I7: adet | N7: 1 | AO7: =SUM(J7:AN7) -> 1 | AQ7: =+AP7*AO7 -> 0 | AS7: =+AR7*AO7 -> 0 | AT7: =+AP7+AR7 -> 0 | AU7: =+AT7*AO7 -> 0
B8: 2 | C8: UPS (KGS - KESİNTİSİZ GÜÇ KAYNAĞI) | AQ8: =SUM(AQ9) -> 0 | AS8: =SUM(AS9) -> 0 | AU8: =SUM(AU9) -> 0
C9: 20 kVA - 380/380V UPS, 10 dk. süreli, bakımsız akü grubu ve bağlantılar | E9: UPS ve akü kabininin temini ve montajı İşveren kapsamındadır | F9: SOCOMEC/EATON/ VERTİV/ABB | G9: İŞVEREN / YÜKLENİCİ | H9: YÜKLENİCİ | I9: adet | K9: 1 | AO9: =SUM(J9:AN9) -> 1 | AQ9: =+AP9*AO9 -> 0 | AS9: =+AR9*AO9 -> 0 | AT9: =+AP9+AR9 -> 0 | AU9: =+AT9*AO9 -> 0
B10: 3 | C10: AG PANOLARI - Şalt malzemeleri, ölçü aletleri, sinyal lambaları, parafudrlar, aydınlatma otomasyon üniteleri ve her türlü aksesuar, proje cebi, montaj, sarf malzemesi, havalandırma fanları, menfezleri, fabrika ve sahada montaj sonrası testleri ve devreye alma çalışmaları dahil, çalışır vaziyette teslim edilmesi - Tüm (Açık tip, Termik Manyetik, Manyetik vb) şalterler, pako şalterler, yük ayırıcılar ve otomatik transfer şalterleri askı kilit ile kilitlenebilir özellikte olacaktır. - İşveren tarafından temin edilmesi durumunda, frekans Konvertörleri vb ekipmanların panoya montajı, panoda gerekli havalandırma önlemlerinin alınması, her türlü bağlantısı ve çalışır vaziyette teslimi pano birim fiyatına dahildir - Ana dağıtım panolarında pano üzeri mimik diyagram (bara ve giriş-çıkış şalterleri), pano üzeri ve oda içinde uyarı ve açıklama yazıları, tehlike işaretleri pano birim fiyatına dahildir | AQ10: =SUM(AQ11:AQ36) -> 0 | AS10: =SUM(AS11:AS36) -> 0 | AU10: =SUM(AU11:AU36) -> 0
B11: 3.1.1 | C11: ADP | E11: AG PANOLARI - Dikili tip panolarda kabloların alttan girişi için 20cm yükseklikte kaide pano birim fiyatına dahildir (kablo giriş çıkışları alttan yapılacaktır) - yükseltilmiş döşeme ve yükseltilmiş döşeme kotunda kaide yapılması İNŞAİ işler kapsamındadır. | F11: AC GÖVDE : EAE, ETİS, CUBERA, ÖZKAN, PANELSİS, (ISO BELGELİ YEREL) ŞALT : SIEMENS, SCHNEIDER, ABB, EATON | G11: İŞVEREN | H11: YÜKLENİCİ | I11: ad. | O11: 1 | AO11: =SUM(J11:AN11) -> 1 | AQ11: =+AP11*AO11 -> 0 | AS11: =+AR11*AO11 -> 0 | AT11: =+AR11+AP11 -> 0 | AU11: =+AT11*AO11 -> 0
B12: 3.1.2 | C12: KOMP (BİNA AG ODASINDA) - Enerji temin projesi ile pano şeması kesinleşecektir - İşverenden bilgi alınacak | I12: ad. | P12: 1 | AO12: =SUM(J12:AN12) -> 1 | AQ12: =+AP12*AO12 -> 0 | AS12: =+AR12*AO12 -> 0 | AT12: =+AR12+AP12 -> 0 | AU12: =+AT12*AO12 -> 0
B13: 3.1.3 | C13: TR (TRAFO KÖŞKÜNDE) - Enerji temin projesi ile pano şeması kesinleşecektir - İşverenden bilgi alınacak | I13: ad. | Q13: 1 | AO13: =SUM(J13:AN13) -> 1 | AQ13: =+AP13*AO13 -> 0 | AS13: =+AR13*AO13 -> 0 | AT13: =+AR13+AP13 -> 0 | AU13: =+AT13*AO13 -> 0
B14: 3.1.4 | C14: SP | I14: ad. | R14: 1 | AO14: =SUM(J14:AN14) -> 1 | AQ14: =+AP14*AO14 -> 0 | AS14: =+AR14*AO14 -> 0 | AT14: =+AR14+AP14 -> 0 | AU14: =+AT14*AO14 -> 0
B15: 3.1.5 | C15: MCC-K | I15: ad. | S15: 1 | AO15: =SUM(J15:AN15) -> 1 | AQ15: =+AP15*AO15 -> 0 | AS15: =+AR15*AO15 -> 0 | AT15: =+AR15+AP15 -> 0 | AU15: =+AT15*AO15 -> 0
B16: 3.1.6 | C16: MCC-P | I16: ad. | T16: 1 | AO16: =SUM(J16:AN16) -> 1 | AQ16: =+AP16*AO16 -> 0 | AS16: =+AR16*AO16 -> 0 | AT16: =+AR16+AP16 -> 0 | AU16: =+AT16*AO16 -> 0
B17: 3.1.7 | C17: AP-B | I17: ad. | U17: 1 | AO17: =SUM(J17:AN17) -> 1 | AQ17: =+AP17*AO17 -> 0 | AS17: =+AR17*AO17 -> 0 | AT17: =+AR17+AP17 -> 0 | AU17: =+AT17*AO17 -> 0
B18: 3.1.8 | C18: AP-Z | I18: ad. | V18: 1 | AO18: =SUM(J18:AN18) -> 1 | AQ18: =+AP18*AO18 -> 0 | AS18: =+AR18*AO18 -> 0 | AT18: =+AR18+AP18 -> 0 | AU18: =+AT18*AO18 -> 0
B19: 3.1.9 | C19: AT-1 | I19: ad. | W19: 1 | AO19: =SUM(J19:AN19) -> 1 | AQ19: =+AP19*AO19 -> 0 | AS19: =+AR19*AO19 -> 0 | AT19: =+AR19+AP19 -> 0 | AU19: =+AT19*AO19 -> 0
B20: 3.1.10 | C20: AT-2 | I20: ad. | X20: 1 | AO20: =SUM(J20:AN20) -> 1 | AQ20: =+AP20*AO20 -> 0 | AS20: =+AR20*AO20 -> 0 | AT20: =+AR20+AP20 -> 0 | AU20: =+AT20*AO20 -> 0
B21: 3.1.11 | C21: PYP - İPTAL EDİLMİŞTİR | I21: ad. | Y21: 0 | AO21: =SUM(J21:AN21) -> 0 | AQ21: =+AP21*AO21 -> 0 | AS21: =+AR21*AO21 -> 0 | AT21: =+AR21+AP21 -> 0 | AU21: =+AT21*AO21 -> 0
B22: 3.1.12 | C22: GP | I22: ad. | Z22: 1 | AO22: =SUM(J22:AN22) -> 1 | AQ22: =+AP22*AO22 -> 0 | AS22: =+AR22*AO22 -> 0 | AT22: =+AR22+AP22 -> 0 | AU22: =+AT22*AO22 -> 0
B23: 3.1.13 | C23: MP | I23: ad. | AA23: 1 | AO23: =SUM(J23:AN23) -> 1 | AQ23: =+AP23*AO23 -> 0 | AS23: =+AR23*AO23 -> 0 | AT23: =+AR23+AP23 -> 0 | AU23: =+AT23*AO23 -> 0
B24: 3.1.14 | C24: AP-A | I24: set | AB24: 1 | AO24: =SUM(J24:AN24) -> 1 | AQ24: =+AP24*AO24 -> 0 | AS24: =+AR24*AO24 -> 0 | AT24: =+AR24+AP24 -> 0 | AU24: =+AT24*AO24 -> 0
B25: 3.1.15 | C25: ASP Asansör ile birlikte temin edilebilir - İşverenden bilgi alınacak | I25: set | AC25: 1 | AO25: =SUM(J25:AN25) -> 1 | AQ25: =+AP25*AO25 -> 0 | AS25: =+AR25*AO25 -> 0 | AT25: =+AR25+AP25 -> 0 | AU25: =+AT25*AO25 -> 0
B26: 3.1.16 | C26: BP | I26: set | AD26: 1 | AO26: =SUM(J26:AN26) -> 1 | AQ26: =+AP26*AO26 -> 0 | AS26: =+AR26*AO26 -> 0 | AT26: =+AR26+AP26 -> 0 | AU26: =+AT26*AO26 -> 0
B27: 3.1.17 | C27: EAS-1 - Kullanılacak şarj ünitesine göre pano şeması kesinleşecektir - İşverenden bilgi alınacak | I27: set | AE27: 1 | AO27: =SUM(J27:AN27) -> 1 | AQ27: =+AP27*AO27 -> 0 | AS27: =+AR27*AO27 -> 0 | AT27: =+AR27+AP27 -> 0 | AU27: =+AT27*AO27 -> 0
B28: 3.1.18 | C28: EAS-2 - Kullanılacak şarj ünitesine göre pano şeması kesinleşecektir - İşverenden bilgi alınacak | I28: set | AF28: 1 | AO28: =SUM(J28:AN28) -> 1 | AQ28: =+AP28*AO28 -> 0 | AS28: =+AR28*AO28 -> 0 | AT28: =+AR28+AP28 -> 0 | AU28: =+AT28*AO28 -> 0
B29: 3.1.19 | C29: UADP | I29: set | AG29: 1 | AO29: =SUM(J29:AN29) -> 1 | AQ29: =+AP29*AO29 -> 0 | AS29: =+AR29*AO29 -> 0 | AT29: =+AR29+AP29 -> 0 | AU29: =+AT29*AO29 -> 0
B30: 3.1.20 | C30: UP-Z | I30: set | AH30: 1 | AO30: =SUM(J30:AN30) -> 1 | AQ30: =+AP30*AO30 -> 0 | AS30: =+AR30*AO30 -> 0 | AT30: =+AR30+AP30 -> 0 | AU30: =+AT30*AO30 -> 0
B31: 3.1.21 | C31: UP-1 | I31: set | AI31: 1 | AO31: =SUM(J31:AN31) -> 1 | AQ31: =+AP31*AO31 -> 0 | AS31: =+AR31*AO31 -> 0 | AT31: =+AR31+AP31 -> 0 | AU31: =+AT31*AO31 -> 0
B32: 3.1.22 | C32: UP-2 | I32: set | AJ32: 1 | AO32: =SUM(J32:AN32) -> 1 | AQ32: =+AP32*AO32 -> 0 | AS32: =+AR32*AO32 -> 0 | AT32: =+AR32+AP32 -> 0 | AU32: =+AT32*AO32 -> 0
B33: 3.1.23 | C33: GUP | I33: set | AK33: 1 | AO33: =SUM(J33:AN33) -> 1 | AQ33: =+AP33*AO33 -> 0 | AS33: =+AR33*AO33 -> 0 | AT33: =+AR33+AP33 -> 0 | AU33: =+AT33*AO33 -> 0
B34: 3.1.24 | C34: UP-A | I34: set | AL34: 1 | AO34: =SUM(J34:AN34) -> 1 | AQ34: =+AP34*AO34 -> 0 | AS34: =+AR34*AO34 -> 0 | AT34: =+AR34+AP34 -> 0 | AU34: =+AT34*AO34 -> 0
B35: 3.1.25 | C35: UP-S | I35: set | AM35: 1 | AO35: =SUM(J35:AN35) -> 1 | AQ35: =+AP35*AO35 -> 0 | AS35: =+AR35*AO35 -> 0 | AT35: =+AR35+AP35 -> 0 | AU35: =+AT35*AO35 -> 0
B36: 3.1.26 | C36: UP-BK | I36: set | AN36: 1 | AO36: =SUM(J36:AN36) -> 1 | AQ36: =+AP36*AO36 -> 0 | AS36: =+AR36*AO36 -> 0 | AT36: =+AR36+AP36 -> 0 | AU36: =+AT36*AO36 -> 0
B37: 4 | C37: OTOMATİK ŞALTERLER OTOMATİK TRANSFER ŞALTERLERİ (ATS-for use in emergency systems) - NFPA 20, 70, 99, 110 standartlarına uygun, UL-1008 ve IEC 60947-6-1 belgeli - Pano, her türlü şalt malzemeleri, ölçü aletleri, sinyal lambaları, her türlü aksesuar, montaj, sarf malzemesi, havalandırma fanları, menfezleri, fabrika ve sahada montaj sonrası testleri ve devreye alma çalışmaları dahil, çalışır vaziyette teslim edilmesi - Yangın Dağıtım Panolarında bulunan ATS ler ilgili pano fiyatına dahildir, Teklif ekinde verilecek pano detaylı dökümlerinde ATS ler de belirtilecektir | AQ37: =SUM(AQ38:AQ42) -> 0 | AS37: =SUM(AS38:AS42) -> 0 | AU37: =SUM(AU38:AU42) -> 0
B38: 4.1.1 | C38: 3x100A e kadar ATS Pano Dahil | E38: ATS (PANO DAHİL) | F38: ASCO, RUSSELECTRIC, GENERAL ZENITH SOCOMEC | G38: İŞVEREN | H38: YÜKLENİCİ | I38: ad. | AO38: =SUM(J38:AN38) -> 0 | AQ38: =+AP38*AO38 -> 0 | AS38: =+AR38*AO38 -> 0 | AT38: =+AR38+AP38 -> 0 | AU38: =+AT38*AO38 -> 0
B39: 4.1.2 | C39: 3x160A e kadar ATS Pano Dahil | I39: ad. | AO39: =SUM(J39:AN39) -> 0 | AQ39: =+AP39*AO39 -> 0 | AS39: =+AR39*AO39 -> 0 | AT39: =+AR39+AP39 -> 0 | AU39: =+AT39*AO39 -> 0
B40: 4.1.3 | C40: 3x250A e kadar ATS Pano Dahil | I40: ad. | J40: 0 | AO40: =SUM(J40:AN40) -> 0 | AQ40: =+AP40*AO40 -> 0 | AS40: =+AR40*AO40 -> 0 | AT40: =+AR40+AP40 -> 0 | AU40: =+AT40*AO40 -> 0
...

Sheet Enerji temini
A1: ENERJİ TEMİNİ | F1: KEŞİF | H1: MALZEME | J1: İŞÇİLİK | L1: Satış Br. Fiyat | M1: Satış Tutar
A2: Şartname No | B2: Poz No | C2: İmalatlar | F2: Birim | G2: Metraj | H2: Malzeme Br. Fiyat | I2: Malzeme Tutar | J2: İşçilik Br. Fiyat | K2: İşçilik Tutar
B3: 1 | C3: ENERJİ TEMİNİ VE ORTA GERİLİM İŞLERİ | I3: =+I4+I5 -> 0 | K3: =+K4+K5 -> 0 | M3: =+M4+M5 -> 0
B4: 1.1 | C4: Bina güç ihtiyacına uygun olarak enerji temini yapılabilmesi için ilgili kurumlara başvuru yapılması, enerji şartı alınması, projelerin hazırlanarak onaylatılması | F4: AD | G4: 1 | I4: =+H4*G4 -> 0 | K4: =+J4*G4 -> 0 | L4: =+H4+J4 -> 0 | M4: =L4*G4 -> 0
B5: 1.2 | C5: Hazırlanacak enerji temin projesine uygun olarak beton köşkün temin edilmesi, tüm uygulamanın yapılması tesise enerji verilene kadar gerekli teknik ve idari süreçlerin takip edilmesi, İşverene çalışır vaziyette teslim edilmesi. | F5: AD | G5: 1 | I5: =+H5*G5 -> 0 | K5: =+J5*G5 -> 0 | L5: =+H5+J5 -> 0 | M5: =L5*G5 -> 0
F7: TOPLAM | J7: MALZEME | L7: =+I3 -> 0
J8: İŞÇİLİK | L8: =+K3 -> 0
J9: TOPLAM FİYAT (KDV'siz) | L9: =+L7+L8 -> 0

Sheet Asansör
A1: ASANSÖR | F1: KEŞİF | H1: MALZEME | J1: İŞÇİLİK | L1: Satış Br. Fiyat | M1: Satış Tutar
A2: Şartname No | B2: Poz No | C2: İmalatlar | F2: Birim | G2: Metraj | H2: Malzeme Br. Fiyat | I2: Malzeme Tutar | J2: İşçilik Br. Fiyat | K2: İşçilik Tutar
B3: 1 | C3: ASANSÖR TEMİNİ VE MONTAJI | I3: =+I4 -> 0 | K3: =+K4 -> 0 | M3: =+M4 -> 0
B4: 1.1 | C4: 800 Kg kapasiteli elektrik motorlu asansörün avan proje ve teknik şartnamesine uygun olarak uygulama-ruhsat projelerinin hazırlanması, gerekli kurumlara onaylatılması, temini ve montajının yapılarak, asansörün kullanıma açılması için tüm onayların alınarak işletmeye açılması | F4: AD | G4: 1 | I4: =+H4*G4 -> 0 | K4: =+J4*G4 -> 0 | L4: =+H4+J4 -> 0 | M4: =L4*G4 -> 0
F6: TOPLAM | J6: MALZEME | L6: =+I3 -> 0
J7: İŞÇİLİK | L7: =+K3 -> 0
J8: TOPLAM FİYAT (KDV'siz) | L8: =+L6+L7 -> 0
