Workbook
Name __GRUP__: #REF!
Name __MAIN__: #REF!
Name __YM__: #REF!
Name __YMBM__: #REF!
Name __YMNAK__: #REF!
Name _BFK20: [1]bfk!$A:$IV
Name _BFK2003: #REF!
Name _BFK21: [1]bfk!$A:$IV
Name A: #REF!
Name AllPrice: '[3]Operatör İstasyonları'!#REF!
Name AMORTİSMAN: '[4]2-KAR KATSAYI'!#REF!
Name ASD: #REF!
Name ASDDSADSA: #REF!
Name ASDSADSAD: '[4]2-KAR KATSAYI'!#REF!
Name B784j85: #REF!
Name Bağlantı_Aparatı__Armut_Kelepçe__U_Kelepçe__Ağır_Yük_Kelepçesi_vb.____projeye_uygun_galvaniz_sacdan_imal_edilecektir.: #REF!
Name BaseModel: '[3]Operatör İstasyonları'!#REF!
Name BaseModelPrice: '[3]Operatör İstasyonları'!#REF!
Name BAY_2005: '[5]2005BRF'!$A$3:$D$23351
Name BF_1995: #REF!
Name bfk: #REF!
Name BFKK: '[1]ANA SAYFA'!$B$2
Name Boru_Montaj_Malzeme_Bedeli__Dişli_Bağlantı____T__Dirsek__Kep__Redüksiyon_vb._Tüm_Bağlantı_Parçaları____Boru_metrajının__30_u: #REF!
Name Boru_Montaj_Malzeme_Bedeli__Kaynak_Bağlantılı____T__Dirsek__Kep__Redüksiyon_vb._Tüm_Bağlantı_Parçaları____Boru_metrajının__25_i: #REF!
Name Boru_Montaj_Malzeme_Bedeli__Yivli_Bağlantılı____T__Dirsek__Kep__Redüksiyon_vb._Tüm_Bağlantı_Parçaları____Boru_metrajının__40_ı: #REF!
Name ClientComp0: '[3]Operatör İstasyonları'!#REF!
Name ClientCompany: '[3]Operatör İstasyonları'!#REF!
Name ClientFax: '[3]Operatör İstasyonları'!#REF!
Name ClientName: '[3]Operatör İstasyonları'!#REF!
Name ClientStreet: '[3]Operatör İstasyonları'!#REF!
Name ClientTel: '[3]Operatör İstasyonları'!#REF!
Name ClientTown: '[3]Operatör İstasyonları'!#REF!
Name ConfigState: '[3]Operatör İstasyonları'!#REF!
Name ÇELİK_BORU__BORU_MALZEMESİ__ASTM_A53_GR.B____KAYNAK_BAĞLANTILI: #REF!
Name ÇELİK_BORU__BORU_MALZEMESİ__ASTM_A53_GR.B____YİVLİ_BAĞLANTILI: #REF!
Name ÇELİK_BORU__TS_EN_10255_A1__AĞIR_SERİ___KAYNAK_BAĞLANTILI: #REF!
Name ÇELİK_BORU__TS_EN_10255_A1__AĞIR_SERİ___YİVLİ_BAĞLANTILI: #REF!
Name ÇELİK_BORU__TS_EN_10255_A1__ORTA_SERİ____TS_EN_ISO_1461_GALVANİZ_KAPLI: #REF!
Name ÇELİK_BORU__TS_EN_10255_A1__ORTA_SERİ___KAYNAK_BAĞLANTILI: #REF!
Name ÇELİK_BORU__TS_EN_10255_A1__ORTA_SERİ__YİVLİ_BAĞLANTILI: #REF!
Name Dış_Dişli_Körtapa: #REF!
Name DİL: '[6]1-KAR KATSAYI'!$C$4
Name Dişli_Dirsek: #REF!
Name Dişli_Manşon: #REF!
Name Dişli_Manşon_Redüksiyon: #REF!
Name Dişli_Mekanik_Te: #REF!
Name Dişli_Nipel_Redüksiyon: #REF!
Name Dişli_Te: #REF!
Name DOLAR: [7]KATSAYI!$B$5
Name DOLARYTL: #REF!
Name ds: #REF!
Name Düz_Rekor: #REF!
Name E: #REF!
Name Eksantrik_Sch30_Redüksiyon: #REF!
Name Eksantrik_Sch40_Redüksiyon: #REF!
Name Eksantrik_Sch80_Redüksiyon: #REF!
Name Equipment: #REF!
Name Esnek_Kaplin_ASTM_A536__300_Psi: #REF!
Name EURO: [7]KATSAYI!$B$4
Name EUROYTL: #REF!

Sheet İCMAL
B3: FIRMA-C ENTEGRE SAHA-ALTI TESİSİ YANGIN SÖNDÜRME SİSTEMLERİ TEMİNİ-MONTAJ,TEST & DEVREYE ALMA İŞİ
B5: İCMAL SAYFASI- İŞÇİLİK
B6: Bölge No | C6: KAPSAM
B7: 1 | C7: Hidrant Sistemi | D7: =hidrant!H21 -> 497500
B8: 2 | C8: Yangın Pompa Odası | D8: =pompa!H45 -> 388103
B9: 3 | C9: Konveyör | D9: =konveyör!H266 -> 102700
B10: 4 | C10: Sprinkler Sistemi | D10: =sprinkler!H78 -> 29327215
B11: 5 | C11: İdari Bina | D11: ='idari bina'!H52 -> 236350
B12: 6 | C12: Metanol Köpük | D12: ='metanol köpük'!H45 -> 0
B13: 7 | C13: Otomatik köpük | D13: ='otomatik köpük'!H86 -> 0
B14: 8 | C14: Yangın Durdurucu | D14: ='yangin durdurucu'!G21 -> 0
B15: 9
C16: TOPLAM MALİYET: | D16: =D7+D8+D9+D10+D11+D12+D13+D14+D15 -> 30551868

Sheet hidrant
A9: HİDRANT SİSTEMİ
A10: NO | B10: MALZEME ADI | C10: MİKTARI | D10: BİRİM | E10: MARKA | F10: ONAY | G10: İŞÇİLİK BF | H10: İŞÇİLİK TF
A11: 1 | B11: Dış Saha Yerüstü Hidrantı (Mevcut) | C11: 19 | D11: Ad | E11: KAPSAM DIŞI
A12: 2 | B12: Dış Saha Yerüstü Hidrantı (Yeni Planlanan) Türü : Yer Üstü Hidrantı Giriş Çapı : DN100 Çıkış Çapı : 2 x DN 65 Storz Giriş Bağlantısı : Flanşlı Çıkış Bağlantısı : Flanşlı Montaj Biçimi : Yer Üstü Açılma : Elle Aksesuarlar : 1 adet Açma Anahtarı ve Hidrant Dirseği ile Onaylar : TSE Onaylı Yedekler : - | C12: 2 | D12: Ad | F12: TSE | G12: 5000 | H12: =+G12*C12 -> 10000
A13: 3 | B13: Hidrant Koruyucu İmalatı (Yeni Planlanan) Türü : Yer Üstü, Çelik Yere Sabitlenmiş Ayak Koruma : Dış Hava Koşullarına, Paslanmaya Dayanıklı ve Korumalı Montaj Yeri : Hidrant Yakınına Malzeme : DN 80 Borudan İmal Renk : Sarı ve Siyah Boyalı | C13: 2 | D13: Ad
A14: 4 | B14: Yerüstü Hidrant Dolabı (Yeni Planlanan) Türü : Yer Üstü, Ayaklı Koruma : Dış Hava Koşullarına Dayanıklı ve Korumalı Montaj Yeri : Hidrant Yakınına Malzeme : Fosfatlanmış Galvanize Saç (Üzeri Epoksi Kaplı) Renk : RAL3000 Kırmızı Aksesuarlar : 1 adet Hidrant Açma Anahtarı, 2 adet DN65 PVC Kaplı 30 m Bez Hortum ve Tekerli ve 2 adet Ayarlı Nozul ve Nozul Tutturma Kelepçesiyle Onaylar : TSE Belgeli Yedekler : - | C14: 2 | D14: Ad | F14: TSE | G14: 2500 | H14: 5000
A15: 5 | B15: Yükselen Milli Vana (OS&Y Vana) (Yeni Planlanan) DN150 | C15: 1 | D15: Ad | G15: 4500 | H15: 4500
A16: 6 | B16: PE Yeraltı Yangın Suyu Borusu, (DN180 )(Yeni Planlanan) Malzeme : PE-100 (HDPE), SDR 11 Çap : DN 180 Basınç Sınıfı : PN 16 Ek Türü : Elektrofüzyon veya Alın Kaynaklı Ek veya Fittings : Her Türlü Yardımcı Malzeme ve Fittings Dahil Uygunluk : TS 418-2 EN 12201-2 | C16: 850 | D16: m | G16: 400 | H16: 340000
A17: 7 | B17: Su Monitörü (Mevcut) | C17: 9 | D17: Ad | E17: KAPSAM DIŞI
A18: 8 | B18: Dikişli Siyah Çelik Yangın Suyu Borusu, (DN150) (Yeni Planlanan) - 5mm Türü : Siyah Çelik Üzeri Standartlara Uygun 1 Kat Antipas ve 2 Kat RAL 3000 Yağlı Boya Çap : DN 150 Basınç Sınıfı : PN 16 Ek veya Fittings : Boru Sistemi için Gerekli Her Türlü Dirsek, T, Flanş, Kaynak vb. Uygunluk : TSE EN 10255 Orta Seri | C18: 60 | D18: m | F18: TSE | G18: 500 | H18: 30000
A19: 9 | B19: Dikişli Siyah Çelik Yangın Suyu Borusu, (DN100) (Yeni Planlanan) - 4.5 mm Türü : Yukardakinin aynısı Çap : DN 100 | C19: 200 | D19: m | F19: TSE | G19: 540 | H19: 108000
A20: 10 | B20: ø400 , tek parça ,2000 mm /ad ,400 doz yüksek dayanımlı betondan vibratör tekniğiyle üretilmiş entegre contalı Büz beton | C20: 0 | D20: ad | F20: TS,EN
A21: GENEL TOPLAM : | H21: =SUM(H12:H20) -> 497500

Sheet pompa
B7: NOT : MEVCUT POMPALAR ÇIKARILARAK YENİ POMPALAR MINTE EDİLECEK.
A9: YANGIN POMPA ODASI
A10: NO | B10: MALZEME ADI | C10: MİKTARI | D10: BİRİM | E10: MARKA | F10: ONAY | G10: İŞÇİLİK BF | H10: İŞÇİLİK TF
A11: 1 | B11: Dizel Motorlu Yangın Pompası Türü : Tek Kademeli, Yatay, Ayrılabilir Gövdeli (Horizontal Split-Case) Anma Debisi (Rated Flow) : 2500 gpm Anma Basıncı (Rated Head): 175 psi Kapalı Basma Basıncı : En Fazla 245 psi (Shut-Off Head) Motor Dönüş Yönü : Saat Yönünde (Clockwise) Uygunluk : NFPA 20'ye Uygun Gövde : Eksenel Bölünmüş Tip ve Dökme Demir Dizel Motor Türü : Yatay Milli Dizel Motor Soğutması : Su Soğutmalı (Basma Hattı Yangın Suyu) Yakıt Deposu : Kapasitesi NFPA 20’ye Uygun, Seviye Göstergeli Yakıt Deposu Nefesliği : Şapkalı Tip, Korozyon Dayanımlı İçindekiler : Yakıt Deposu, Egzoz, 2 Tk. Kuru Tip Akü, Motor Soğutma Hattı, Manometreler, Hava Atma Ventili, | C11: 2 | D11: Ad | F11: UL-FM | G11: 40000 | H11: =+G11*C11 -> 80000 | J11: 10
A12: 2 | B12: Dizel Motorlu Yangın Pompası Kontrol Paneli Türü : Mikroişlemcili Koruma Sınıfı : Tam Kapalı ve Sızdırmaz Koruma (NEMA 4) Güç Beslemesi : 380 VAC/3-Ph//50Hz İçindekiler : Basınç Kumanda Cihazı, Yedek ve Asıl Aküler, Devresi, Otomatik Zaman Saati, Sistem Basıncı Kayıt Cihazı, Test Devresi, Min. Çalışma Süresi Zamanlayıcısı | C12: 2 | D12: Ad | F12: UL-FM | G12: 40000 | H12: 80000
A13: 3 | B13: Elektrik Motorlu Kaçak Pompası (Jokey Pompa) Türü : Dikey Milli, Çok Kademeli Anma Debisi : 25 gpm Anma Basıncı : 185 psi Elektrik Motor : ODP İçindekiler : Emniyet Ventili, Manometreler, Hava Atma Ventili | C13: 1 | D13: Ad | F13: UL-FM | G13: 20000 | H13: 20000
A14: 4 | B14: Elektrik Motorlu Kaçak Giderme Pompası (Jokey Pompa) Kontrol Paneli Türü : Röleli Koruma Sınıfı : Tam Kapalı ve Sızdırmaz Koruma (NEMA 4) Gücü : Pompaya Uygun Olarak Seçilmiş İçindekiler : Basınç Kumanda Cihazı, Min. Çalışma Süresi Zamanlayıcısı, Çalışma Süresi Toplayıcısı (Totaliser) | C14: 1 | D14: Ad | F14: " | G14: 20000 | H14: 20000
A15: 5 | B15: Yükselen Milli Vana (OS&Y Valve) Çap : DN 250 Vana Türü : Yükselen Milli Sürgülü Bağlantı Türü : Flanşlı Basınç Sınıfı : 175 psi Açılma : Volanlı Malzeme : - Vana Gövdesi : Dökme Demir - Disk : EPDM Kaplamalı Döküm Demir Aksesuarlar : İzleme Anahtarlı (TKÇY) | C15: 2 | D15: Ad | F15: UL-FM | G15: 6000 | H15: 12000
A16: 6 | B16: Yükselen Milli Vana (OS&Y Valve) Yukarıdaki gibi ancak; Giriş – Çıkış : DN 32 | C16: 1 | D16: Ad | F16: UL-FM | G16: 600 | H16: 600
A17: 7 | B17: Çek Vana Giriş – Çıkış : DN 250 Tip : Çalparalı (Swing) Bağlantı : Flanşlı Basınç Sınıfı : 300 psi Montaj Biçimi : Dik veya yatay | C17: 2 | D17: Ad | F17: UL-FM | G17: 4000 | H17: 8000
A18: 8 | B18: Çek Vana Yukarıdaki gibi ancak; Giriş – Çıkış : DN 100 | C18: 1 | D18: Ad | F18: UL-FM | G18: 2200 | H18: 2200
A19: 9 | B19: Çek Vana Yukarıdaki gibi ancak; Giriş – Çıkış : DN 32 | C19: 1 | D19: Ad | F19: UL-FM | G19: 600 | H19: 600
A20: 10 | B20: Basınç Rahatlatma Vanası (Pressure Relief Valve) Çap : DN 150 Bağlantı Türü : Flanşlı Basınç Sınıfı : 300 psi | C20: 2 | D20: Ad | F20: UL-FM | G20: 3000 | H20: 6000
A21: 10 | B21: waste cone, size 6” x 10 Çap : DN 150 x DN250 Bağlantı Türü : Flanşlı | C21: 0 | D21: Ad | F21: UL/FM
A22: 11 | B22: Kelebek Vana, DN 250 Giriş – Çıkış : DN 250 Bağlantı : Wafer Tip Basınç Sınıfı : 300 psi Montaj Biçimi : Dik-Yatay Açılma : Dişli Kutulu El Volanı ile Malzeme : Döküm Demir Gövdeli, Bronz Diskli Gösterge : Konum Gösteren İbreli Aksesuarlar : TKÇY İzleme Anahtarı ve 2 adet Bağlantı Kelepçesi ile | C22: 2 | D22: Ad | F22: UL-FM | G22: 4000 | H22: 8000
A23: 12 | B23: Kelebek Vana, DN 200 Yukarıdaki gibi ancak; Çap : DN 200 | C23: 3 | D23: Ad | F23: UL-FM | G23: 3500 | H23: 10500
A24: 13 | B24: Test Akış Ölçme Cihazı Türü : Annubar veya Venturi Giriş – Çıkış : DN 200 Gösterge : 0-2500 gpm İşletme Basıncı : En Fazla 20 Bar (300 psi) | C24: 1 | D24: Ad | F24: UL-FM | G24: 3500 | H24: 3500
A25: 14 | B25: İtfaiye Bağlantı Ağzı İşlevi : Yangın Suyu Sistemine İtfaiye Aracıyla Dışarıdan Yangın Suyu Beslemesini Sağlamak Çıkış Bağlantıları : DN 65 x DN 65 Arka Bağlantısı : DN 100 Aksesuarlar : Çıkış Ağızlarını Koruyucu Kapak, Bronz Duvar Rozeti ve 2 adet - DN 65 Storz Adaptörlü | C25: 1 | D25: Ad | F25: UL-FM | G25: 2500 | H25: 25003
A26: 15 | B26: Otomatik Damlatma Vanası İşlevi : Boru İçinde Kalan Suyu Boşaltma Malzeme : - Gövde: Bronz - Küre: Paslanmaz Çelik veya Pirinç Tip : Otomatik, Yaylı Giriş : DN 15 Dişli | C26: 1 | D26: Ad | F26: UL-FM | G26: 300 | H26: 300
A27: 16 | B27: Küresel Vana Giriş-Çıkış : DN 25, Dişli Tip : Paslanmaz Çelik Küresel, Tam Geçişli Tahrik : 90°, Kollu Aksesuar : Amacını Gösteren İşaret Plakası ve İşaretlemelerle Birlikte | C27: 2 | D27: Ad | F27: TSE | G27: 500 | H27: 1000
A28: 17 | B28: Yivli Boru Bağlantı Kelepçesi, Esnek İşlevi : Boru Üzerinde Esnek Bağlantı Noktası Oluşturmak, Çap : DN 250 Türü : Esnek (Flexible) Malzeme : Demir Döküm Kelepçe Contası : EPDM (Yangın Kullanımına Uygun | C28: 4 | D28: Ad | F28: UL-FM
A29: 18 | B29: 0-20 Bar Manometre ve Kesme Vanası Gösterge Aralığı : 0-20 Bar Göstergeli Tip : İbreli, Gliserinli Tip Aksesuar : Vana Altı, 3 Yollu Kesme ve Tahliye Vanası ile Bağlantı : Dişli Bağlantılı | C29: 1 | D29: Ad | F29: TSE | G29: 400 | H29: 400
A30: 19 | B30: Boru Desteği Destek Malzemesi : Çelik C120 Profil (Ortalama 1 m Uzunluğunda) Sabitleme Malzemesi : M14 U-Vida (U-Bolt) | C30: 30 | D30: Ad
A31: 20 | B31: Paslanmaz Çelik Boru Çap : DN 15 Basınç Sınıfı : PN 16 Aksesuar : DN 15 Şiber Vana, DN 15 Çek Vana, Fittingsler Standardı : TSE EN 10216-5, | C31: 40 | D31: m | F31: TSE | G31: 200 | H31: 8000
A32: 21 | B32: Dikişli Siyah Çelik Boru, DN 250- 5mm Çap : DN 250 Basınç Sınıfı : PN 16 Standardı : TS EN 10217-1’e Uygun Yardımcı Malzeme : Boru Sistemi için Gerekli Her Türlü Dirsek, T, Flanş Vb. Dâhil İmalat : Siyah Çelik Üzeri Standartlara Uygun 1 Kat Antipas ve 2 Kat RAL 3000 Yağlı boya | C32: 50 | D32: m | F32: TSE | G32: 1000 | H32: 50000
A33: 22 | B33: Dikişli Siyah Çelik Boru, DN 200- 5 mm | C33: 40 | D33: m | F33: TSE | G33: 750 | H33: 30000
A34: 23 | B34: Dikişli Siyah Çelik Boru, DN32 | C34: 15 | D34: m | F34: TSE | G34: 300 | H34: 4500
A35: 24 | B35: Kolektör İmalatı (DN300) Çap : DN 300 Malzeme : Dikişli Siyah Çelik Boru Uzunluk : 4 m Giriş-Çıkış : 2 x DN250 + 1 x DN32 Flanşlı Giriş – 2 x HDPE180 + 1 x DN100 Flanşlı Çıkış 1 x DN32 (Gider Vanası), 1 x DN25 (Manometre) Kaynaklı Bağlantı Basınç Sınıfı : PN 16 Standardı : TS EN 10217-1 İmalat : Antipas + 2 Kat Yağlı Boya + Her Türlü Duvara Asma Elemanı ile | C35: 1 | D35: Ad | G35: 10000 | H35: 10000
A36: 25 | B36: Vorteks Plakası Boyutlar : 40 cm x 40 cm Çap : DN 250 Malzeme : Sıcak Daldırma Galvaniz Çelik | C36: 2 | D36: Ad
A37: 26 | B37: Duvar Tipi Eksenel Egzoz Fanı El ile ve dizel pompanın devreye girmesi ile çalışacak şekilde aşağıda belirtilen özelliklere sahip olacaktır. Debi : 2000 m³/h Cihaz Dışı Basınç Kaybı : 50 Pa Malzeme : Galvaniz Çelik Gövde, Alüminyum Döküm Fan Motor : Direk akuple, 0,15 kW, 220V/1Ph/50Hz Özellikleri : Motor Korumalı, Koruma Kafesi ile Aksesuar : Geri Dönüşsüz (Backdraft) Damperli | C37: 1 | D37: tk. | G37: 4000 | H37: 4000
A38: 27 | B38: Geri Dönüşsüz (Backdraft) Damper Kullanım Yeri : Egzoz Fanı için Taze Hava Sağlamak Malzeme : 1,2 mm Galvaniz Çelik Plaka Boyut : 20 cm x 20 cm Montaj Şekli : Yerden 50 cm Yükseklikte | C38: 1 | D38: tk.
A39: 28 | B39: Oda Tipi Termostat Ortam sıcaklığının 10°C’nin altına düşmesi durumunda alarm bilgisi alınacaktır. Sıcaklık Aralığı : 0, 50 °C | C39: 1 | D39: tk.
A40: 29 | B40: Pompa Odası Gider Sistemi Pompa odasına çizimlerde belirtildiği şekilde yer süzgeci kurulumlarıyla en az %4 eğimle doğal cazibeyle oda dışına atılması | C40: 1 | D40: Tk
A41: 30 | B41: Şamandıralı Seviye Kontrol Vanası Giriş – Çıkış : DN 100 Bağlantı : Flanşlı Basınç Sınıfı : PN 10 Malzeme : Sfero Döküm | C41: 2 | D41: Ad | G41: 1500 | H41: 3000
A42: 31 | B42: Su Seviye Gösterge Hortumu ve Aksesuarları Temini Çap : DN 15 Basınç Sınıfı : PN 10 Standardı : TS 8507’e Uygun Et Kalınlığı : En az 1,2 mm - şeffaf Yardımcı Malzeme : Gösterge gerekli her türlü dirsek, hortum kelepçesi , duvara montaj aparatı, boşaltma vanası vb. dâhil | C42: 2 | D42: Ad | F42: TSE | G42: 500 | H42: 500
A43: 32 | B43: Bağlantı Elemanları ve Yardımcı Malzemeler Her türlü bağlantı elemanları, tesisat malzemeleri, Sabitleme amaçlı imalat ve hazır elemanları, Fittings, kaynak, sızdırmalık malzemeleri, Korozyona karşı koruyucular, tesisat boya işleri, Etiketleme ve işaretlemeleri, montaj kutuları, gider aparatları, Klemens, bağlantı kutusu, kablo ve kablolama işleri metal kondüit, Kablo tavası, kablo giriş çıkış işaretleri, Egzost borulaması, paslanmaz çelik boru ile yakıt tankı besleme-geri dönüş borulaması ve çevre ekipmanları, Havalık borulaması, soğutma suyu borulaması ve gideri, Kalıcı gider borulaması, Beton pompa kaidesi yapımı,(hariç) İşin tamamlanması için gerekli her türlü tesisat malzemesi, inşai kırma, delme ve onarım işleri, Tekniğine uygun işin yapımı için çalışmalar ve şartname gereklerine göre her türlü mühendislik hizmetleri, İşin gerçekleştirilmesi için her türlü çalışma. | C43: 1 | D43: SET
A44: 33 | B44: Pompaların ilk devrye Alımı ücretsiz olup.Talep dahilinde diğer servis daveti | C44: 0 | D44: Gün/Adam
A45: GENEL TOPLAM : | H45: =SUM(H11:H44) -> 388103

Sheet sprinkler
A10: SPRINKLER SİSTEMİ
A11: NO | B11: MALZEME ADI | C11: MİKTARI | D11: BİRİM | E11: MARKA | F11: ONAY | G11: İŞÇİLİK BF | H11: İŞÇİLİK TF
A12: A. FIRMA-C Entegre SAHA-ALTI Tesisi - Otomatik Sprinkler Sistemi Kurulumu
B13: Branşman Kelepçesi, DN150 x DN50 | C13: 0 | D13: Ad. | F13: UL/FM | G13: 0 | H13: =+G13*C13 -> 0
B14: Branşman Kelepçesi, DN50 x DN25 | C14: 0 | D14: Ad. | F14: UL/FM
B15: Sert Yivli Boru Bağlantı Kelepçesi, DN50 | C15: 0 | D15: Ad. | F15: UL/FM
A16: 1 | B16: Otomatik Sprinkler Kafası, (Sarkık K=240) Türü : ESFR K Faktörü : Metrik K=240 Montaj Biçimi : Sarkık Malzeme : Pirinç Açılma Sıcaklığı : 79ºC Sıcaklık Elemanı : Ergiyen Metalli veya Cam Tüplü Bağlantı : DN20 Dişli – Düşürücü Manşon ile Yedek : 10 Ad. (Dahil) – Orijinal Yedek Kutusu ve Spr. Anahtarı ile | C16: 9213 | D16: Ad. | F16: UL/FM | G16: 200 | H16: 1842000
A17: 2 | B17: Deneme ve Gider Vanası, DN32 veya DN50 K=240 Gözetleme Camı : Vardır Manometre : 0-20 Bar, Gliserinli ve Kesme Vanalı | C17: 26 | D17: Ad. | F17: UL/FM | G17: 600 | H17: 15600
A18: 3 | B18: Branşman Kelepçesi, DN150 x DN65 İşlevi : Borudan Branşman Almak Türü : Kelepçeli, Boru Üstü Deliğe Geçmeli Malzeme : Dökme Demir Kelepçe Contası : EPDM (Yangın Kullanımına Uygun) | C18: 998 | D18: Ad. | F18: UL/FM
A19: 4 | B19: Branşman Kelepçesi, DN65 x DN25 İşlevi : Borudan Branşman Almak Türü : Kelepçeli, Boru Üstü Deliğe Geçmeli Malzeme : Dökme Demir Kelepçe Contası : EPDM (Yangın Kullanımına Uygun) | C19: 9213 | D19: Ad. | F19: UL/FM
A20: 5 | B20: Esnek Yivli Boru Bağlantı Kelepçesi, DN150 | C20: 52 | D20: Ad. | F20: UL/FM
A21: 6 | B21: Sert Yivli Boru Bağlantı Kelepçesi, DN200 | C21: 1667 | D21: Ad. | F21: UL/FM
A22: 7 | B22: Sert Yivli Boru Bağlantı Kelepçesi, DN150 | C22: 3834 | D22: Ad. | F22: UL/FM
A23: 8 | B23: Sert Yivli Boru Bağlantı Kelepçesi, DN65 | C23: 11334 | D23: Ad. | F23: UL/FM
A24: 9 | B24: Dikişli Siyah Çelik Boru, DN200 - 5 MM | C24: 5000 | D24: m | F24: TSE | G24: 750 | H24: 3750000
A25: 10 | B25: Dikişli Siyah Çelik Boru, DN150 5 MM | C25: 6500 | D25: m | F25: TSE | G25: 675 | H25: 4387500
A26: 11 | B26: Dikişli Siyah Çelik Boru, DN65 | C26: 34000 | D26: m | F26: TSE | G26: 430 | H26: 14620000
A27: 12 | B27: Dikişli Siyah Çelik Boru, DN25 | C27: 10000 | D27: m | F27: TSE | G27: 270 | H27: 2700000
A28: 13 | B28: Yüksek Yoğunluklu Polietilen Boru, HDPE160 | C28: 30 | D28: m | F28: TSE | G28: 500 | H28: 15000
A29: 14 | B29: 4 Yollu Boru Askısı, DN150 Kullanım Amacı : Hiçbir Yöne Harekete Müsaade Etmeyen Askı, Borulamayı Sismik Hareketlere Karşı Korumak Sehpa Malzemesi : Galvanize Çelikten İmal Dayanım : En Az 9500 N Çekme Kuvvetine Dayanıklı Aksesuarlar : Ayarlama ve Kontra Somunu, Vida, Somun ve Tüm Montaj Elemanlarıyla | C29: 52 | D29: Ad. | F29: FM | G29: 400 | H29: 20800
A30: 15 | B30: 2 Yollu Boru Askısı, DN150 (Enine) | C30: 408 | D30: Ad. | F30: FM | G30: 300 | H30: 122400
A31: 16 | B31: 2 Yollu Boru Askısı, DN150 (Boyuna) | C31: 186 | D31: Ad. | F31: FM | G31: 300 | H31: 55800
A32: 17 | B32: Sprinkler Boru Askısı, DN150 | C32: 2413 | D32: Ad. | F32: TSE
A33: 18 | B33: Sprinkler Boru Askısı, DN65 | C33: 9213 | D33: Ad. | F33: TSE
A34: 19 | B34: Hat Sonu Yıkama Vanası, DN150 ,REDÜKTÖRLÜ,KV-7 | C34: 78 | D34: Ad. | F34: TSE
A35: 20 | B35: Kelebek Vana, DN150 Türü : Yivli veya Wafer Montaj Biçimi : Dik veya Yatay Açılma : Dişli Kutulu El Volanı ile Malzeme : Döküm Demir Gövdeli, Bronz Diskli Basınç Sınıfı : En Az 300 psi Gösterge : Konum Gösteren İbreli Aksesuarlar : TKÇY İzleme Anahtarı ve Sıkıştırma Vida Somunlarıyla Birlikte | C35: 78 | D35: Ad. | F35: UL/FM | G35: 3000 | H35: 234000
A36: 21 | B36: Akış Anahtarı, DN150 | C36: 78 | D36: Ad. | F36: UL/FM | G36: 1000 | H36: 78000
A37: 22 | B37: Yangın Hortum Dolabı, Yarı-Sert Hortumlu Türü : 1,5 mm DKP Sac Kapak ve Gövde, 6 kg ABC KKT Taşınabilir Söndürücü Giriş Çapı : DN50 Storz Kaplinli Vana ve DN50-DN25 Adaptör Hortum Çapı : DN25 Sert veya Yarı Sert (EN 694‘e Uygun) Hortum Uzunluğu : 30 m Nozul : Ayarlanabilir Renk : Kırmızı (RAL 3001) Montaj Tipi : Sıva Üstü | C37: 65 | D37: Ad. | F37: TSE, EN671-1 | G37: 2500 | H37: 162500
A38: 23 | B38: Islak Alarm Vanası, DN150 | C38: 26 | D38: Ad. | F38: UL/FM | G38: 7500 | H38: 195000
A39: 24 | B39: Kolektör, DN200 Çap : DN 200 Malzeme : Dikişli Siyah Çelik Boru Uzunluk : 4 m Basınç Sınıfı : PN 20 Standardı : TS EN 10217-1 İmalat : Antipas + 2 Kat Yağlı Boya + Her Türlü Duvara Asma Elemanıyla | C39: 6 | D39: Ad. | G39: 6000 | H39: 36000
A40: C. FIRMA-C Entegre SAHA-ALTI Eski Talaş Depo - Otomatik Sprinkler Sistemi Kurulumu
A41: 1 | B41: Otomatik Sprinkler Kafası, (Sarkık, K=115),68°C,BR | C41: 180 | D41: Ad. | F41: UL/FM | G41: 200 | H41: 36000
A42: 2 | B42: Deneme ve Gider Vanası, K=115, DN50 | C42: 1 | D42: Ad. | F42: UL/FM | G42: 1000 | H42: 1000
A43: 3 | B43: Branşman Kelepçesi, DN150 x DN50 | C43: 36 | D43: Ad. | F43: UL/FM
A44: 4 | B44: Esnek Yivli Boru Bağlantı Kelepçesi, DN150 | C44: 6 | D44: Ad. | F44: UL/FM
A45: 5 | B45: Sert Yivli Boru Bağlantı Kelepçesi, DN150 | C45: 51 | D45: Ad. | F45: UL/FM
A46: 6 | B46: Dişli Siyah Çelik Boru, DN50 | C46: 460 | D46: m | F46: TSE | G46: 380 | H46: 174800
A47: 7 | B47: Dikişli Siyah Çelik Boru, DN150 5 MM | C47: 152 | D47: m | F47: TSE | G47: 675 | H47: 102600
A48: 8 | B48: 4 Yollu Boru Askısı, DN150 | C48: 2 | D48: Ad. | F48: FM | G48: 400 | H48: 800
A49: 9 | B49: 2 Yollu Boru Askısı, DN150 (Enine) | C49: 10 | D49: Ad. | F49: FM | G49: 300 | H49: 3000
...

Sheet idari bina
A10: SPRINKLER SİSTEMİ
A11: NO | B11: MALZEME ADI | C11: MİKTARI | D11: BİRİM | E11: MARKA | F11: ONAYLAR | G11: İŞÇİLİK BF | H11: İŞÇİLİK TF
A12: B. FIRMA-C Entegre SAHA-ALTI İdari Bina Tesisi - Otomatik Sprinkler Sistemi Kurulumu
A13: 1 | B13: Otomatik Sprinkler Kafası, (Sarkık, K=80),BR | C13: 150 | D13: Ad. | F13: UL/FM | G13: 200 | H13: =+G13*C13 -> 30000
A14: 1 | B14: Otomatik Sprinkler Kafası, (Sarkık, K=80),WT | C14: 0 | D14: Ad. | F14: UL/FM
A15: 1 | B15: Sprinkler Flex ve seti,1"-500 | C15: 0 | F15: FM/VDS
A16: 1 | B16: Sprinkler Rozet-WT | C16: 0 | F16: UL/FM
A17: 2 | B17: Deneme ve Gider Vanası, K=80, DN32 | C17: 4 | D17: Ad. | F17: UL/FM | G17: 600 | H17: 2400
A18: 3 | B18: Branşman Kelepçesi, DN125 x DN25 | C18: 124 | D18: Ad. | F18: UL/FM
A19: 4 | B19: Branşman Kelepçesi, DN125 x DN32 | C19: 4 | D19: Ad. | F19: UL/FM
A20: 5 | B20: Branşman Kelepçesi, DN32 x DN25 | C20: 4 | D20: Ad. | F20: UL/FM
A21: 6 | B21: Branşman Kelepçesi, DN125 x DN40 | C21: 8 | D21: Ad. | F21: UL/FM
A22: 7 | B22: Branşman Kelepçesi, DN40 x DN25 | C22: 8 | D22: Ad. | F22: UL/FM
A23: 8 | B23: Esnek Yivli Boru Bağlantı Kelepçesi, DN125 | C23: 2 | D23: Ad. | F23: UL/FM
A24: 9 | B24: Sert Yivli Boru Bağlantı Kelepçesi, DN65 | C24: 15 | D24: Ad. | F24: UL/FM
A25: 10 | B25: Sert Yivli Boru Bağlantı Kelepçesi, DN80 | C25: 21 | D25: Ad. | F25: UL/FM
A26: 11 | B26: Sert Yivli Boru Bağlantı Kelepçesi, DN125 | C26: 4 | D26: Ad. | F26: UL/FM
A27: 12 | B27: Dikişli Siyah Çelik Boru, DN25 | C27: 390 | D27: m | F27: TSE | G27: 270 | H27: 105300
A28: 13 | B28: Dikişli Siyah Çelik Boru, DN32 | C28: 12 | D28: m | F28: TSE | G28: 300 | H28: 3600
A29: 14 | B29: Dikişli Siyah Çelik Boru, DN40 | C29: 16 | D29: m | F29: TSE | G29: 340 | H29: 5440
A30: 15 | B30: Dikişli Siyah Çelik Boru, DN50 | C30: 19 | D30: m | F30: TSE | G30: 380 | H30: 7220
A31: 16 | B31: Dikişli Siyah Çelik Boru, DN65 | C31: 45 | D31: m | F31: TSE | G31: 430 | H31: 19350
A32: 17 | B32: Dikişli Siyah Çelik Boru, DN80 | C32: 63 | D32: m | F32: TSE | G32: 480 | H32: 30240
A33: 18 | B33: Dikişli Siyah Çelik Boru, DN125 | C33: 10 | D33: m | F33: TSE | G33: 600 | H33: 6000
A34: 19 | B34: 4 Yollu Boru Askısı, DN125 | C34: 2 | D34: Ad. | F34: FM | G34: 400 | H34: 800
A35: 20 | B35: 2 Yollu Boru Askısı, DN40 (Enine) | C35: 3 | D35: Ad. | F35: FM | G35: 300 | H35: 900
A36: 21 | B36: 2 Yollu Boru Askısı, DN50 (Enine) | C36: 3 | D36: Ad. | F36: FM | G36: 300 | H36: 900
A37: 22 | B37: 2 Yollu Boru Askısı, DN65 (Enine) | C37: 4 | D37: Ad. | F37: FM | G37: 300 | H37: 1200
A38: 23 | B38: 2 Yollu Boru Askısı, DN80 (Enine) | C38: 9 | D38: Ad. | F38: FM | G38: 300 | H38: 2700
... A41: 26 | B41: 2 Yollu Boru Askısı, DN80 (Boyuna) | C41: 1 | D41: Ad. | F41: FM | G41: 300 | H41: 300
A42: 27 | B42: Sprinkler Boru Askısı, DN25 | C42: 140 | D42: Ad. | F42: TSE
A43: 28 | B43: Sprinkler Boru Askısı, DN32 | C43: 8 | D43: Ad. | F43: TSE
A44: 29 | B44: Sprinkler Boru Askısı, DN40 | C44: 4 | D44: Ad. | F44: TSE
A45: 30 | B45: Sprinkler Boru Askısı, DN50 | C45: 6 | D45: Ad. | F45: TSE
A46: 31 | B46: Sprinkler Boru Askısı, DN65 | C46: 8 | D46: Ad. | F46: TSE
A47: 32 | B47: Sprinkler Boru Askısı, DN80 | C47: 15 | D47: Ad. | F47: TSE
A48: 33 | B48: Kelebek Vana, DN125 | C48: 1 | D48: Ad. | F48: UL/FM | G48: 2500 | H48: 2500
A49: 34 | B49: Akış Anahtarı, DN125 | C49: 4 | D49: Ad. | F49: UL/FM | G49: 1000 | H49: 4000
A50: 35 | B50: Islak Alarm Vanası, DN125 | C50: 1 | D50: Ad. | F50: UL/FM | G50: 6000 | H50: 6000
A51: 36 | B51: Kolektör, DN150 | C51: 1 | D51: Ad. | E51: İMALAT | G51: 6000 | H51: 6000
...

Sheet metanol köpük
A9: METANOL TANKLARI OTOMATİK KÖPÜKLÜ SÖNDÜRME SİSTEMİ
A10: NO | B10: MALZEME ADI | C10: MİKTARI | D10: BİRİM | E10: MARKA | F10: ONAYLAR | G10: İŞÇİLİK BF | H10: İŞÇİLİK TF
A12: 0 | B12: Su Püskürtme Memesi, Foam Nozul Türü : Açık (Open),Aspirate Montaj Biçimi : pendent Malzeme : Pirinç Püskürtme Yapısı : Konik Bağlantı : 1/2" NPT K Faktörü : 41 Metrik (2.8 ANSI) | C12: 0 | D12: Ad | F12: UL/FM | G12: 0 | H12: =+G12*C12 -> 0
A13: 1 | B13: Su Püskürtme Memesi, Spray Nozul Türü : Açık (Open) Montaj Biçimi : açılı-yatay Malzeme : Pirinç Püskürtme Yapısı : Konik Bağlantı : 1/2" NPT K Faktörü : 40 Metrik (2.8 ANSI) | C13: 2 | D13: Ad | F13: UL/FM
A14: 2 | B14: Köpük Yapıcı (Foam Maker), Alçak Genleşmeli +Köpük dökücü ağız Türü : Hava Karışımlı (Aspirating) Hat Tipi (In-line) Çapı : DN65 (2 1/2”) Karışım Oranı : %3 SFFF Köpüklü Su Debisi : 43 – 226 Gpm @ 3-9 Bar Malzeme : Karbon Çeliği Kaplama : Dış Hava Korumalı (Epoksi Kaplamalı) | C14: 5 | D14: Ad | F14: UL/FM
A15: 3 | B15: Köpük Hücresi (Foam Chamber), Alçak Genleşmeli + Solid Deflector Türü : Sabit Tavanlı Tank Kenarı Tipi Çapı : DN65 (2 1/2”) Karışım Oranı : %3 SFFF Köpüklü Su Debisi : 36- 226 Gpm @ 30 psi Kurulum Biçimi : Dikey Malzeme : Karbon Çeliği Kaplama : Dış Hava Korumalı (Epoksi Kaplamalı) Aksesuar : Kırılabilir Cam, Orifis (Paslanmaz Çelik) | C15: 3 | D15: Ad | F15: UL/FM
A16: c | B16: Baskın Vana İstasyonu (Elektrik Tahrikli), DN100 (4”) Tür : Diyaframlı veya Klapeli Çapı : DN100 (4”) Tahrik Şekli : Elektrik ve Elle Kapanma : Elle Yerinden Bağlantı Türü : Yivli veya Flanşlı Yeniden Kurma : Tamamen Dışarıdan, Açmadan Basınç sınıfı : 175 psi Kurulum Biçimi : Dikey – Düz veya Açılı Tahrik Ünite : - Türü : Algılama Hattından : - Çalışma Şekli : Elektrik - Tüm Aparat (Trim)Leri ve Solenoid Vanası ile Elle Tahrik Ünitesi : - Türü : Küresel Vana : - Çapı : ½” : - Koruma Kutusu : Çelik Sac veya Onaylı Sert Plastik : - Renk : RAL 3000 Aksesuar : Her Türlü Aksamlarıyla (Trim) Birlikte : Giriş-Çıkış Manometreleri, Basınç Anahtarı ve Motor Gongu ile | C16: 1 | D16: Ad | F16: UL/FM
A17: 5 | B17: Baskın Vana İstasyonu (Elektrik Tahrikli), DN65 (2 1/2”) Yukarıdaki gibi ancak; Çapı : DN65 (2 1/2”) | C17: 3 | D17: Ad | F17: UL/FM
A18: 6 | B18: Kelebek Vana, DN150 Türü : Yivli veya Wafer veya Kulaklı (Lug Tipi) Giriş – Çıkış : Montaj Biçimi : Dik veya Yatay Açılma : Dişli Kutulu El Volanı ile Malzeme : Döküm Demir Gövdeli, Bronz Diskli Gösterge : Konum Gösteren İbreli Aksesuarlar : TKÇY İzleme Anahtarı ve Sıkıştırma Vida Somunlarıyla Birlikte | C18: 1 | D18: Ad | F18: UL/FM
A19: 7 | B19: Kelebek Vana, DN100 (4”) Yukarıdaki gibi ancak; Çap : DN100 (4”) | C19: 1 | D19: Ad | F19: UL/FM
A20: 8 | B20: Kelebek Vana, DN65 (2 1/2”) Yukarıdaki gibi ancak; Çap : DN65 (2 1/2”) | C20: 3 | D20: Ad | F20: UL/FM
A21: 9 | B21: Boru Desteği Türü : Rijit (U-Bolt veya Kelepçe) Kelepçe/U-Bolt Çapı : Muhtelif (DN150, DN100, DN80, DN65) Kelepçe Malzemesi : 2 mm Kalınlığında, 25 mm Eninde Galvanize Sacdan İmal Destek Malzemesi : Çelik C120 Profil (Ortalama 1 m Uzunluğunda) Sabitleme Malzemesi : M12 U-vida (U-bolt) Taşıyıcıya Tutturma : Beton Dübeli veya Taşıyıcıya Uygun Montaj Biçimi : Duvardan veya Çelik Profillerden Taşıyıcıya Tutturma : Taşıyıcıya Açılacak Deliklere Somun + Pul ve Kontra Somun + Pul Taşıma Kapasitesi : Borunun Su Dolu Ağırlığı + 115 kg Aksesuarlar : Ayarlama ve Kontra Somunu, Vida, Somun ve Taban Elemanı | C21: 150 | D21: Ad | F21: TSE
A22: 10 | B22: 4 Yollu Boru Askısı, DN65 (2 1/2”) Kullanım Amacı : Hiçbir Yöne Harekete İzin Vermeyen Askı, Borulamayı Sismik Hareketlere Karşı Korumak Sehpa Malzemesi : Galvanize Çelikten İmal Kelepçe Çapı : Taşıdığı Boru Çapına Eşit Dayanım : En Az 9500 N Çekme Kuvvetine Dayanıklı Aksesuarlar : Ayarlama ve Kontra Somunu, Vida, Somun ve Tüm Montaj Elemanlarıyla Birlikte | C22: 6 | D22: Ad | F22: FM
A23: 11 | B23: Sert Yivli Boru Bağlantı Kelepçesi, DN150 (6”) İşlevi : Borunun Boruya Bağlanmasını Sağlamak Türü : Sert (Rigid) Malzeme : Dökme Demir Çap : DN150 (6”) Kelepçe Contası : EPDM (Yangın Kullanımına Uygun) | C23: 4 | D23: Ad | F23: UL/FM
A24: 12 | B24: Sert Yivli Boru Bağlantı Kelepçesi, DN100 (4”) Yukarıdaki gibi ancak; Çap : DN100 (4”) | C24: 40 | D24: Ad | F24: UL/FM
A25: 13 | B25: Sert Yivli Boru Bağlantı Kelepçesi, DN65 (2 1/2”) | C25: 57 | D25: Ad | F25: UL/FM
A26: 14 | B26: Esnek Yivli Boru Bağlantı Kelepçesi, DN65 (2 1/2”) İşlevi : Borunun Boruya Bağlanmasını Sağlamak Türü : Esnek (Flexible) Malzeme : Dökme Demir Çap : DN65 (2 1/2”) Kelepçe Contası : EPDM (Yangın Kullanımına Uygun) Özellik : Model Numarası Yazan Ya Da Dışarıdan Tipi Anlaşılabilen | C26: 6 | D26: Ad | F26: UL/FM
A27: 15 | B27: Dikişli Siyah Çelik Boru, DN150 (6”) 5 MM Çap : DN150 (6”) Basınç Sınıfı : PN16 Standardı : TSE EN 10255 Orta Seri Yardımcı Malzeme : Boru Sistemi İçin Gerekli Her Türlü Dirsek, T, Flanş, Kaynak Vb. Dâhil İmalat : Siyah Çelik Üzeri Standartlara Uygun 1 Kat Antipas ve 2 Kat RAL 3000 Yağlı Boya | C27: 10 | D27: m | F27: TSE
A28: 16 | B28: Dikişli Siyah Çelik Boru, DN100 (4”) Yukarıdaki gibi ancak Çap : DN100 (4”) | C28: 120 | D28: m | F28: TSE
... A40: 28 | B40: Kelebek Vana, Saf Köpük Kullanımına Uygun yerine küresel vana kullanılmalı.Sistem tamalayıcısı olarak F2 halar vana mevcut olduğundan tamalayıcı unusr olarak eklenmiştir. Türü : Yivli, Flanşlı veya Dişli Giriş – Çıkış : DN80 Montaj Biçimi : Dik veya Yatay Açılma : Dişli Kutulu El Volanı ile Malzeme : Döküm Demir Gövdeli, Bronz Diskli Basınç Sınıfı : En Az 175 psi Gösterge : Konum Gösteren İbreli Aksesuarlar : TKÇY İzleme Anahtarı ve Sıkıştırma Vida Somunlarıyla Birlikte | C40: 2 | D40: Ad | F40: UL/FM
A41: 29 | B41: Borulamanın ve Tüm Çelik Konstrüksiyon Topraklaması İşlevi : Tüm Köpük Sisteminin Borulamasını Topraklamak | C41: 1 | D41: tk.
A42: 30 | B42: Yangın Söndürme Kontrol Paneli C-TEC EP203 | C42: 4 | D42: Ad | F42: LPCB
A43: 31 | B43: Söndürme Aktivasyon Butonu – C-TEC EP203 Paneli Uyumlu (Sarı Renk) | C43: 4 | D43: Ad | F43: LPCB
A44: 32 | B44: Söndürme Durdurma Butonu – C-TEC EP203 Paneli Uyumlu (Mavi Renk) | C44: 4 | D44: Ad | F44: LPCB
E45: GENEL TOPLAM : | H45: =SUM(H12:H44) -> 0

Sheet otomatik köpük
A9: OTOMATİK KÖPÜKLÜ SÖNDÜRME SİSTEMİ
A10: NO | B10: MALZEME ADI | C10: MİKTARI | D10: BİRİM | E10: MARKA | F10: ONAY | G10: İŞÇİLİK BF | H10: İŞÇİLİK TF
A11: 1. KOLLEKTÖR
B12: water foam sprinkler için metanol tarafında kırmızı layer ile belirtilen köpük sprinkler eklenmiştir.
A13: 1 | B13: Su Püskürtme Memesi, (Spray Nozzle) Türü : Açık (Open) Montaj Biçimi : Açılı veya Yatay Malzeme : Pirinç veya Çelik Püskürtme Yapısı : Konik Bağlantı : 1/2" NPT K Faktörü : 40 Metrik (2.8 ANSI) | C13: 12 | D13: Ad | E13: Viking | F13: UL/FM | G13: 0 | H13: =+G13*C13 -> 0
A14: 2 | B14: Baskın Vana İstasyonu (Elektrik Tahrikli), DN50 (2”) Tür : Diyaframlı veya Klapeli Çapı : DN50 (2”) Tahrik Şekli : Elektrik ve Elle Kapanma : Elle Yerinden Bağlantı Türü : Yivli veya Flanşlı Yeniden Kurma : Tamamen Dışarıdan, Açmadan Basınç sınıfı : 175 psi Kurulum Biçimi : Dikey – Düz veya Açılı Tahrik Ünite : - Türü : Algılama Hattından : - Çalışma Şekli : Elektrik - Tüm Aparat (Trim)Leri ve Solenoid Vanası ile Elle Tahrik Ünitesi : - Türü : Küresel Vana : - Çapı : ½” : - Koruma Kutusu : Çelik Sac veya Onaylı Sert Plastik : - Renk : RAL 3000 Aksesuar : Her Türlü Aksamlarıyla (Trim) Birlikte : Giriş-Çıkış Manometreleri, Basınç Anahtarı ve Motor Gongu ile | C14: 6 | D14: Ad | E14: Viking | F14: UL/FM
A15: 3 | B15: Kelebek Vana, DN80 (3”) Türü : Yivli veya Wafer veya Kulaklı (Lug Tipi) Giriş – Çıkış : DN80 (3”) Montaj Biçimi : Dik veya Yatay Açılma : Dişli Kutulu El Volanı ile Malzeme : Döküm Demir Gövdeli, Bronz Diskli Gösterge : Konum Gösteren İbreli Aksesuarlar : TKÇY İzleme Anahtarı ve Sıkıştırma Vida Somunlarıyla Birlikte | C15: 1 | D15: Ad | E15: Viking | F15: UL/FM
A16: 4 | B16: Kelebek Vana, DN50 (2”) Yukarıdaki gibi ancak; Çap : DN50 (2”) | C16: 1 | D16: Ad | E16: Viking | F16: UL/FM
A17: 5 | B17: Boru Desteği Türü : Rijit (U-Bolt veya Kelepçe) Kelepçe/U-Bolt Çapı : Muhtelif (DN100, DN80, DN65) Kelepçe Malzemesi : 2 mm Kalınlığında, 25 mm Eninde Galvanize Sacdan İmal Destek Malzemesi : Çelik C120 Profil (Ortalama 1 m Uzunluğunda) Sabitleme Malzemesi : M12 U-vida (U-bolt) Taşıyıcıya Tutturma : Beton Dübeli veya Taşıyıcıya Uygun Montaj Biçimi : Duvardan veya Çelik Profillerden Taşıyıcıya Tutturma : Taşıyıcıya Açılacak Deliklere Somun + Pul ve Kontra Somun + Pul Taşıma Kapasitesi : Borunun Su Dolu Ağırlığı + 115 kg Aksesuarlar : Ayarlama ve Kontra Somunu, Vida, Somun ve Taban Elemanı | C17: 334 | D17: Ad | E17: Norm | F17: TSE
A18: 6 | B18: 4 Yollu Boru Askısı, DN50 (2”) Kullanım Amacı : Hiçbir Yöne Harekete İzin Vermeyen Askı, Borulamayı Sismik Hareketlere Karşı Korumak Sehpa Malzemesi : Galvanize Çelikten İmal Kelepçe Çapı : Taşıdığı Boru Çapına Eşit Dayanım : En Az 9500 N Çekme Kuvvetine Dayanıklı Aksesuarlar : Ayarlama ve Kontra Somunu, Vida, Somun ve Tüm Montaj Elemanlarıyla Birlikte | C18: 12 | D18: Ad | E18: Hilti | F18: UL/FM
A19: 7 | B19: Esnek Yivli Boru Bağlantı Kelepçesi, DN50 (2”) İşlevi : Borunun Boruya Bağlanmasını Sağlamak Türü : Esnek (Flexible) Malzeme : Dökme Demir Çap : DN50 (2”) Kelepçe Contası : EPDM (Yangın Kullanımına Uygun) Özellik : Model Numarası Yazan Ya Da Dışarıdan Tipi Anlaşılabilen | C19: 12 | D19: Ad | E19: Victaulic | F19: UL/FM
A20: 8 | B20: 2 Yollu Boru Askısı, (Enine) Kullanım Amacı : Tek Yönlü Harekete Müsaade Eden Askı, Borulamayı Sismik Hareketlere Karşı Korumak Sehpa Malzemesi : Galvanize Çelik Askı Çubuğu : DN 25 Boru Boruya Tutturma : Çelik U-Vida (U-Bolt) Aksesuarlar : Çelik Konstrüksiyon için Evrensel Bağlantı Elemanları, Ayarlama ve Kontra Somunu, Vida, Somun ve Tüm Montaj Elemanlarıyla Birlikte | C20: 42 | D20: Ad | E20: Hilti | F20: UL/FM
A21: 9 | B21: 2 Yollu Boru Askısı, (Boyuna) Kullanım Amacı : Tek Yönlü Harekete Müsaade Eden Askı, Borulamayı Sismik Hareketlere Karşı Korumak Sehpa Malzemesi : Galvanize Çelik Askı Çubuğu : DN 25 Boru Boruya Tutturma : Ağır Yük Kelepçesi Dayanım : En Az 9500 N Çekme Kuvvetine Dayanıklı Aksesuarlar : Çelik Konstrüksiyon için Evrensel Bağlantı Elemanları, Ayarlama ve Kontra Somunu, Vida, Somun ve Tüm Montaj Elemanlarıyla Birlikte | C21: 19 | D21: Ad | E21: Hilti | F21: UL/FM
A22: 10 | B22: Sprinkler Boru Askısı Türü : Fabrikasyon Kelepçe veya Armut Sprinkler Askısı Armut Çapı : Muhtelif (DN 150, DN 80, DN 65, DN 50, DN 40, DN 32, DN 25) Kelepçe Malzemesi : 2 mm Kalınlığında, 25 mm Eninde Galvanize Sacdan İmal Askı Çubuğu : M10 Taşıyıcıya Tutturma : Beton Dübelli ve/veya Kiriş Kenedi + Muhafaza Bandı Malzeme : %0,6 Elektrogalvaniz Kaplı Çelik Taşıma Kapasitesi : Borunun Su Dolu Ağırlığı + 115 kg Aksesuarlar : Ayarlama ve Kontra Somunu, Vida, Somun ve Taban Elemanı, Muhafaza Bandı | C22: 100 | D22: Ad | E22: Norm | F22: TSE
A23: 11 | B23: Dikişli Siyah Çelik Boru, DN50 (2”) Çap : DN50 (2”) Basınç Sınıfı : PN16 Standardı : TSE EN 10255 Orta Seri Yardımcı Malzeme : Boru Sistemi İçin Gerekli Her Türlü Dirsek, T, Flanş, Kaynak Vb. Dâhil İmalat : Siyah Çelik Üzeri Standartlara Uygun 1 Kat Antipas ve 2 Kat RAL 3000 Yağlı Boya | C23: 1000 | D23: m | E23: Çayırova | F23: TSE
A24: 12 | B24: Kolektör Revizyonu (DN150) Çap : DN150 (6”) Malzeme : Dikişli Siyah Çelik Boru Boy : 4 m Giriş-Çıkış : 1HDPE180 Giriş + 1xDN50(2”) Flanşlı Çıkış + 1Xdn50(2”) Flanşlı Çıkış Basınç Sınıfı : PN16 Standardı : TS EN 10217-1, En Az 5,4 mm Et Kalınlıklı İmalat : Antipas + 2 Kat Yağlı Boya + Her Türlü Duvara Asma Elemanı ile | C24: 1 | D24: Ad | E24: İmalat | F24: TSE
A25: 13 | B25: Yeni Köpük Kolektörü (DN100) (4”) Çap : DN100 (4”) Malzeme : Dikişli Siyah Çelik Boru Boy : 4 m Giriş-Çıkış : 1xDN50(2”) Giriş + 6xDN50(2”) Flanşlı Çıkış + Basınç Sınıfı : PN16 Standardı : TS EN 10217-1, En Az 5,4 mm Et Kalınlıklı İmalat : Antipas + 2 Kat Yağlı Boya + Her Türlü Duvara Asma Elemanı ile | C25: 1 | D25: Ad | E25: İmalat | F25: TSE
... A33: 21 | B33: Küresel Vana, Saf Köpük Kullanımına Uygun Türü : Yivli, Flanşlı veya Dişli Giriş – Çıkış : DN50 Montaj Biçimi : Dik veya Yatay Açılma : Dişli Kutulu El Volanı ile Malzeme : Döküm Demir Gövdeli, Bronz Diskli Basınç Sınıfı : En Az 175 psi Gösterge : Konum Gösteren İbreli Aksesuarlar : TKÇY İzleme Anahtarı ve Sıkıştırma Vida Somunlarıyla Birlikte | C33: 2 | D33: Ad | E33: Viking | F33: UL/FM
A34: 22 | B34: Borulamanın ve Tüm Çelik Konstrüksiyon Topraklaması İşlevi : Tüm Köpük Sisteminin Borulamasını Topraklamak | C34: 1 | D34: tk. | E34: EA
A35: 2. KOLLEKTÖR
A36: 1 | B36: Su Püskürtme Memesi, (Spray Nozzle) Türü : Açık (Open) Montaj Biçimi : Açılı veya Yatay Malzeme : Pirinç veya Çelik Püskürtme Yapısı : Konik Bağlantı : 1/2" NPT K Faktörü : 40 Metrik (2.8 ANSI) | C36: 6 | D36: Ad | E36: Viking | F36: UL/FM
A37: 2 | B37: Baskın Vana İstasyonu (Elektrik Tahrikli), DN50 (2”) Tür : Diyaframlı veya Klapeli Çapı : DN50 (2”) Tahrik Şekli : Elektrik ve Elle Kapanma : Elle Yerinden Bağlantı Türü : Yivli veya Flanşlı Yeniden Kurma : Tamamen Dışarıdan, Açmadan Basınç sınıfı : 175 psi Kurulum Biçimi : Dikey – Düz veya Açılı Tahrik Ünite : - Türü : Algılama Hattından : - Çalışma Şekli : Elektrik - Tüm Aparat (Trim)Leri ve Solenoid Vanası ile Elle Tahrik Ünitesi : - Türü : Küresel Vana : - Çapı : ½” : - Koruma Kutusu : Çelik Sac veya Onaylı Sert Plastik : - Renk : RAL 3000 Aksesuar : Her Türlü Aksamlarıyla (Trim) Birlikte : Giriş-Çıkış Manometreleri, Basınç Anahtarı ve Motor Gongu ile | C37: 2 | D37: Ad | E37: Viking | F37: UL/FM
A38: 3 | B38: Kelebek Vana, DN50 (3”) Türü : Yivli veya Wafer veya Kulaklı (Lug Tipi) Giriş – Çıkış : DN50 (2”) Montaj Biçimi : Dik veya Yatay Açılma : Dişli Kutulu El Volanı ile Malzeme : Döküm Demir Gövdeli, Bronz Diskli Gösterge : Konum Gösteren İbreli Aksesuarlar : TKÇY İzleme Anahtarı ve Sıkıştırma Vida Somunlarıyla Birlikte | C38: 2 | D38: Ad | E38: Viking | F38: UL/FM
A39: 4 | B39: Kelebek Vana, DN50 (2”) Yukarıdaki gibi ancak; Çap :Dn50(2”) | C39: 4 | D39: Ad | E39: Viking | F39: UL/FM
A40: 5 | B40: Boru Desteği Türü : Rijit (U-Bolt veya Kelepçe) Kelepçe/U-Bolt Çapı : Muhtelif (DN100, DN80, DN65) Kelepçe Malzemesi : 2 mm Kalınlığında, 25 mm Eninde Galvanize Sacdan İmal Destek Malzemesi : Çelik C120 Profil (Ortalama 1 m Uzunluğunda) Sabitleme Malzemesi : M12 U-vida (U-bolt) Taşıyıcıya Tutturma : Beton Dübeli veya Taşıyıcıya Uygun Montaj Biçimi : Duvardan veya Çelik Profillerden Taşıyıcıya Tutturma : Taşıyıcıya Açılacak Deliklere Somun + Pul ve Kontra Somun + Pul Taşıma Kapasitesi : Borunun Su Dolu Ağırlığı + 115 kg Aksesuarlar : Ayarlama ve Kontra Somunu, Vida, Somun ve Taban Elemanı | C40: 3 | D40: Ad | E40: Norm | F40: TSE
A41: 6 | B41: 4 Yollu Boru Askısı, DN50 (2”) Kullanım Amacı : Hiçbir Yöne Harekete İzin Vermeyen Askı, Borulamayı Sismik Hareketlere Karşı Korumak Sehpa Malzemesi : Galvanize Çelikten İmal Kelepçe Çapı : Taşıdığı Boru Çapına Eşit Dayanım : En Az 9500 N Çekme Kuvvetine Dayanıklı Aksesuarlar : Ayarlama ve Kontra Somunu, Vida, Somun ve Tüm MontajElemanlarıyla Birlikte | C41: 2 | D41: Ad | E41: Hilti | F41: UL/FM
A42: 7 | B42: Esnek Yivli Boru Bağlantı Kelepçesi, DN100 (4”) İşlevi : Borunun Boruya Bağlanmasını Sağlamak Türü : Esnek (Flexible) Malzeme : Dökme Demir Çap : DN100 (4”) Kelepçe Contası : EPDM (Yangın Kullanımına Uygun) Özellik : Model Numarası Yazan Ya Da Dışarıdan Tipi Anlaşılabilen | C42: 2 | D42: Ad | E42: Victaulic | F42: UL/FM
A43: 8 | B43: Sprinkler Boru Askısı Türü : Fabrikasyon Kelepçe veya Armut Sprinkler Askısı Armut Çapı : Muhtelif (DN 150, DN 80, DN 65, DN 50, DN 40, DN 32, DN 25) Kelepçe Malzemesi : 2 mm Kalınlığında, 25 mm Eninde Galvanize Sacdan İmal Askı Çubuğu : M10 Taşıyıcıya Tutturma : Beton Dübelli ve/veya Kiriş Kenedi + Muhafaza Bandı Malzeme : %0,6 Elektrogalvaniz Kaplı Çelik Taşıma Kapasitesi : Borunun Su Dolu Ağırlığı + 115 kg Aksesuarlar : Ayarlama ve Kontra Somunu, Vida, Somun ve Taban Elemanı, Muhafaza Bandı | C43: 8 | D43: Ad | E43: Norm | F43: TSE
A44: 9 | B44: Dikişli Siyah Çelik Boru, DN50 (2”) Çap : DN50 (2”) Basınç Sınıfı : PN16 Standardı : TSE EN 10255 Orta Seri Yardımcı Malzeme : Boru Sistemi İçin Gerekli Her Türlü Dirsek, T, Flanş, Kaynak Vb. Dâhil İmalat : Siyah Çelik Üzeri Standartlara Uygun 1 Kat Antipas ve 2 Kat RAL 3000 Yağlı Boya | C44: 120 | D44: m | E44: Çayırova | F44: TSE
A45: 10 | B45: Kolektör Revizyonu (DN150) Çap : DN150 (6”) Malzeme : Dikişli Siyah Çelik Boru Boy : 4 m Giriş-Çıkış : 1HDPE160 Giriş + 1xDN50(2”) Flanşlı Çıkış + 1xDN50(2”) Flanşlı Çıkış Basınç Sınıfı : PN16 Standardı : TS EN 10217-1, En Az 5,4 mm Et Kalınlıklı İmalat : Antipas + 2 Kat Yağlı Boya + Her Türlü Duvara Asma Elemanı ile | C45: 1 | D45: Ad | E45: İmalat | F45: TSE
A46: 11 | B46: Yeni Köpük Kolektörü (DN100) Çap : DN100 (4”) Malzeme : Dikişli Siyah Çelik Boru Boy : 4 m Giriş-Çıkış : 1xDN50(2”) Giriş + 2xDN50(2”) Flanşlı Çıkış Basınç Sınıfı : PN16 Standardı : TS EN 10217-1, En Az 5,4 mm Et Kalınlıklı İmalat : Antipas + 2 Kat Yağlı Boya + Her Türlü Duvara Asma Elemanı ile | C46: 1 | D46: Ad | E46: İmalat | F46: TSE
A47: 12 | B47: Küresel Vana, DN25 (1”) Giriş-Çıkış : DN25 (1”), Dişli Tip : Paslanmaz Çelik Küresel, Tam Geçişli Tahrik : 90, Kollu Aksesuar : Amacını Gösteren İşaret Plakası ve İşaretlemelerle Birlikte | C47: 2 | D47: Ad | E47: Ayvaz | F47: TSE
... A54: 19 | B54: Kelebek Vana, Saf Köpük Kullanımına Uygun Türü : Yivli, Flanşlı veya Dişli Giriş – Çıkış : DN50 Montaj Biçimi : Dik veya Yatay Açılma : Dişli Kutulu El Volanı ile Malzeme : Döküm Demir Gövdeli, Bronz Diskli Basınç Sınıfı : En Az 175 psi Gösterge : Konum Gösteren İbreli Aksesuarlar : TKÇY İzleme Anahtarı ve Sıkıştırma Vida Somunlarıyla Birlikte | C54: 2 | D54: Ad | E54: Viking | F54: UL/FM
A55: 20 | B55: Borulamanın ve Tüm Çelik Konstrüksiyon Topraklaması İşlevi : Tüm Köpük Sisteminin Borulamasını Topraklamak | C55: 1 | D55: tk. | E55: EA
A56: 3. KOLLEKTÖR
A57: 1 | B57: Su Püskürtme Memesi, (Spray Nozzle) Türü : Açık (Open) Montaj Biçimi : Açılı veya Yatay Malzeme : Pirinç veya Çelik Püskürtme Yapısı : Konik Bağlantı : 1/2" NPT K Faktörü : 40 Metrik (2.8 ANSI) | C57: 72 | D57: Ad | E57: Viking | F57: UL/FM
A58: 2 | B58: Baskın Vana İstasyonu (Elektrik Tahrikli), DN100 (4”) 1 ad. Tür : Diyaframlı veya Klapeli Çapı : DN100 (4”) Tahrik Şekli : Elektrik ve Elle Kapanma : Elle Yerinden Bağlantı Türü : Yivli veya Flanşlı Yeniden Kurma : Tamamen Dışarıdan, Açmadan Basınç sınıfı : 175 psi Kurulum Biçimi : Dikey – Düz veya Açılı Tahrik Ünite : - Türü : Algılama Hattından : - Çalışma Şekli : Elektrik - Tüm Aparat (Trim)Leri ve Solenoid Vanası ile Elle Tahrik Ünitesi : - Türü : Küresel Vana : - Çapı : ½” : - Koruma Kutusu : Çelik Sac veya Onaylı Sert Plastik : - Renk : RAL 3000 Aksesuar : Her Türlü Aksamlarıyla (Trim) Birlikte Giriş-Çıkış Manometreleri, Basınç Anahtarı ve Motor Gongu ile | C58: 1 | D58: Ad | E58: Viking | F58: UL/FM
A59: 3 | B59: Kelebek Vana, DN80 (3”) Türü : Yivli veya Wafer veya Kulaklı (Lug Tipi) Giriş – Çıkış : DN80 (3”) Montaj Biçimi : Dik veya Yatay Açılma : Dişli Kutulu El Volanı ile Malzeme : Döküm Demir Gövdeli, Bronz Diskli Gösterge : Konum Gösteren İbreli Aksesuarlar : TKÇY İzleme Anahtarı ve Sıkıştırma Vida Somunlarıyla Birlikte | C59: 2 | D59: Ad | E59: Viking | F59: UL/FM
A60: 4 | B60: Kelebek Vana, DN50 (2”) Yukarıdaki gibi ancak; Çap : DN50 (2”) | C60: 2 | D60: Ad | E60: Viking | F60: UL/FM
A61: 5 | B61: Boru Desteği Türü : Rijit (U-Bolt veya Kelepçe) Kelepçe/U-Bolt Çapı : Muhtelif (DN100, DN80, DN65) Kelepçe Malzemesi : 2 mm Kalınlığında, 25 mm Eninde Galvanize Sacdan İmal Destek Malzemesi : Çelik C120 Profil (Ortalama 1 m Uzunluğunda) Sabitleme Malzemesi : M12 U-vida (U-bolt) Taşıyıcıya Tutturma : Beton Dübeli veya Taşıyıcıya Uygun Montaj Biçimi : Duvardan veya Çelik Profillerden Taşıyıcıya Tutturma : Taşıyıcıya Açılacak Deliklere Somun + Pul ve Kontra Somun + Pul Taşıma Kapasitesi : Borunun Su Dolu Ağırlığı + 115 kg Aksesuarlar : Ayarlama ve Kontra Somunu, Vida, Somun ve Taban Elemanı | C61: 23 | D61: Ad | E61: Norm | F61: TSE
...

Sheet konveyör
A9: KONVEYÖR SULU SÖNDÜRME SİSTEMİ
A10: NO | B10: MALZEME ADI | C10: MİKTARI | D10: BİRİM | E10: MARKA | F10: ONAYLAR | G10: İŞÇİLİK BF | H10: İŞÇİLİK TF
B11: Basınç Düşürücü & sabitleyici Vana DN100,F x F CLASS150 | C11: 0 | D11: Ad | H11: =+G11*C11 -> 0
B12: Su Püskürtme Memesi, (Spray Nozzle) Türü : Açık (Open) Montaj Biçimi : Açılı veya Yatay Malzeme : Pirinç veya Çelik Püskürtme Yapısı : Konik Bağlantı : 1/2" NPT K Faktörü : 41 | C12: 0 | D12: Ad | F12: UL/FM
A13: 14 | B13: Kelebek Vana, DN100 | C13: 0 | D13: Ad. | F13: UL/FM
B14: Baskın Vana İstasyonu (Elektrik Tahrikli), DN100 (4”) Tür : Diyaframlı veya Klapeli Çapı : DN100 (4”) Tahrik Şekli : Elektrik ve Elle Kapanma : Elle Yerinden Bağlantı Türü : Yivli veya Flanşlı Yeniden Kurma : Tamamen Dışarıdan, Açmadan Basınç sınıfı : 175 psi Kurulum Biçimi : Dikey – Düz veya Açılı Tahrik Ünite : - Türü : Algılama Hattından : - Çalışma Şekli : Elektrik - Tüm Aparat (Trim)Leri ve Solenoid Vanası ile Elle Tahrik Ünitesi : - Türü : Küresel Vana : - Çapı : ½” : - Koruma Kutusu : Çelik Sac veya Onaylı Sert Plastik : - Renk : RAL 3000 Aksesuar : Her Türlü Aksamlarıyla (Trim) Birlikte : Giriş-Çıkış Manometreleri, Basınç Anahtarı ve Motor Gongu ile | C14: 0 | D14: Ad | F14: UL/FM
B15: Basınç Düşürücü Vana 4" Çalışma Basıncı : 300 PSI (20,68 bar) Çalışma Sıcaklığı : 80 ºC Ayar Sahası : 30-165 PSI (2,0-11,3 bar) Gövde : Demir Döküm Bağlantı : Yivli | C15: 0 | D15: Ad. | F15: UL/FM
B16: Kolektör, DN150 | C16: 0 | D16: Ad. | E16: İMALAT
A17: A. 1255 Konveyör Bandı- Otomatik Sprinkler Sistemi Kurulumu
A18: 1 | B18: Otomatik Sprinkler Kafası, Standart Tepkili (Sarkık, K=115) | C18: 22 | D18: Ad. | F18: UL/FM | G18: 200 | H18: 4400
A19: 2 | B19: Deneme ve Gider Vanası, DN40, K=115 | C19: 1 | D19: Ad. | F19: UL/FM | G19: 800 | H19: 800
A20: 3 | B20: Branşman Kelepçesi, DN80 x DN32 | C20: 2 | D20: Ad. | F20: UL/FM
A21: 4 | B21: Branşman Kelepçesi, DN32 x DN15 | C21: 22 | D21: Ad. | F21: UL/FM
A22: 5 | B22: Esnek Yivli Boru Bağlantı Kelepçesi, DN80 | C22: 2 | D22: Ad. | F22: UL/FM
A23: 6 | B23: Sert Yivli Boru Bağlantı Kelepçesi, DN80 | C23: 40 | D23: Ad. | F23: UL/FM
A24: 7 | B24: Yivli Çelik Boru, DN80 | C24: 120 | D24: m | F24: TSE | G24: 480 | H24: 57600
A25: 8 | B25: Yivli Çelik Boru, DN32 | C25: 80 | D25: m | F25: TSE | G25: 300 | H25: 24000
A26: 9 | B26: 4 Yollu Boru Askısı, DN80 | C26: 2 | D26: Ad. | F26: FM | G26: 400 | H26: 800
A27: 10 | B27: 2 Yollu Boru Askısı, DN80 (Enine) | C27: 5 | D27: Ad. | F27: FM | G27: 300 | H27: 1500
A28: 11 | B28: 2 Yollu Boru Askısı, DN80 (Boyuna) | C28: 3 | D28: Ad. | F28: FM | G28: 300 | H28: 900
A29: 12 | B29: Sprinkler Boru Askısı | C29: 47 | D29: Ad. | F29: TSE
A30: 13 | B30: Hat Sonu Yıkama Vanası, DN80 ,REDÜKTÖRLÜ,KV-7 | C30: 2 | D30: Ad. | F30: TSE | G30: 1800 | H30: 3600
A31: 14 | B31: Kelebek Vana, DN80 (1275 Numaralı Konveyör ile Ortak) | C31: 1 | D31: Ad. | F31: UL/FM | G31: 1800 | H31: 1800
A32: 15 | B32: Akış Anahtarı, DN80 (1275 Numaralı Konveyör ile Ortak) | C32: 1 | D32: Ad. | F32: UL/FM | G32: 1800 | H32: 1800
A33: 16 | B33: Islak Alarm Vanası, DN80 (1275 Numaralı Konveyör ile Ortak) | C33: 1 | D33: Ad. | F33: UL/FM | G33: 4500 | H33: 4500
A34: 17 | B34: Kolektör, DN100 (1275 Numaralı Konveyör ile Ortak) | C34: 1 | D34: Ad. | G34: 1000 | H34: 1000
A35: B. 1275 Konveyör Bandı - Otomatik Sprinkler Sistemi Kurulumu
A36: 1 | B36: Otomatik Sprinkler Kafası, Standart Tepkili (Sarkık, K=115) | C36: 17 | D36: Ad. | F36: UL/FM
A37: 2 | B37: Deneme ve Gider Vanası, DN40, K=115 | C37: 1 | D37: Ad. | F37: UL/FM
A38: 3 | B38: Branşman Kelepçesi, DN80 x DN32 | C38: 2 | D38: Ad. | F38: UL/FM
A39: 4 | B39: Branşman Kelepçesi, DN32 x DN15 | C39: 22 | D39: Ad. | F39: UL/FM
A40: 5 | B40: Esnek Yivli Boru Bağlantı Kelepçesi, DN80 | C40: 2 | D40: Ad. | F40: UL/FM
A41: 6 | B41: Sert Yivli Boru Bağlantı Kelepçesi, DN80 | C41: 34 | D41: Ad. | F41: UL/FM
A42: 7 | B42: Yivli Çelik Boru, DN80 | C42: 100 | D42: m | F42: TSE
A43: 8 | B43: Yivli Çelik Boru, DN32 | C43: 60 | D43: m | F43: TSE
A44: 9 | B44: 4 Yollu Boru Askısı, DN80 | C44: 2 | D44: Ad. | F44: FM
A45: 10 | B45: 2 Yollu Boru Askısı, DN80 (Enine) | C45: 5 | D45: Ad. | F45: FM
A46: 11 | B46: 2 Yollu Boru Askısı, DN80 (Boyuna) | C46: 3 | D46: Ad. | F46: FM
A47: 12 | B47: Sprinkler Boru Askısı | C47: 29 | D47: Ad. | F47: TSE
... A51: 16 | B51: Islak Alarm Vanası, DN80 (1255 Numaralı Konveyör ile Ortak) | C51: 1 | D51: Ad. | F51: UL/FM
...

Sheet yangin durdurucu
A13: YANGIN DURDURUCU
A14: NO | B14: MALZEME ADI | C14: MİKTARI | D14: BİRİM | E14: MARKA | F14: İŞÇİLİK BF | G14: İŞÇİLİK TF
A15: 2 | B15: Akrilik Mastik CP 606 580ml INT gri | C15: 120 | D15: Ad. | F15: 0 | G15: =+F15*C15 -> 0
A16: 3 | B16: İntümesan Mastik FS-ONE MAX 20.0OZ FOI | C16: 42 | D16: Ad.
A17: 4 | B17: Köpük CP 660 INT | C17: 144 | D17: Ad.
A18: 5 | B18: Harç CP 636 20KG | C18: 33 | D18: Ad.
A19: 6 | B19: Sonsuz sargı CP 648-E-W45/1.8" | C19: 12 | D19: Ad.
A20: 7 | B20: Panel Boyası CP 673 17,5kg | C20: 15 | D20: Ad.
A21: GENEL TOPLAM : | G21: =SUM(G15:G20) -> 0
