Workbook
Name ABD_271125: #REF!
Name AD_271125: #REF!
Name ATEKSİS_061225: #REF!
Name AVRP_271125: #REF!
Name BAKİ_031225: #REF!
Name BORUSANDİŞ_031225: #REF!
Name BORUSANYİV_031225: #REF!
Name BOYA_031225: #REF!
Name BURİNOKS_031225: #REF!
Name CLAVAL_031225: #REF!
Name FETAŞ_031225: #REF!
Name GALVDİŞFİT_031225: #REF!
Name GALVFİT_031225: #REF!
Name HAKAN_031225: #REF!
Name HDPEFİT_031225: #REF!
Name İGG_271125: #REF!
Name İŞÇL_271125: #REF!
Name KAYSE_051225: #REF!
Name KOLLEKTÖR_031225: #REF!
Name KONSOL_031225: #REF!
Name LİNK_051225: #REF!
Name MGG_271125: #REF!
Name PASLFİT_031225: #REF!
Name PATTERSON_031225: #REF!
Name PLT_031225: #REF!
Name SİYAHDİŞFİT_031225: #REF!
Name SİYAHYİVFİT_031225: #REF!
Name TYCO_031225: #REF!
Name VİCTAULİC_031225: #REF!
Name VİKİNG_260126: [1]Degişken!$E$30
Name WİKİNG_031225: #REF!
Name YRL_271125: #REF!
Name ZEKA_031225: #REF!
Name ZETTLER_031225: #REF!

Sheet İcmal
B2: FIRMA-C ENTEGRE SAHA-UC TEİSİSİ YANGIN TESİSATI
B5: FİRMA: | D5: FIRMA-C ENTEGRE
B6: İLGİLİ: | D6: HASAN SEVİNDİK
B7: KONU: | D7: YANGIN TESİSATI
B8: TARİH:
B9: TEKLİF NO:
B10: ADRES: | D10: KOCAELİ/SAHA-UC
B11: S.N | C11: AÇIKLAMA | E11: İŞÇİLİK TOPLAM
B12: 1 | C12: Yangın Pompası | E12: =Yangın.Pompa.Odası!G244 -> 270850
B13: 2 | C13: Hidrant Sistemi | D13: Otomatik Sprinkler | E13: =Hidrant.Sistemi!G150 -> 8303150
B14: 3 | C14: Pres2-3 Çelik Kule Yangın Dolabı | E14: ='Pres2-3 Çelik Kule'!F17 -> 1153500
B15: 4 | C15: Trafo Su Püskürtme Sistemi | D15: Otomatik Sprinkler | E15: =Trafo.Su.Püskürtme!G176 -> 751120
B16: 5 | C16: Otomatik Sprinkler Sistemi | D16: Otomatik Sprinkler | E16: =Sprinkler.Sistemi!G78 -> 49111550
B17: 6 | C17: Konveyör Sprinkler Sistemi | D17: Otomatik Sprinkler | E17: =Konveyör.Sprink!H284 -> 2343160
B18: 7 | C18: Toz Ambarı Södürme Sistemi | D18: Otomatik Sprinkler | E18: =Toz.Ambarı!G71 -> 92190
B19: 8 | C19: Pompa Odası Söndürme Sistemi | D19: Otomatik Sprinkler | E19: =Pompa.Odası.Sprink!H20 -> 18180
B20: 9 | C20: Otomatik Köpüklü Söndürme Sistemi | D20: Otomatik Sprinkler | E20: =Otomatik.Köpüklü!G735 -> 0
B21: 11 | C21: Pasif Yangın Durdurucu | E21: =Yangın.Durdurucu!H16 -> 0
B22: Genel Toplam | E22: =SUM(E12:E21) -> 62043700
B24: NOTLAR ;

Sheet Yangın.Pompa.Odası
B2: FIRMA-C ENTEGRE SAHA-UC YANGIN TESİSATI TEKLİFİ
B7: No | C7: YANGIN POMPA ODASI | D7: Miktar | E7: Birim | F7: BİRİM FİYAT İŞÇİLİK | G7: TOPLAM FİYAT İŞÇİLİK
B10: 1 | C10: Dizel Motorlu Yangın Pompası | D10: 2 | E10: Adet | F10: 40000 | G10: =F10*D10 -> 80000
C11: Türü : Tek Kademeli, Yatay, Ayrılabilir Gövdeli (Horizontal Split-Case)
C12: Anma Debisi (Rated Flow) : 2000 gpm
C13: Anma Basıncı (Rated Head): 145 psi
C14: Kapalı Basma Basıncı : En Fazla 203 psi (Shut-Off Head)
C15: Motor Dönüş Yönü : Saat Yönünde (Clockwise)
C16: Uygunluk : NFPA 20'ye Uygun
C17: Gövde : Eksenel Bölünmüş Tip ve Dökme Demir
C18: Dizel Motor Türü : Yatay Milli
C19: Dizel Motor Soğutması : Su Soğutmalı (Basma Hattı Yangın Suyu)
C20: Yakıt Deposu : Kapasitesi NFPA 20’ye Uygun, Seviye Göstergeli
C21: Yakıt Deposu Nefesliği : Şapkalı Tip, Korozyon Dayanımlı
C22: İçindekiler : Yakıt Deposu, Egzoz, 2 Tk. Kuru Tip Akü, Motor Soğutma Hattı,
... C25: Üretici : Patterson, Armstrong
B26: 2 | C26: Dizel Motorlu Yangın Pompası Kontrol Paneli | D26: 2 | E26: Adet | G26: =F26*D26 -> 0
C27: Türü : Mikroişlemcili
C28: Koruma Sınıfı : Tam Kapalı ve Sızdırmaz Koruma (NEMA 4)
C29: Güç Beslemesi : 380 VAC/3-Ph//50Hz
C30: İçindekiler : Basınç Kumanda Cihazı, Yedek ve Asıl Aküler, Devresi, Otomatik
C31: Zaman Saati, Sistem Basıncı Kayıt Cihazı, Test Devresi, Min. Çalışma Süresi Zamanlayıcısı
C32: Onay : UL Listeli, FM Onaylı, CE Belgeli
B33: 3 | C33: Elektrik Motorlu Kaçak Pompası (Jokey Pompa) | D33: 1 | E33: Adet | F33: 20000 | G33: =F33*D33 -> 20000
C34: Türü : Dikey Milli, Çok Kademeli
C35: Anma Debisi : 20 gpm
C36: Anma Basıncı : 155 psi
C37: Elektrik Motor : ODP
C38: İçindekiler : Emniyet Ventili, Manometreler, Hava Atma Ventili
C39: Onay : TSE Onaylı, CE Belgeli
B40: 4 | C40: Elektrik Motorlu Kaçak Giderme Pompası (Jokey Pompa) Kontrol Paneli | D40: 1 | E40: Adet | G40: =F40*D40 -> 0
C41: Türü : Röleli
C42: Koruma Sınıfı : Tam Kapalı ve Sızdırmaz Koruma (NEMA 4)
C43: Gücü : Pompaya Uygun Olarak Seçilmiş
C44: İçindekiler : Basınç Kumanda Cihazı, Min. Çalışma Süresi Zamanlayıcısı,
C45: Çalışma Süresi Toplayıcısı (Totaliser)
C46: Onay : TSE Onaylı, CE Belgeli
B47: 5 | C47: Yükselen Milli Vana (OS&Y Valve) | D47: 2 | E47: Adet | F47: 6000 | G47: =F47*D47 -> 12000
C48: Çap : DN 250
C49: Vana Türü : Yükselen Milli Sürgülü
...

Sheet Hidrant.Sistemi
B2: FIRMA-C ENTEGRE SAHA-UC YANGIN TESİSATI TEKLİFİ
B7: No | C7: HİDRANT SİSTEMİ | D7: Miktar | E7: Birim | F7: BİRİM FİYAT İŞÇİLİK | G7: TOPLAM FİYAT İŞÇİLİK
B10: 1 | C10: Dış Saha Yerüstü Hidrantı (Mevcut) | D10: 41 | E10: Adet | G10: =F10*D10 -> 0
B12: 2 | C12: Dış Saha Yerüstü Hidrantı (Yeni Planlanan) | D12: 2 | E12: Adet | F12: 5000 | G12: =F12*D12 -> 10000
C13: Türü : Yer Üstü Hidrantı
C14: Giriş Çapı : DN100
C15: Çıkış Çapı : 2 x DN 65 Storz
C16: Giriş Bağlantısı : Flanşlı
C17: Çıkış Bağlantısı : Flanşlı
C18: Montaj Biçimi : Yer Üstü
C19: Açılma : Elle
C20: Aksesuarlar : 1 adet Açma Anahtarı ve Hidrant Dirseği ile
C21: Onaylar : TSE Onaylı
C22: Yedekler : -
C23: Üretici : Klinger, Fetaş veya Valftek
B24: 3 | C24: Hidrant Koruyucu İmalatı (Yeni Planlanan) | D24: 2 | E24: Adet | G24: =F24*D24 -> 0
C25: Türü : Yer Üstü, Çelik Yere Sabitlenmiş Ayak
C26: Koruma : Dış Hava Koşullarına, Paslanmaya Dayanıklı ve Korumalı
C27: Montaj Yeri : Hidrant Yakınına
C28: Malzeme : DN 80 Borudan İmal
C29: Renk : Sarı ve Siyah Boyalı
C30: Üretici : Yerinde İmalat
B31: 4 | C31: Yerüstü Hidrant Dolabı (Yeni Planlanan) | D31: 2 | E31: Adet | F31: 2500 | G31: =F31*D31 -> 5000
C32: Türü : Yer Üstü, Ayaklı
C33: Koruma : Dış Hava Koşullarına Dayanıklı ve Korumalı
C34: Montaj Yeri : Hidrant Yakınına
C35: Malzeme : Fosfatlanmış Galvanize Saç (Üzeri Epoksi Kaplı)
C36: Renk : RAL3000 Kırmızı
C37: Aksesuarlar : 1 adet Hidrant Açma Anahtarı, 2 adet DN65 PVC Kaplı 30 m Bez Hortum
C38: ve Tekerli ve 2 adet Ayarlı Nozul ve Nozul Tutturma Kelepçesiyle
C39: Onaylar : TSE Belgeli
C40: Yedekler : -
C41: Üretici : Fetaş veya Normeks
B42: 5 | C42: Gömme Tip Kesme Vanası (Burried NRS), DN315 (Yeni Planlanan) | D42: 19 | E42: Adet | F42: 4500 | G42: =F42*D42 -> 85500
C43: Türü : Gömme NRS
C44: Vana Çapı : DN 315
C45: Montaj biçimi : Beton Takviyeli
C46: Vana Bağlantı : ANSI/DIN Flanşlı
C47: Kullanım Amacı : Su Kontrol, Kesme Vanası
C48: Onay : FM Onaylı
...

Sheet Pres2-3 Çelik Kule
A1: Pres-2 ve Pres-3 - Çelik Yangın Dolabı Sistemi Kurulumu
A2: No | C2: Miktar | D2: Birim | E2: BİRİM FİYAT İŞÇİLİK | F2: TOPLAM FİYAT İŞÇİLİK
A3: 1 | B3: Esnek Yivli Boru Bağlantı Kelepçesi, DN150 | C3: 34 | D3: Ad. | F3: =E3*C3 -> 0
A4: 2 | B4: Sert Yivli Boru Bağlantı Kelepçesi, DN150 | C4: 400 | D4: Ad. | F4: =E4*C4 -> 0
A5: 3 | B5: Sert Yivli Boru Bağlantı Kelepçesi, DN65 | C5: 400 | D5: Ad. | F5: =E5*C5 -> 0
A6: 4 | B6: Dikişli Siyah Çelik Boru, DN150 | C6: 500 | D6: m | E6: 675 | F6: =E6*C6 -> 337500
A7: 5 | B7: Dikişli Siyah Çelik Boru, DN65 | C7: 700 | D7: m | E7: 430 | F7: =E7*C7 -> 301000
A8: 6 | B8: 4 Yollu Boru Askısı, DN150 | C8: 100 | D8: Ad. | E8: 400 | F8: =E8*C8 -> 40000
A9: 7 | B9: 2 Yollu Boru Askısı, DN150 (Enine) | C9: 150 | D9: Ad. | E9: 300 | F9: =E9*C9 -> 45000
A10: 8 | B10: 2 Yollu Boru Askısı, DN150 (Boyuna) | C10: 150 | D10: Ad. | E10: 300 | F10: =E10*C10 -> 45000
A11: 9 | B11: Sprinkler Boru Askısı, DN65 | C11: 400 | D11: Ad. | F11: =E11*C11 -> 0
A12: 10 | B12: Kelebek Vana, DN300 | C12: 4 | D12: Ad. | E12: 4500 | F12: =E12*C12 -> 18000
A13: 11 | B13: Kelebek Vana, DN150 | C13: 17 | D13: Ad. | E13: 3000 | F13: =E13*C13 -> 51000
A14: 12 | B14: Yangın Hortum Dolabı | C14: 30 | D14: Ad. | E14: 2500 | F14: =E14*C14 -> 75000
A15: 13 | B15: Islak Alarm Vanası, DN150 | C15: 30 | D15: Ad. | E15: 7500 | F15: =E15*C15 -> 225000
A16: 14 | B16: Kolektör, DN200 | C16: 2 | D16: Ad. | E16: 8000 | F16: =E16*C16 -> 16000
D17: GENEL TOPLAM : | F17: =SUM(F3:F16) -> 1153500

Sheet Trafo.Su.Püskürtme
B2: FIRMA-C ENTEGRE SAHA-UC YANGIN TESİSATI TEKLİFİ
B7: No | C7: TRAFO SU PÜSKÜRTME SİSTEMİ | D7: Miktar | E7: Birim | F7: BİRİM FİYAT İŞÇİLİK | G7: TOPLAM FİYAT İŞÇİLİK
B10: 1 | C10: Su Sprayi Püskürtme Memesi, (Spray Nozul ) 125° | D10: 420 | E10: ad. | F10: 200 | G10: =F10*D10 -> 84000
C11: Türü : Açık (Open
C12: Montaj Biçimi : Açılı veya Yatay
C13: Malzeme : Pirinç veya Çelik
C14: Püskürtme Yapısı : Konik
C15: Bağlantı : ½” NPT
C16: Aksesuar : Koruma Kapağı
C17: Onay : FM Onaylı
C18: Üretici : Reliable, Tyco, Victaulic, Viking
B19: 2 | C19: Baskın Vana İstasyonu, DN 65 | D19: 19 | E19: Adet | F19: 3000 | G19: =F19*D19 -> 57000
C20: Tür : Diyaframlı veya Klapeli
C21: Tahrik Şekli : Elektrik Aktivasyonlu veya Elle
C22: Tahrik Ünitesi : Yangın Algılama Sistemi
C23: Kapanma : Elle Yerinden
C24: Tip : Değişken Basınçlı
C25: Bağlantı : Giriş – Çıkış Yivli veya Flanşlı Bağlantılı
C26: Çapı : DN65
C27: Montaj Biçim : Dik
C28: Aksesuar : Her Türlü Aksamlarıyla (Trim) Birlikte
C29: Su Motorlu Gong ve Aksamı, Basınç Anahtarı,
C30: Giriş-Çıkış Manometreleriyle Birlikte
C31: Onay : UL Listeli veya FM Onaylı
C32: Üretici : Tyco, Victaulic, Viking
B33: 3 | C33: Baskın Vana İstasyonu, DN 80 | D33: 2 | E33: Adet | F33: 3500 | G33: =F33*D33 -> 7000
C34: Tür : Diyaframlı veya Klapeli
C35: Tahrik Şekli : Elektrik Aktivasyonlu veya Elle
C36: Tahrik Ünitesi : Yangın Algılama Sistemi
C37: Kapanma : Elle Yerinden
C38: Tip : Değişken Basınçlı
C39: Bağlantı : Giriş – Çıkış Yivli veya Flanşlı Bağlantılı
C40: Çapı : DN80
C41: Montaj Biçim : Dik
C42: Aksesuar : Her Türlü Aksamlarıyla (Trim) Birlikte
C43: - Su Motorlu Gong ve Aksamı, Basınç Anahtarı,
C44: Giriş-Çıkış Manometreleriyle Birlikte
C45: Onay : UL Listeli veya FM Onaylı
C46: Üretici : Tyco, Victaulic, Viking
B47: 4 | C47: Baskın Vana Dolabı | D47: 21 | E47: Adet | F47: 2500 | G47: =F47*D47 -> 52500
...

Sheet Sprinkler.Sistemi
B2: FIRMA-C ENTEGRE SAHA-UC YANGIN TESİSATI TEKLİFİ
B7: No | C7: SPRİNKLER SİSTEMİ | D7: Miktar | E7: Birim | F7: BİRİM FİYAT İŞÇİLİK | G7: TOPLAM FİYAT İŞÇİLİK
C9: A. Melamin Pres - Zımpara ve Boya Hattı - Otomatik Sprinkler Sistemi Kurulumu
B10: 1 | C10: Otomatik Sprinkler Kafası, (Sarkık, K=240) | D10: 11670 | E10: Ad. | F10: 200 | G10: =F10*D10 -> 2334000
B11: 2 | C11: Deneme ve Gider Vanası, DN32 veya DN40 K=240 | D11: 34 | E11: Ad. | F11: 750 | G11: =F11*D11 -> 25500
B12: 3 | C12: Branşman Kelepçesi, DN150 x DN65 | D12: 900 | E12: Ad. | G12: =F12*D12 -> 0
B13: 4 | C13: Branşman Kelepçesi, DN65 x DN25 | D13: 11670 | E13: Ad. | G13: =F13*D13 -> 0
B14: 5 | C14: Esnek Yivli Boru Bağlantı Kelepçesi, DN150 | D14: 82 | E14: Ad. | G14: =F14*D14 -> 0
B15: 6 | C15: Sert Yivli Boru Bağlantı Kelepçesi, DN150 | D15: 2285 | E15: Ad. | G15: =F15*D15 -> 0
B16: 7 | C16: Sert Yivli Boru Bağlantı Kelepçesi, DN65 | D16: 11135 | E16: Ad. | G16: =F16*D16 -> 0
B17: 8 | C17: Dikişli Siyah Çelik Boru, DN150 | D17: 7873 | E17: m | F17: 750 | G17: =F17*D17 -> 5904750
B18: 9 | C18: Dikişli Siyah Çelik Boru, DN65 | D18: 34000 | E18: m | F18: 420 | G18: =F18*D18 -> 14280000
B19: 10 | C19: Dikişli Siyah Çelik Boru, DN25 | D19: 12200 | E19: m | F19: 270 | G19: =F19*D19 -> 3294000
B20: 11 | C20: 4 Yollu Boru Askısı, DN150 | D20: 114 | E20: Ad. | F20: 400 | G20: =F20*D20 -> 45600
B21: 12 | C21: 2 Yollu Boru Askısı, DN150 (Enine) | D21: 952 | E21: Ad. | F21: 300 | G21: =F21*D21 -> 285600
B22: 13 | C22: 2 Yollu Boru Askısı, DN150 (Boyuna) | D22: 365 | E22: Ad. | F22: 300 | G22: =F22*D22 -> 109500
B23: 14 | C23: Sprinkler Boru Askısı, DN150 | D23: 1612 | E23: Ad. | G23: =F23*D23 -> 0
B24: 15 | C24: Sprinkler Boru Askısı, DN65 | D24: 11670 | E24: Ad. | G24: =F24*D24 -> 0
B25: 16 | C25: Hat Sonu Yıkama Vanası, DN150 | D25: 105 | E25: Ad. | F25: 3000 | G25: =F25*D25 -> 315000
B26: 17 | C26: Kelebek Vana, DN300 | D26: 8 | E26: Ad. | F26: 4500 | G26: =F26*D26 -> 36000
B27: 18 | C27: Kelebek Vana, DN150 | D27: 34 | E27: Ad. | F27: 3000 | G27: =F27*D27 -> 102000
B28: 19 | C28: Akış Anahtarı, DN150 | D28: 34 | E28: Ad. | F28: 1500 | G28: =F28*D28 -> 51000
B29: 20 | C29: Yangın Hortum Dolabı | D29: 80 | E29: Ad. | F29: 2500 | G29: =F29*D29 -> 200000
B30: 21 | C30: Islak Alarm Vanası, DN150 | D30: 34 | E30: Ad. | F30: 7500 | G30: =F30*D30 -> 255000
B31: 22 | C31: Kolektör, DN200 | D31: 9 | E31: Ad. | F31: 8000 | G31: =F31*D31 -> 72000
C32: B. Variodor Tesisi - Otomatik Sprinkler Sistemi Kurulumu
B33: 1 | C33: Otomatik Sprinkler Kafası, (Sarkık, K=240) | D33: 7053 | E33: Ad. | F33: 200 | G33: =F33*D33 -> 1410600
B34: 2 | C34: Deneme ve Gider Vanası, K=240 | D34: 17 | E34: Ad. | F34: 750 | G34: =F34*D34 -> 12750
B35: 3 | C35: Branşman Kelepçesi, DN150 x DN65 | D35: 330 | E35: Ad. | G35: =F35*D35 -> 0
B36: 4 | C36: Branşman Kelepçesi, DN65 x DN25 | D36: 7053 | E36: Ad. | G36: =F36*D36 -> 0
B37: 5 | C37: Esnek Yivli Boru Bağlantı Kelepçesi, DN150 | D37: 34 | E37: Ad. | G37: =F37*D37 -> 0
B38: 6 | C38: Sert Yivli Boru Bağlantı Kelepçesi, DN150 | D38: 1199 | E38: Ad. | G38: =F38*D38 -> 0
B39: 7 | C39: Sert Yivli Boru Bağlantı Kelepçesi, DN65 | D39: 6570 | E39: Ad. | G39: =F39*D39 -> 0
B40: 8 | C40: Dikişli Siyah Çelik Boru, DN150 | D40: 4221 | E40: m | F40: 750 | G40: =F40*D40 -> 3165750
B41: 9 | C41: Dikişli Siyah Çelik Boru, DN65 | D41: 19710 | E41: m | F41: 420 | G41: =F41*D41 -> 8278200
B42: 10 | C42: Dikişli Siyah Çelik Boru, DN25 | D42: 7200 | E42: m | F42: 270 | G42: =F42*D42 -> 1944000
B43: 11 | C43: 4 Yollu Boru Askısı, DN150 | D43: 77 | E43: Ad. | F43: 400 | G43: =F43*D43 -> 30800
B44: 12 | C44: 2 Yollu Boru Askısı, DN150 (Enine) | D44: 384 | E44: Ad. | F44: 300 | G44: =F44*D44 -> 115200
B45: 13 | C45: 2 Yollu Boru Askısı, DN150 (Boyuna) | D45: 173 | E45: Ad. | F45: 300 | G45: =F45*D45 -> 51900
B46: 14 | C46: Sprinkler Boru Askısı, DN150 | D46: 850 | E46: Ad. | G46: =F46*D46 -> 0
...

Sheet Konveyör.Sprink
B2: FIRMA-C ENTEGRE SAHA-UC YANGIN TESİSATI TEKLİFİ
B7: No | C7: KONVEYÖR SPRİNK SİSTEMİ | D7: MARKA | E7: Miktar | F7: Birim | G7: BİRİM FİYAT İŞÇİLİK | H7: TOPLAM FİYAT İŞÇİLİK
B10: 1 | C10: 1-BETON SİLO-1-2 REFİNER 1 KONVEYÖRÜ
C11: Otomatik Sprinkler Kafası, Standart Tepkili (Sarkık, K=115) | D11: Reliable, Tyco,_x000D_ Victaulic,Viking | E11: 8 | F11: Ad. | G11: 200 | H11: =G11*E11 -> 1600
C12: Deneme ve Gider Vanası, DN32 veya DN40, K=115 | D12: AGF, Giacomini | E12: 1 | F12: Ad. | G12: 750 | H12: =G12*E12 -> 750
C13: Branşman Kelepçesi, DN50 x DN32 | D13: Shurjoint, Grinnell,_x000D_ Victaulic | E13: 2 | F13: Ad. | H13: =G13*E13 -> 0
C14: Branşman Kelepçesi, DN32 x DN25 | D14: Shurjoint, Grinnell,_x000D_ Victaulic | E14: 8 | F14: Ad. | H14: =G14*E14 -> 0
C15: Esnek Yivli Boru Bağlantı Kelepçesi, DN50 | D15: Shurjoint, Grinnell,_x000D_ Victaulic | E15: 2 | F15: Ad. | H15: =G15*E15 -> 0
C16: Sert Yivli Boru Bağlantı Kelepçesi, DN50 | D16: Shurjoint, Grinnell,_x000D_ Victaulic | E16: 24 | F16: Ad. | H16: =G16*E16 -> 0
C17: Sert Yivli Boru Bağlantı Kelepçesi, DN32 | D17: Shurjoint, Grinnell,_x000D_ Victaulic | E17: 6 | F17: Ad. | H17: =G17*E17 -> 0
C18: Yivli Çelik Boru, DN50 - 3.2 mm | D18: Borusan_x000D_ veya Çayırova | E18: 42 | F18: m | G18: 380 | H18: =G18*E18 -> 15960
C19: Yivli Çelik Boru, DN32 - 3.2 mm | D19: Borusan_x000D_ veya Çayırova | E19: 36 | F19: m | G19: 300 | H19: =G19*E19 -> 10800
C20: Yivli Çelik Boru, DN25 - 3.2 mm | D20: Borusan_x000D_ veya Çayırova | E20: 36 | F20: m | G20: 270 | H20: =G20*E20 -> 9720
C21: Sprinkler Boru Askısı | D21: Hilti, İnka_x000D_ veya Link | E21: 38 | F21: Ad. | H21: =G21*E21 -> 0
C22: Hat Sonu Yıkama Vanası, DN32 | D22: ECA, Duyar | F22: Ad. | G22: 750 | H22: =G22*E22 -> 0
C23: Kelebek Vana, DN50 | D23: Tyco,_x000D_ Victualic, Viking | E23: 1 | F23: Ad. | G23: 1000 | H23: =G23*E23 -> 1000
C24: Akış Anahtarı, DN50 | D24: SYSTEM SENSOR,_x000D_ POTTER ROEMER,_x000D_ SAFE SIGNAL | E24: 1 | F24: Ad. | G24: 1000 | H24: =G24*E24 -> 1000
C25: Islak Alarm Vanası, DN50 | D25: Tyco,_x000D_ Victualic, Viking | E25: 1 | F25: Ad. | G25: 3000 | H25: =G25*E25 -> 3000
C26: Çelik Konstrüksiyon_x000D_ Uygulama Amacı: Trafolar Sprinkler Boru Desteği_x000D_ Malzeme: En az 6 mm Çelik Sacdan İmal, U ve L Profiller | D26: İMALAT | E26: 18 | F26: Ad. | H26: =G26*E26 -> 0
B27: 2 | C27: 2-BETON SİLO-1-2 REFİNER 2 KONVEYÖRÜ
C28: Otomatik Sprinkler Kafası, Standart Tepkili (Sarkık, K=115) | D28: Reliable, Tyco,_x000D_ Victaulic,Viking | E28: 11 | F28: Ad. | G28: 200 | H28: =G28*E28 -> 2200
C29: Deneme ve Gider Vanası, DN32 veya DN40, K=115 | D29: AGF, Giacomini | E29: 1 | F29: Ad. | G29: 750 | H29: =G29*E29 -> 750
C30: Branşman Kelepçesi, DN50 x DN32 | D30: Shurjoint, Grinnell,_x000D_ Victaulic | E30: 2 | F30: Ad. | H30: =G30*E30 -> 0
C31: Branşman Kelepçesi, DN32 x DN25 | D31: Shurjoint, Grinnell,_x000D_ Victaulic | E31: 11 | F31: Ad. | H31: =G31*E31 -> 0
C32: Esnek Yivli Boru Bağlantı Kelepçesi, DN80 | D32: Shurjoint, Grinnell,_x000D_ Victaulic | E32: 3 | F32: Ad. | H32: =G32*E32 -> 0
C33: Sert Yivli Boru Bağlantı Kelepçesi, DN80 | D33: Shurjoint, Grinnell,_x000D_ Victaulic | E33: 6 | F33: Ad. | H33: =G33*E33 -> 0
C34: Sert Yivli Boru Bağlantı Kelepçesi, DN50 | D34: Shurjoint, Grinnell,_x000D_ Victaulic | E34: 14 | F34: Ad. | H34: =G34*E34 -> 0
C35: Sert Yivli Boru Bağlantı Kelepçesi, DN32 | D35: Shurjoint, Grinnell,_x000D_ Victaulic | E35: 6 | F35: Ad. | H35: =G35*E35 -> 0
C36: Yivli Çelik Boru, DN80 - 4 mm | D36: Borusan_x000D_ veya Çayırova | E36: 12 | F36: m | G36: 480 | H36: =G36*E36 -> 5760
C37: Yivli Çelik Boru, DN50 - 3.2 mm | D37: Borusan_x000D_ veya Çayırova | E37: 42 | F37: m | G37: 380 | H37: =G37*E37 -> 15960
C38: Yivli Çelik Boru, DN32 - 3.2 mm | D38: Borusan_x000D_ veya Çayırova | E38: 36 | F38: m | G38: 300 | H38: =G38*E38 -> 10800
C39: Yivli Çelik Boru, DN25 - 3.2 mm | D39: Borusan_x000D_ veya Çayırova | E39: 3 | F39: m | G39: 270 | H39: =G39*E39 -> 810
C40: 4 Yollu Boru Askısı, DN80 | D40: Link, Erico, Hilti,_x000D_ Tolco, | E40: 1 | F40: Ad. | G40: 400 | H40: =G40*E40 -> 400
C41: Sprinkler Boru Askısı | D41: Hilti, İnka_x000D_ veya Link | E41: 30 | F41: Ad. | H41: =G41*E41 -> 0
C42: Hat Sonu Yıkama Vanası, DN32 | D42: ECA, Duyar | F42: Ad. | G42: 750 | H42: =G42*E42 -> 0
C43: Kelebek Vana, DN80 | D43: Tyco,_x000D_ Victualic, Viking | E43: 1 | F43: Ad. | G43: 1750 | H43: =G43*E43 -> 1750
C44: Akış Anahtarı, DN80 | D44: SYSTEM SENSOR,_x000D_ POTTER ROEMER, | E44: 1 | F44: Ad. | G44: 1250 | H44: =G44*E44 -> 1250
C45: Islak Alarm Vanası, DN80 | D45: Tyco,_x000D_ Victualic, Viking | E45: 1 | F45: Ad. | G45: 3000 | H45: =G45*E45 -> 3000
C46: Çelik Konstrüksiyon_x000D_ Uygulama Amacı: Trafolar Sprinkler Boru Desteği_x000D_ Malzeme: En az 6 mm Çelik Sacdan İmal, U ve L Profiller | D46: İMALAT | E46: 27 | F46: Ad. | H46: =G46*E46 -> 0
B47: 3 | C47: 3-KAZAN YERDEN YAKIT BESLEME TKF KONVEYÖRLERİ -1
...

Sheet Toz.Ambarı
B2: FIRMA-C ENTEGRE SAHA-UC YANGIN TESİSATI TEKLİFİ
B7: No | C7: TOZ AMBARI SÖNDÜRME SİSTEMİ | D7: Miktar | E7: Birim | F7: BİRİM FİYAT İŞÇİLİK | G7: TOPLAM FİYAT İŞÇİLİK
B10: 1 | C10: Kelebek Vana, DN100 (4”) | D10: 1 | E10: Adet | F10: 2000 | G10: =F10*D10 -> 2000
C11: Türü : Yivli veya Wafer veya Kulaklı (Lug Tipi)
C12: Giriş – Çıkış : DN100 (4”)
C13: Montaj Biçimi : Dik veya Yatay
C14: Açılma : Dişli Kutulu El Volanı ile
C15: Malzeme : Döküm Demir Gövdeli, Bronz Diskli
C16: Gösterge : Konum Gösteren İbreli
C17: Aksesuarlar : TKÇY İzleme Anahtarı ve Sıkıştırma Vida
C18: Somunlarıyla Birlikte
B19: 2 | C19: Akış Anahtarı, DN100 | D19: 1 | E19: Adet | F19: 1250 | G19: =F19*D19 -> 1250
B21: 3 | C21: Baskın Vana İstasyonu (Elektrik Tahrikli), DN100 (4”) 1 ad. | D21: 1 | E21: Adet | F21: 5000 | G21: =F21*D21 -> 5000
C22: Tür : Diyaframlı veya Klapeli
C23: Çapı : DN100 (4”)
C24: Tahrik Şekli : Elektrik ve Elle
C25: Kapanma : Elle Yerinden
C26: Bağlantı Türü : Yivli veya Flanşlı
C27: Yeniden Kurma : Tamamen Dışarıdan, Açmadan
C28: Basınç sınıfı : 175 psi
C29: Kurulum Biçimi : Dikey – Düz veya Açılı
C30: Tahrik Ünite : - Türü : Algılama Hattından
C31: : - Çalışma Şekli : Elektrik - Tüm Aparat (Trim)Leri ve Solenoid
C32: Vanası ile
C33: Elle Tahrik Ünitesi : - Türü : Küresel Vana
... C38: : Giriş-Çıkış Manometreleri, Basınç Anahtarı ve Motor Gongu
B39: 4 | C39: Dikişli Siyah Çelik Boru, DN100 (4”) | D39: 78 | E39: Metre | F39: 550 | G39: =F39*D39 -> 42900
C40: Çap : DN100 (4”)
C41: Basınç Sınıfı : PN16
C42: Standardı : TSE EN 10255 Orta Seri
C43: Yardımcı Malzeme : Boru Sistemi İçin Gerekli Her Türlü Dirsek, T, Flanş, Kaynak Vb. Dâhil
C44: İmalat : Siyah Çelik Üzeri Standartlara Uygun 1 Kat Antipas ve 2 Kat RAL
C45: 3000 Yağlı Boya
C46: Üretici : Borusan veya Çayırova
B47: 5 | C47: Dikişli Siyah Çelik Boru, DN50 (2”) | D47: 108 | E47: Metre | F47: 380 | G47: =F47*D47 -> 41040
C48: Yukarıdaki gibi ancak
C49: Çap : DN50 (2”)
B50: 6 | C50: Esnek Yivli Boru Bağlantı Kelepçesi DN100 | D50: 1 | E50: Adet | G50: =F50*D50 -> 0
C51: İşlevi : Borunun Boruya Bağlanmasını Sağlamak
C52: Türü : Esnek (Flexible)
...

Sheet Pompa.Odası.Sprink
B2: FIRMA-C ENTEGRE SAHA-UC YANGIN TESİSATI TEKLİFİ
B7: No | C7: POMPA ODASI SPRİNK SİSTEMİ | D7: MARKA | E7: Miktar | F7: Birim | G7: BİRİM FİYAT İŞÇİLİK | H7: TOPLAM FİYAT İŞÇİLİK
B10: 1 | C10: Otomatik Sprinkler Kafası, (Sarkık, K=80) | D10: Tyco, Victualic, Viking | E10: 6 | F10: Ad. | G10: 200 | H10: =G10*E10 -> 1200
B11: 2 | C11: Deneme ve Gider Vanası, K=80 | D11: AGF, Giacomini | E11: 1 | F11: Ad. | G11: 750 | H11: =G11*E11 -> 750
B12: 3 | C12: Branşman Kelepçesi, DN65 x DN25 | D12: Shurjoint, Grinnell, Victaulic | E12: 2 | F12: Ad. | H12: =G12*E12 -> 0
B13: 4 | C13: Esnek Yivli Boru Bağlantı Kelepçesi, DN65 | D13: Shurjoint, Grinnell, Victaulic | E13: 2 | F13: Ad. | H13: =G13*E13 -> 0
B14: 5 | C14: Sprinkler Askısı | D14: Hilti, İnka veya Link | E14: 6 | F14: Ad. | H14: =G14*E14 -> 0
B15: 6 | C15: Sprinkler Askı Çubuğu | D15: Hilti, İnka veya Link | E15: 6 | F15: Ad. | H15: =G15*E15 -> 0
B16: 7 | C16: Dikişli Çelik Boru, DN50 | D16: Borusan veya Çayırova | E16: 24 | F16: m | G16: 380 | H16: =G16*E16 -> 9120
B17: 8 | C17: Dikişli Çelik Boru, DN25 | D17: Borusan veya Çayırova | E17: 18 | F17: m | G17: 270 | H17: =G17*E17 -> 4860
B18: 9 | C18: Kelebek Vana, DN50 | D18: Tyco, Victualic, Viking | E18: 1 | F18: Ad. | G18: 1250 | H18: =G18*E18 -> 1250
B19: 10 | C19: Akış Anahtarı, DN50 | D19: System Sensor, Potter,Roemer,Safe Sıgnal | E19: 1 | F19: Ad. | G19: 1000 | H19: =G19*E19 -> 1000
E20: GENEL TOPLAM : | H20: =SUM(H10:H19) -> 18180

Sheet Otomatik.Köpüklü
B2: FIRMA-C ENTEGRE SAHA-UC YANGIN TESİSATI TEKLİFİ
B7: No | C7: OTOMATİK KÖPÜKLÜ SÖNDÜRME SİSTEMİ | D7: Miktar | E7: Birim | F7: BİRİM FİYAT İŞÇİLİK | G7: TOPLAM FİYAT İŞÇİLİK
B10: 1 | C10: Su Püskürtme Memesi, (Spray Nozzle) | D10: 124 | E10: Adet | F10: 0 | G10: =F10*D10 -> 0
C11: Türü : Açık (Open)
C12: Montaj Biçimi : Açılı veya Yatay
C13: Malzeme : Pirinç veya Çelik
C14: Püskürtme Yapısı : Konik
C15: Bağlantı : 1/2" NPT
C16: K Faktörü : 40 Metrik (2.8 ANSI)
C17: Onay : UL Listeli, FM Onaylı
C18: Üretici : Reliable, Tyco, Viking
B19: 2 | C19: Baskın Vana İstasyonu (Elektrik Tahrikli), DN100 (4”) | D19: 1 | E19: Adet | G19: =F19*D19 -> 0
C20: Tür : Diyaframlı veya Klapeli
C21: Çapı : DN100 (4”)
C22: Tahrik Şekli : Elektrik ve Elle
C23: Kapanma : Elle Yerinden
C24: Bağlantı Türü : Yivli veya Flanşlı
C25: Yeniden Kurma : Tamamen Dışarıdan, Açmadan
C26: Basınç sınıfı : 175 psi
C27: Kurulum Biçimi : Dikey – Düz veya Açılı
C28: Tahrik Ünite : - Türü : Algılama Hattından
C29: : - Çalışma Şekli : Elektrik - Tüm Aparat (Trim)Leri ve Solenoid
C30: Vanası ile
C31: Elle Tahrik Ünitesi : - Türü : Küresel Vana
... C38: Üretici : Tyco, Victaulic, Viking
B39: 3 | C39: Baskın Vana İstasyonu (Elektrik Tahrikli), DN80 (3”) | D39: 2 | E39: Adet | G39: =F39*D39 -> 0
C40: Tür : Diyaframlı veya Klapeli
C41: Çapı : DN80 (3”)
C42: Tahrik Şekli : Elektrik ve Elle
B43: 4 | C43: Baskın Vana İstasyonu (Elektrik Tahrikli), DN50 (2”) | D43: 6 | E43: Adet | G43: =F43*D43 -> 0
C44: Tür : Diyaframlı veya Klapeli
C45: Çapı : DN50 (2”)
C46: Tahrik Şekli : Elektrik ve Elle
C47: Kapanma : Elle Yerinden
C48: Bağlantı Türü : Yivli veya Flanşlı
C49: Yeniden Kurma : Tamamen Dışarıdan, Açmadan
C50: Basınç sınıfı : 175 psi
C51: Kurulum Biçimi : Dikey – Düz veya Açılı
C52: Tahrik Ünite : - Türü : Algılama Hattından
C53: : - Çalışma Şekli : Elektrik - Tüm Aparat (Trim)Leri ve Solenoid
...

Sheet Yangın.Durdurucu
B2: FIRMA-C ENTEGRE SAHA-UC YANGIN TESİSATI TEKLİFİ
B7: No | C7: PASİF YANGIN DURDURUCU | D7: MARKA | E7: Miktar | F7: Birim | G7: BİRİM FİYAT MALZEME | H7: TOPLAM FİYAT İŞÇİLİK
B10: 1 | C10: Akrilik Mastik CP 606 Yangın Durdurucu Akustik Mastik - 580ml Beyaz | D10: HİLTİ / FISCHER | E10: 369 | F10: Adet | G10: 0 | H10: =-G10*E10 -> 0
B11: 2 | C11: İntümesan Mastik FS ONE Max Yangın Durdurucu İntümesan Mastik- Sosis | D11: HİLTİ / FISCHER | E11: 126 | F11: Adet | H11: =-G11*E11 -> 0
B12: 3 | C12: Köpük CP 660 Yangın Durdurucu Köpük | D12: HİLTİ / FISCHER | E12: 432 | F12: Adet | H12: =-G12*E12 -> 0
B13: 4 | C13: Harç CP 636 Yangın Durdurucu Harç | D13: HİLTİ / FISCHER | E13: 99 | F13: Adet | H13: =-G13*E13 -> 0
B14: 5 | C14: Sonsuz Sargı CP 648-E-W45/1.8" Yangın Durdurucu Çoklu Sargı - 10 metre | D14: HİLTİ / FISCHER | E14: 36 | F14: Adet | H14: =-G14*E14 -> 0
B15: 6 | C15: Panel Boyası CP 673 Yangın Durdurucu Taşyünü Panel Boyası | D15: HİLTİ / FISCHER | E15: 45 | F15: Adet | H15: =-G15*E15 -> 0
E16: GENEL TOPLAM : | H16: =SUM(H10:H15) -> 0
