Workbook
Name ____xlnm.Print_Area_2: #REF!
Name ____xlnm.Print_Area_2: #REF!
Name ____xlnm.Print_Area_2: #REF!
Name ____xlnm.Print_Area_2: #REF!
Name ____xlnm.Print_Area_2: #REF!
Name ___BFK2003: #REF!
Name ___BFK2003: #REF!
Name ___BFK2003: #REF!
Name ___BFK2003: #REF!
Name ___BFK2003: #REF!
Name ___xlnm.Print_Area_2: #REF!
Name ___xlnm.Print_Area_2: #REF!
Name ___xlnm.Print_Area_2: #REF!
Name ___xlnm.Print_Area_2: #REF!
Name ___xlnm.Print_Area_2: #REF!
Name __BFK2003: #REF!
Name __BFK2003: #REF!
Name __BFK2003: #REF!
Name __BFK2003: #REF!
Name __BFK2003: #REF!
Name __xlnm.Print_Area_2: #REF!
Name __xlnm.Print_Area_2: #REF!
Name __xlnm.Print_Area_2: #REF!
Name __xlnm.Print_Area_2: #REF!
Name __xlnm.Print_Area_2: #REF!
Name _1000İŞÇ_9_2_1_2: #REF!
Name _1000İŞÇ_9_2_1_2: #REF!
Name _1000İŞÇ_9_2_1_2: #REF!
Name _1000İŞÇ_9_2_1_2: #REF!
Name _1000İŞÇ_9_2_1_2: #REF!
Name _1005KK_10_2_1: #REF!
Name _1005KK_10_2_1: #REF!
Name _1005KK_10_2_1: #REF!
Name _1005KK_10_2_1: #REF!
Name _1005KK_10_2_1: #REF!
Name _100DEM_10_2_1_2: #REF!
Name _100DEM_10_2_1_2: #REF!
Name _100DEM_10_2_1_2: #REF!
Name _100DEM_10_2_1_2: #REF!
Name _100DEM_10_2_1_2: #REF!
Name _1010KK_10_2_2: #REF!
Name _1010KK_10_2_2: #REF!
Name _1010KK_10_2_2: #REF!
Name _1010KK_10_2_2: #REF!
Name _1010KK_10_2_2: #REF!
Name _1015KK_10_2_1_1: #REF!
Name _1015KK_10_2_1_1: #REF!
Name _1015KK_10_2_1_1: #REF!
Name _1015KK_10_2_1_1: #REF!
Name _1015KK_10_2_1_1: #REF!
Name _1020KK_10_2_1_2: #REF!
Name _1020KK_10_2_1_2: #REF!
Name _1020KK_10_2_1_2: #REF!
Name _1020KK_10_2_1_2: #REF!
Name _1020KK_10_2_1_2: #REF!
Name _1025KK_10_3_1: #REF!
Name _1025KK_10_3_1: #REF!
Name _1025KK_10_3_1: #REF!
Name _1025KK_10_3_1: #REF!
Name _1025KK_10_3_1: #REF!

Sheet ICMAL
B2: FIRMA-A FABRİKA MEKANİK TESİSAT KEŞİF İCMALİ
B3: SIRA NO | C3: BÖLÜM ADI | D3: TOPLAM FİYAT
B4: 1 | C4: SIHHİ TESİSAT | D4: =SIHHİ!L216 -> 3730534
B5: 2 | C5: HAVALANDIRMA TESİSATI | D5: =HAVALANDIRMA!L60 -> 184435
B6: 3 | C6: YANGIN TESİSATI | D6: =YANGIN!L180 -> 10209650
B7: 4 | C7: VRV-VRF TESİSATI | D7: ='VRV-VRF'!L69 -> 0
B8: 5 | C8: SİFONİK YAĞMUR TESİSATI | D8: ='SIFONIK YAĞMUR'!L44 -> 0
B10: GENEL TOPLAM ( TL - TÜRK LİRASI ) | D10: =SUM(D4:D8) -> 14124619
B12: NOTLAR:
B13: 1 | C13: Bina dışındaki toprak Altında gecen temiz su ve pis su boruları, temel içindeki altyapı boruları keşif özetine dahil değildir.
B14: 2 | C14: Bina içinde gerekli olan kırma dökme ,örme,sıva…. Vb inşai işler keşif özetine dahil değildir.
C15: sadece sıhhi tesisattaki pis su ve temiz su boruların gecmesi için gerekli alan karot işleri dahildir.
C16: Duvar içinden geçen hatların duvara gömülmesi için gerekli kesme ve boşaltma işi dahildir.
C17: Bütün tesisatlar için duvar geçişleri delme işlemi birim fiyata dahildir.
B18: 3 | C18: Radyant sistemi ve doğalgaz tesisatı keşif özetine dahil değildir. Uygulama projesi doğrultusunda keşif çalışması oluşturulmalıdır.
B19: 4 | C19: Keşif özetinde belirtilen malzeme listesi, teklif verecek olan firmalara ön bilgi olarak aktarılmıştır. Anahtar teslimi yapılacak olan ihlaye firmalar kendi metrajları ile teklif verebilirler.
B20: 5 | C20: Keşif özeti ruhsat mimari projesine göre çizilmiş olup uygulamada yer alacak sistemler (basınçlı hava proses hatları, ısıtma soğutma proses hatları vb.) keşif özetine dahil edilmemiştir.

Sheet SIHHİ
B2: FIRMA-A FABRİKA Sıhhi Tesisat Keşif Özeti
B3: SIRA NO | C3: CİNSİ TANIMI | D3: MARKASI | E3: MİKTAR | F3: BİRİM | G3: MALZEME | I3: İŞÇİLİK | K3: TOPLAM
G4: BİRİM FİYAT | H4: TUTAR | I4: BİRİM FİYAT | J4: TUTAR | K4: BİRİM FİYAT | L4: TUTAR
C5: VİTRİFİYE MALZEMESİ VE ARMATÜR MONTAJLARI, | L5: =IF(OR(H5<>"",J5<>""),SUM(H5,J5),"")
C6: MALZEMENİN TEMİN EDİLDİĞİ MARKANIN YETKİLİ | L6: =IF(OR(H6<>"",J6<>""),SUM(H6,J6),"")
C7: SERVİSLERİ veya MEKANİK MÜTEAHHİT TARAFINDAN YAPILACAKTIR. | L7: =IF(OR(H7<>"",J7<>""),SUM(H7,J7),"")
C8: Mekanik Tesisat Taşeron Firması, vitrefiye malzemelerinin ve armatür- | L8: =IF(OR(H8<>"",J8<>""),SUM(H8,J8),"")
C9: lerinin ihtiyacı olan pis ve temiz su ağızlarını, markanın montaj kataloğu- | L9: =IF(OR(H9<>"",J9<>""),SUM(H9,J9),"")
C10: ndaki ölçülere uygun olarak hazırlayacaktır. Bunu dışında her türlü montaj | L10: =IF(OR(H10<>"",J10<>""),SUM(H10,J10),"")
C11: ve yardımcı malzeme yetkili servis tarafından sağlanacaktır. Her türlü | L11: =IF(OR(H11<>"",J11<>""),SUM(H11,J11),"")
C12: yeter miktardaki adaptör conta, uzatma parçası, yeter uzunlukta fleksible | L12: =IF(OR(H12<>"",J12<>""),SUM(H12,J12),"")
C13: bağlantı parçası, her türlü montaj seti v.b. malzeme, vitrefiye malzemesinin | L13: =IF(OR(H13<>"",J13<>""),SUM(H13,J13),"")
C14: satın alındığı markanın yetkili servisi tarafından temin edilip, montajı | L14: =IF(OR(H14<>"",J14<>""),SUM(H14,J14),"")
C15: yine yetkili sevis tarafından yapılacaktır. | L15: =IF(OR(H15<>"",J15<>""),SUM(H15,J15),"")
B16: =MAX(INDIRECT(CONCATENATE(ADDRESS(4,2,1,1),":",ADDRESS(ROW()-1,2,4,1))))+1 -> 1 | C16: GÖMME REZERVUAR MONTAJ BEDELİ | L16: =IF(OR(H16<>"",J16<>""),SUM(H16,J16),"")
C17: Gömme rezervuar montajı için çelik karkas inşaai grup tarafından hazırlanacaktır. | L17: =IF(OR(H17<>"",J17<>""),SUM(H17,J17),"")
C18: Kada, rezervuar gider dirseği gibi parçalar İşveren tarafından temin edilecektir. | E18: 13 | F18: Adet | I18: 4000 | J18: =SUM(E18*I18) -> 52000 | K18: =SUM(G18+I18) -> 4000 | L18: =IF(OR(H18<>"",J18<>""),SUM(H18,J18),"") -> 52000
B19: =MAX(INDIRECT(CONCATENATE(ADDRESS(4,2,1,1),":",ADDRESS(ROW()-1,2,4,1))))+1 -> 2 | C19: STOP VALF MONTAJ BEDELİ | J19: =SUM(E19*I19) -> 0 | K19: =SUM(G19+I19) -> 0 | L19: =IF(OR(H19<>"",J19<>""),SUM(H19,J19),"") -> 0
C20: İşveren tarafından temin edilen alafranga wc ler için stop valfin ve taharet musluğu montaj bedeli. | E20: 9 | F20: Adet | I20: 830 | J20: =SUM(E20*I20) -> 7470 | K20: =SUM(G20+I20) -> 830 | L20: =IF(OR(H20<>"",J20<>""),SUM(H20,J20),"") -> 7470
B21: =MAX(INDIRECT(CONCATENATE(ADDRESS(4,2,1,1),":",ADDRESS(ROW()-1,2,4,1))))+1 -> 3 | C21: KLOZET MONTAJ BEDELİ | J21: =SUM(E21*I21) -> 0 | K21: =SUM(G21+I21) -> 0 | L21: =IF(OR(H21<>"",J21<>""),SUM(H21,J21),"") -> 0
C22: İşveren tarafından temin edilen klozetin montaj bedeli. Özürlü klozeti montajı bu pozdan ödenir. | E22: 9 | F22: Adet | I22: 3000 | J22: =SUM(E22*I22) -> 27000 | K22: =SUM(G22+I22) -> 3000 | L22: =IF(OR(H22<>"",J22<>""),SUM(H22,J22),"") -> 27000
B23: =MAX(INDIRECT(CONCATENATE(ADDRESS(4,2,1,1),":",ADDRESS(ROW()-1,2,4,1))))+1 -> 4 | C23: TAHARET MUSLUĞU MONTAJ BEDELİ | J23: =SUM(E23*I23) -> 0 | K23: =SUM(G23+I23) -> 0 | L23: =IF(OR(H23<>"",J23<>""),SUM(H23,J23),"") -> 0
C24: İşveren tarafından temin edilen alaturka wc ler için taharet montaj bedeli | E24: 4 | F24: Adet | I24: 450 | J24: =SUM(E24*I24) -> 1800 | K24: =SUM(G24+I24) -> 450 | L24: =IF(OR(H24<>"",J24<>""),SUM(H24,J24),"") -> 1800
B25: =MAX(INDIRECT(CONCATENATE(ADDRESS(4,2,1,1),":",ADDRESS(ROW()-1,2,4,1))))+1 -> 5 | C25: LAVABO//EVİYE MONTAJ BEDELİ | J25: =SUM(E25*I25) -> 0 | K25: =SUM(G25+I25) -> 0 | L25: =IF(OR(H25<>"",J25<>""),SUM(H25,J25),"") -> 0
C26: İşveren tarafından temin edilen lavabonun/eviye montaj bedeli.(fotosel bataryası dahil) | E26: 17 | F26: Adet | I26: 4000 | J26: =SUM(E26*I26) -> 68000 | K26: =SUM(G26+I26) -> 4000 | L26: =IF(OR(H26<>"",J26<>""),SUM(H26,J26),"") -> 68000
B27: =MAX(INDIRECT(CONCATENATE(ADDRESS(4,2,1,1),":",ADDRESS(ROW()-1,2,4,1))))+1 -> 6 | C27: LAVABO/EVİYE BATARYASI MONTAJ BEDELİ | J27: =SUM(E27*I27) -> 0 | K27: =SUM(G27+I27) -> 0 | L27: =IF(OR(H27<>"",J27<>""),SUM(H27,J27),"") -> 0
C28: İşveren tarafından temin edilen bataryanın montaj bedeli. Özürlü bataryası, kurna musluğu,eviye musluğu,… vb | J28: =SUM(E28*I28) -> 0 | K28: =SUM(G28+I28) -> 0 | L28: =IF(OR(H28<>"",J28<>""),SUM(H28,J28),"") -> 0
C29: bataryalar montajı bu pozdan ödenir. | E29: 17 | F29: Adet | I29: 830 | J29: =SUM(E29*I29) -> 14110 | K29: =SUM(G29+I29) -> 830 | L29: =IF(OR(H29<>"",J29<>""),SUM(H29,J29),"") -> 14110
B30: =MAX(INDIRECT(CONCATENATE(ADDRESS(4,2,1,1),":",ADDRESS(ROW()-1,2,4,1))))+1 -> 7 | C30: FİLTRELİ ARA MUSLUK MONTAJ BEDELİ | J30: =SUM(E30*I30) -> 0 | K30: =SUM(G30+I30) -> 0 | L30: =IF(OR(H30<>"",J30<>""),SUM(H30,J30),"") -> 0
C31: İşveren tarafından temin edilen Filtreli Ara Musluk montaj bedeli. | E31: 34 | F31: Adet | I31: 830 | J31: =SUM(E31*I31) -> 28220 | K31: =SUM(G31+I31) -> 830 | L31: =IF(OR(H31<>"",J31<>""),SUM(H31,J31),"") -> 28220
B32: =MAX(INDIRECT(CONCATENATE(ADDRESS(4,2,1,1),":",ADDRESS(ROW()-1,2,4,1))))+1 -> 8 | C32: DUŞ TEKNESİ MONTAJ BEDELİ | J32: =SUM(E32*I32) -> 0 | K32: =SUM(G32+I32) -> 0 | L32: =IF(OR(H32<>"",J32<>""),SUM(H32,J32),"") -> 0
C33: İşveren tarafından temin edilen Duş teknesinin montaj bedeli. | E33: 4 | F33: Adet | I33: 4000 | J33: =SUM(E33*I33) -> 16000 | K33: =SUM(G33+I33) -> 4000 | L33: =IF(OR(H33<>"",J33<>""),SUM(H33,J33),"") -> 16000
B34: =MAX(INDIRECT(CONCATENATE(ADDRESS(4,2,1,1),":",ADDRESS(ROW()-1,2,4,1))))+1 -> 9 | C34: DUŞ BATARYASI MONTAJ BEDELİ | J34: =SUM(E34*I34) -> 0 | K34: =SUM(G34+I34) -> 0 | L34: =IF(OR(H34<>"",J34<>""),SUM(H34,J34),"") -> 0
C35: İşveren tarafından temin edilen Duş bataryasının montaj bedeli. | E35: 4 | F35: Adet | I35: 830 | J35: =SUM(E35*I35) -> 3320 | K35: =SUM(G35+I35) -> 830 | L35: =IF(OR(H35<>"",J35<>""),SUM(H35,J35),"") -> 3320
B36: =MAX(INDIRECT(CONCATENATE(ADDRESS(4,2,1,1),":",ADDRESS(ROW()-1,2,4,1))))+1 -> 10 | C36: PİSUAR ve TESİSATI MONTAJ BEDELİ | J36: =SUM(E36*I36) -> 0 | K36: =SUM(G36+I36) -> 0 | L36: =IF(OR(H36<>"",J36<>""),SUM(H36,J36),"") -> 0
C37: İşveren tarafından temin edilen pisuar ve tesisatının montaj bedeli.(fotosel bataryası dahil) | E37: 2 | F37: Adet | I37: 4000 | J37: =SUM(E37*I37) -> 8000 | K37: =SUM(G37+I37) -> 4000 | L37: =IF(OR(H37<>"",J37<>""),SUM(H37,J37),"") -> 8000
B38: =MAX(INDIRECT(CONCATENATE(ADDRESS(4,2,1,1),":",ADDRESS(ROW()-1,2,4,1))))+1 -> 11 | C38: ALATURKA TUVALET ve TESİSATI MONTAJ BEDELİ | J38: =SUM(E38*I38) -> 0 | K38: =SUM(G38+I38) -> 0 | L38: =IF(OR(H38<>"",J38<>""),SUM(H38,J38),"") -> 0
C39: İşveren tarafından temin edilen Alaturka tuvalet ve tesisatının montaj bedeli. | E39: 4 | F39: Adet | I39: 4000 | J39: =SUM(E39*I39) -> 16000 | K39: =SUM(G39+I39) -> 4000 | L39: =IF(OR(H39<>"",J39<>""),SUM(H39,J39),"") -> 16000
B40: =MAX(INDIRECT(CONCATENATE(ADDRESS(4,2,1,1),":",ADDRESS(ROW()-1,2,4,1))))+1 -> 12 | C40: SABUNLUK MONTAJ BEDELİ | J40: =SUM(E40*I40) -> 0 | K40: =SUM(G40+I40) -> 0
C41: İşveren tarafından temin edilen Sabunluğun montaj bedeli. | E41: 9 | F41: Adet | I41: 1250 | J41: =SUM(E41*I41) -> 11250 | K41: =SUM(G41+I41) -> 1250 | L41: =IF(OR(H41<>"",J41<>""),SUM(H41,J41),"") -> 11250
...

Sheet HAVALANDIRMA
B2: FIRMA-A FABRİKA Havalandırma Tesisatı Keşif Özeti
B3: SIRA NO | C3: CİNSİ TANIMI | D3: MARKASI | E3: MİKTAR | F3: BİRİM | G3: MALZEME | I3: İŞÇİLİK | K3: TOPLAM
G4: BİRİM FİYAT | H4: TUTAR | I4: BİRİM FİYAT | J4: TUTAR | K4: BİRİM FİYAT | L4: TUTAR
B5: 1 | C5: SIĞINAK TAZE HAVA CİHAZI MONTAJ BEDELİ | L5: =IF(OR(H5<>"",J5<>""),SUM(H5,J5),"")
C6: Tavan Tipi - İstenilensayıda gözetleme camı bulunacaktır. | L6: =IF(OR(H6<>"",J6<>""),SUM(H6,J6),"")
C7: Hücreler: Taze Hava Emiş + G4 Filtre +F7 Filtre+Hepa Filtre+Kurşun Separatör+ Aktif Karbon +Karışım hüçresi+ | L7: =IF(OR(H7<>"",J7<>""),SUM(H7,J7),"")
C8: G4 Filtre +Vantratör
C9: Elektrik Motoru IE3 enerji sınıfında olacaktır | L9: =IF(OR(H9<>"",J9<>""),SUM(H9,J9),"")
C10: Vvant =500 m³/h, Hcd =150Pa | E10: 1 | F10: Adet | I10: 11500 | J10: =SUM(E10*I10) -> 11500 | K10: =SUM(G10+I10) -> 11500 | L10: =IF(OR(H10<>"",J10<>""),SUM(H10,J10),"") -> 11500
B11: =+B5+1 -> 2 | C11: KANAL TİPİ WC EGZOST ASPİRATÖRÜ | J11: =SUM(E11*I11) -> 0 | K11: =SUM(G11+I11) -> 0 | L11: =IF(OR(H11<>"",J11<>""),SUM(H11,J11),"") -> 0
C12: Kanal tipi fanlar hız anahtarı veya frekans konvertörü ile beraber temin edilecektir. | J12: =SUM(E12*I12) -> 0 | K12: =SUM(G12+I12) -> 0 | L12: =IF(OR(H12<>"",J12<>""),SUM(H12,J12),"") -> 0
C13: Vasp:400 m³/h Hcd:200 pa | E13: 1 | F13: Adet | I13: 5000 | J13: =SUM(E13*I13) -> 5000 | K13: =SUM(G13+I13) -> 5000 | L13: =IF(OR(H13<>"",J13<>""),SUM(H13,J13),"") -> 5000
C14: Vasp:500 m³/h Hcd:200 pa | E14: 1 | F14: Adet | I14: 5000 | J14: =SUM(E14*I14) -> 5000 | K14: =SUM(G14+I14) -> 5000 | L14: =IF(OR(H14<>"",J14<>""),SUM(H14,J14),"") -> 5000
C15: Vasp:1 000 m³/h Hcd:200 pa | E15: 1 | F15: Adet | I15: 5000 | J15: =SUM(E15*I15) -> 5000 | K15: =SUM(G15+I15) -> 5000 | L15: =IF(OR(H15<>"",J15<>""),SUM(H15,J15),"") -> 5000
C16: Vasp:720 m³/h Hcd:200 pa | E16: 1 | F16: Adet | I16: 5000 | J16: =SUM(E16*I16) -> 5000 | K16: =SUM(G16+I16) -> 5000 | L16: =IF(OR(H16<>"",J16<>""),SUM(H16,J16),"") -> 5000
C17: Vasp:400 m³/h Hcd:200 pa | E17: 1 | F17: Adet | I17: 5000 | J17: =SUM(E17*I17) -> 5000 | K17: =SUM(G17+I17) -> 5000 | L17: =IF(OR(H17<>"",J17<>""),SUM(H17,J17),"") -> 5000
B18: =MAX(INDIRECT(CONCATENATE(ADDRESS(4,2,1,1),":",ADDRESS(ROW()-1,2,4,1))))+1 -> 3 | C18: GALVANİZ SACTAN İMAL HAVA KANALLARI | J18: =SUM(E18*I18) -> 0 | K18: =SUM(G18+I18) -> 0 | L18: =IF(OR(H18<>"",J18<>""),SUM(H18,J18),"") -> 0
C19: (Kendinden Flansli ) | J19: =SUM(E19*I19) -> 0 | K19: =SUM(G19+I19) -> 0 | L19: =IF(OR(H19<>"",J19<>""),SUM(H19,J19),"") -> 0
C20: Özel parçalar (dirsek,tee,redüksiyün v.s.) net ölçüsünün 1,50 katı | J20: =SUM(E20*I20) -> 0 | K20: =SUM(G20+I20) -> 0 | L20: =IF(OR(H20<>"",J20<>""),SUM(H20,J20),"") -> 0
C21: olarak ölçülülendirilip, fiyatlandırılacaktır. | J21: =SUM(E21*I21) -> 0 | K21: =SUM(G21+I21) -> 0 | L21: =IF(OR(H21<>"",J21<>""),SUM(H21,J21),"") -> 0
C22: U profiller ile tij arasına metal | J22: =SUM(E22*I22) -> 0 | K22: =SUM(G22+I22) -> 0 | L22: =IF(OR(H22<>"",J22<>""),SUM(H22,J22),"") -> 0
C23: metale titreşimi engelleyecek kauçuk izolatörler konulacaktır. | J23: =SUM(E23*I23) -> 0 | K23: =SUM(G23+I23) -> 0 | L23: =IF(OR(H23<>"",J23<>""),SUM(H23,J23),"") -> 0
C24: Kanal ile taşıyıcı U profiller arasına EPDM levhalar konulacaktır. | J24: =SUM(E24*I24) -> 0 | K24: =SUM(G24+I24) -> 0 | L24: =IF(OR(H24<>"",J24<>""),SUM(H24,J24),"") -> 0
C25: Hava kanallarının duvar, perde ve yangın kaçış koridorlarından geçtiği | J25: =SUM(E25*I25) -> 0 | K25: =SUM(G25+I25) -> 0 | L25: =IF(OR(H25<>"",J25<>""),SUM(H25,J25),"") -> 0
C26: noktalarda, gerekli izolasyon ve önlemler alınacaktır. Bu detaylar için | J26: =SUM(E26*I26) -> 0 | K26: =SUM(G26+I26) -> 0 | L26: =IF(OR(H26<>"",J26<>""),SUM(H26,J26),"") -> 0
C27: uluslararası SMACNA, AHREA,FEMA v.b. standartların ön gördüğü | J27: =SUM(E27*I27) -> 0 | K27: =SUM(G27+I27) -> 0 | L27: =IF(OR(H27<>"",J27<>""),SUM(H27,J27),"") -> 0
C28: detaylar uygulanacaktır. | J28: =SUM(E28*I28) -> 0 | K28: =SUM(G28+I28) -> 0 | L28: =IF(OR(H28<>"",J28<>""),SUM(H28,J28),"") -> 0
C29: Galvaniz Sactan, En geniş kenarı 600 mm'ye kadar 0,60 mm | E29: 47 | F29: m² | I29: 1250 | J29: =SUM(E29*I29) -> 58750 | K29: =SUM(G29+I29) -> 1250 | L29: =IF(OR(H29<>"",J29<>""),SUM(H29,J29),"") -> 58750
C30: Galvaniz Sactan, En geniş kenarı 1250 mm'ye kadar 0,80 mm | E30: 3 | F30: m² | I30: 1250 | J30: =SUM(E30*I30) -> 3750 | K30: =SUM(G30+I30) -> 1250 | L30: =IF(OR(H30<>"",J30<>""),SUM(H30,J30),"") -> 3750
B31: =MAX(INDIRECT(CONCATENATE(ADDRESS(4,2,1,1),":",ADDRESS(ROW()-1,2,4,1))))+1 -> 4 | C31: İZOLESİZ FLEXIBLE HAVA KANALLARI ( PVC malzeme den imal edilmiş) | J31: =SUM(E31*I31) -> 0 | K31: =SUM(G31+I31) -> 0 | L31: =IF(OR(H31<>"",J31<>""),SUM(H31,J31),"") -> 0
C32: Ø102 | E32: 38 | F32: mt | I32: 385 | J32: =SUM(E32*I32) -> 14630 | K32: =SUM(G32+I32) -> 385 | L32: =IF(OR(H32<>"",J32<>""),SUM(H32,J32),"") -> 14630
C33: Ø127 | E33: 4 | F33: mt | I33: 385 | J33: =SUM(E33*I33) -> 1540 | K33: =SUM(G33+I33) -> 385 | L33: =IF(OR(H33<>"",J33<>""),SUM(H33,J33),"") -> 1540
C34: Ø152 | E34: 5 | F34: mt | I34: 385 | J34: =SUM(E34*I34) -> 1925 | K34: =SUM(G34+I34) -> 385 | L34: =IF(OR(H34<>"",J34<>""),SUM(H34,J34),"") -> 1925
B35: =MAX(INDIRECT(CONCATENATE(ADDRESS(4,2,1,1),":",ADDRESS(ROW()-1,2,4,1))))+1 -> 5 | C35: TEK SIRA KANATLI MENFEZ ve İÇTEN 6 mm. NFAF MALZEME İLE İZOLELİ DİFÜZÖR KUTUSU | J35: =SUM(E35*I35) -> 0 | K35: =SUM(G35+I35) -> 0 | L35: =IF(OR(H35<>"",J35<>""),SUM(H35,J35),"") -> 0
C36: 150x150 mm | E36: 6 | F36: Adet | I36: 2000 | J36: =SUM(E36*I36) -> 12000 | K36: =SUM(G36+I36) -> 2000 | L36: =IF(OR(H36<>"",J36<>""),SUM(H36,J36),"") -> 12000
B37: =MAX(INDIRECT(CONCATENATE(ADDRESS(4,2,1,1),":",ADDRESS(ROW()-1,2,4,1))))+1 -> 6 | C37: ÇİFT SIRA KANATLI MENFEZ ve İÇTEN 6 mm. NFAF MALZEME İLE İZOLELİ DİFÜZÖR KUTUSU | J37: =SUM(E37*I37) -> 0 | K37: =SUM(G37+I37) -> 0 | L37: =IF(OR(H37<>"",J37<>""),SUM(H37,J37),"") -> 0
C38: 300x200 mm | E38: 2 | F38: Adet | I38: 2000 | J38: =SUM(E38*I38) -> 4000 | K38: =SUM(G38+I38) -> 2000 | L38: =IF(OR(H38<>"",J38<>""),SUM(H38,J38),"") -> 4000
B39: =MAX(INDIRECT(CONCATENATE(ADDRESS(4,2,1,1),":",ADDRESS(ROW()-1,2,4,1))))+1 -> 7 | C39: GEMİCİ WC ANEMOSTATI | J39: =SUM(E39*I39) -> 0 | K39: =SUM(G39+I39) -> 0 | L39: =IF(OR(H39<>"",J39<>""),SUM(H39,J39),"") -> 0
C40: Ø100 mm. | E40: 17 | F40: Adet | I40: 770 | J40: =SUM(E40*I40) -> 13090 | K40: =SUM(G40+I40) -> 770 | L40: =IF(OR(H40<>"",J40<>""),SUM(H40,J40),"") -> 13090
B41: =MAX(INDIRECT(CONCATENATE(ADDRESS(4,2,1,1),":",ADDRESS(ROW()-1,2,4,1))))+1 -> 8 | C41: TAZE HAVA / EGSOZT PANJURU | J41: =SUM(E41*I41) -> 0 | K41: =SUM(G41+I41) -> 0 | L41: =IF(OR(H41<>"",J41<>""),SUM(H41,J41),"") -> 0
...

Sheet YANGIN
B2: FIRMA-A FABRİKA Yangın Tesisatı Keşif Özeti
B3: SIRA NO | C3: CİNSİ TANIMI | D3: MARKASI | E3: MİKTAR | F3: BİRİM | G3: MALZEME | I3: İŞÇİLİK | K3: TOPLAM
G4: BİRİM FİYAT | H4: TUTAR | I4: BİRİM FİYAT | J4: TUTAR | K4: BİRİM FİYAT | L4: TUTAR
B5: =MAX(INDIRECT(CONCATENATE(ADDRESS(4,2,1,1),":",ADDRESS(ROW()-1,2,4,1))))+1 -> 1 | C5: YANGIN SÖNDÜRME POMPASI GRUBU MONTAJ BEDELİ | L5: =IF(OR(H5<>"",J5<>""),SUM(H5,J5),"")
C6: Ana yangın pompaları için paket tip, end-suction Split case pompalar (ayrılabilir )- | L6: =IF(OR(H6<>"",J6<>""),SUM(H6,J6),"")
C7: ve jokey yangın pompası için dik tip santrüfüj pompa olacaktır. | L7: =IF(OR(H7<>"",J7<>""),SUM(H7,J7),"")
C8: Yangın pompalarının elektrik ve kontrol panoları, basınç prosestatları, emniyet ventili | L8: =IF(OR(H8<>"",J8<>""),SUM(H8,J8),"")
C9: yakıt tankı,akü şarj sistemi v.b. Ekipmanlar fiyata dahildir. | L9: =IF(OR(H9<>"",J9<>""),SUM(H9,J9),"")
C10: Pompalar ve Panoları NFPA bölüm 20'ye uygun olacaktır. | L10: =IF(OR(H10<>"",J10<>""),SUM(H10,J10),"")
C11: UL Listeli, FM onaylı olacaktır. | L11: =IF(OR(H11<>"",J11<>""),SUM(H11,J11),"")
C12: NFPA 20 ye uygunluğu a kredite olmuş bir kurumdan tetkik edilmiş olan evrakı verilecektir. | L12: =IF(OR(H12<>"",J12<>""),SUM(H12,J12),"")
C13: a)Ana yangın pompaları………….:1 Adet (Elektrikli) | L13: =IF(OR(H13<>"",J13<>""),SUM(H13,J13),"")
C14: Q : 140 m³/h; Hm = 9.5 bar | L14: =IF(OR(H14<>"",J14<>""),SUM(H14,J14),"")
C15: b)Ana yangın pompaları………….:1 Adet (Elektrik) | L15: =IF(OR(H15<>"",J15<>""),SUM(H15,J15),"")
C16: Q : 140 m³/h; Hm = 9.5 bar | L16: =IF(OR(H16<>"",J16<>""),SUM(H16,J16),"")
C17: c)Jokey yangın pompaları…………. : 1 Adet | L17: =IF(OR(H17<>"",J17<>""),SUM(H17,J17),"")
C18: Q :5.0 m³/h; Hm =10,0 bar | E18: 1 | F18: Grup | I18: 150000 | J18: =SUM(E18*I18) -> 150000 | K18: =SUM(G18+I18) -> 150000 | L18: =IF(OR(H18<>"",J18<>""),SUM(H18,J18),"") -> 150000
B19: =MAX(INDIRECT(CONCATENATE(ADDRESS(4,2,1,1),":",ADDRESS(ROW()-1,2,4,1))))+1 -> 2 | C19: TÜPLÜ TİP YANGIN DOLABI (TS-671/1'ye uygun) | J19: =SUM(E19*I19) -> 0 | K19: =SUM(G19+I19) -> 0 | L19: =IF(OR(H19<>"",J19<>""),SUM(H19,J19),"") -> 0
C20: Takriben 100x90x25 cm. iç ölçülerinde 1,5mm. DKP sacdan, kolayca | J20: =SUM(E20*I20) -> 0 | K20: =SUM(G20+I20) -> 0 | L20: =IF(OR(H20<>"",J20<>""),SUM(H20,J20),"") -> 0
C21: açılabilen iki kapağı dolap içinde 6 kg Tüp, hortumun kolayca açılıp, sarılabilen ma- | J21: =SUM(E21*I21) -> 0 | K21: =SUM(G21+I21) -> 0 | L21: =IF(OR(H21<>"",J21<>""),SUM(H21,J21),"") -> 0
C22: karası,30 mt. uzunluğunda 1" yarı sertkauçuk hortum, hortum hattına bağlı | J22: =SUM(E22*I22) -> 0 | K22: =SUM(G22+I22) -> 0 | L22: =IF(OR(H22<>"",J22<>""),SUM(H22,J22),"") -> 0
C23: 2" köşe tipi yangın vanası ve fıskiye,füz ve kesik olmak üzere 3 püskürtme pozisyonlu | E23: 24 | F23: Adet | I23: 4000 | J23: =SUM(E23*I23) -> 96000 | K23: =SUM(G23+I23) -> 4000 | L23: =IF(OR(H23<>"",J23<>""),SUM(H23,J23),"") -> 96000
B24: =MAX(INDIRECT(CONCATENATE(ADDRESS(4,2,1,1),":",ADDRESS(ROW()-1,2,4,1))))+1 -> 3 | C24: İTFAİYE SU ALMA AĞIZI (Tekli Tip) | J24: =SUM(E24*I24) -> 0 | K24: =SUM(G24+I24) -> 0 | L24: =IF(OR(H24<>"",J24<>""),SUM(H24,J24),"") -> 0
C25: Ø65 mm. çapında, Ø65/Ø50 mm.'ye hızlı rakor bağlantılı redüksiyon kaplini | J25: =SUM(E25*I25) -> 0 | K25: =SUM(G25+I25) -> 0 | L25: =IF(OR(H25<>"",J25<>""),SUM(H25,J25),"") -> 0
C26: sayesinde itfaiyenin Ø65 mm.ve Ø50 mm. Hortum kullanmasına imkan verecek | J26: =SUM(E26*I26) -> 0 | K26: =SUM(G26+I26) -> 0 | L26: =IF(OR(H26<>"",J26<>""),SUM(H26,J26),"") -> 0
C27: tipte olacaktır. Ø65 mm. köşe vanası fiyata dahildir. | E27: 8 | F27: Adet | I27: 4160 | J27: =SUM(E27*I27) -> 33280 | K27: =SUM(G27+I27) -> 4160 | L27: =IF(OR(H27<>"",J27<>""),SUM(H27,J27),"") -> 33280
B28: =MAX(INDIRECT(CONCATENATE(ADDRESS(4,2,1,1),":",ADDRESS(ROW()-1,2,4,1))))+1 -> 4 | C28: İTFAİYE BAĞLANTI AĞZI | J28: =SUM(E28*I28) -> 0 | K28: =SUM(G28+I28) -> 0 | L28: =IF(OR(H28<>"",J28<>""),SUM(H28,J28),"") -> 0
C29: UL,Fm onaylı. | J29: =SUM(E29*I29) -> 0 | K29: =SUM(G29+I29) -> 0 | L29: =IF(OR(H29<>"",J29<>""),SUM(H29,J29),"") -> 0
C30: Ø 65 x Ø 65 x Ø 100 mm çift ağızlı, isim plakalı ve damlatma ağızlı | E30: 1 | F30: Adet | I30: 4160 | J30: =SUM(E30*I30) -> 4160 | K30: =SUM(G30+I30) -> 4160 | L30: =IF(OR(H30<>"",J30<>""),SUM(H30,J30),"") -> 4160
B31: =MAX(INDIRECT(CONCATENATE(ADDRESS(4,2,1,1),":",ADDRESS(ROW()-1,2,4,1))))+1 -> 5 | C31: YANGIN HİDRANTI - DN100 | J31: =SUM(E31*I31) -> 0 | K31: =SUM(G31+I31) -> 0 | L31: =IF(OR(H31<>"",J31<>""),SUM(H31,J31),"") -> 0
C32: 2 x 2½"x4" - Açma Anahtarı ve hidtant alt destek parçası ve hidrant vanası dahil. | J32: =SUM(E32*I32) -> 0 | K32: =SUM(G32+I32) -> 0 | L32: =IF(OR(H32<>"",J32<>""),SUM(H32,J32),"") -> 0
C33: Otomatik drenaj vanalı tip olacaktır. | E33: 6 | F33: Adet | I33: 10000 | J33: =SUM(E33*I33) -> 60000 | K33: =SUM(G33+I33) -> 10000 | L33: =IF(OR(H33<>"",J33<>""),SUM(H33,J33),"") -> 60000
B34: =MAX(INDIRECT(CONCATENATE(ADDRESS(4,2,1,1),":",ADDRESS(ROW()-1,2,4,1))))+1 -> 6 | C34: SAHRA TİPİ DIŞ YANGIN DOLABI | J34: =SUM(E34*I34) -> 0 | K34: =SUM(G34+I34) -> 0 | L34: =IF(OR(H34<>"",J34<>""),SUM(H34,J34),"") -> 0
C35: Yangın dolabının tipi rengi ve modeli idareye danışılıp onay alındıktan sonra belirlenip alınacaktır. | E35: 6 | F35: Adet | I35: 4000 | J35: =SUM(E35*I35) -> 24000 | K35: =SUM(G35+I35) -> 4000 | L35: =IF(OR(H35<>"",J35<>""),SUM(H35,J35),"") -> 24000
B36: =MAX(INDIRECT(CONCATENATE(ADDRESS(4,2,1,1),":",ADDRESS(ROW()-1,2,4,1))))+1 -> 7 | C36: SİYAH ÇELİK BORULAR | J36: =SUM(E36*I36) -> 0 | K36: =SUM(G36+I36) -> 0 | L36: =IF(OR(H36<>"",J36<>""),SUM(H36,J36),"") -> 0
C37: DN 65( 2½") Dahil ve üst çaplardaki borular yivli bağlantı elamanı ile bağlanacaktır. | J37: =SUM(E37*I37) -> 0 | K37: =SUM(G37+I37) -> 0 | L37: =IF(OR(H37<>"",J37<>""),SUM(H37,J37),"") -> 0
C38: Diğer boru çaplarında dişli bağlantı kullanılacaktır. | J38: =SUM(E38*I38) -> 0 | K38: =SUM(G38+I38) -> 0 | L38: =IF(OR(H38<>"",J38<>""),SUM(H38,J38),"") -> 0
C39: Yangın Tesisatı için getirilen borular fabrikadan astar boyalı ve yivli olarak gelecektir. | J39: =SUM(E39*I39) -> 0 | K39: =SUM(G39+I39) -> 0 | L39: =IF(OR(H39<>"",J39<>""),SUM(H39,J39),"") -> 0
C40: 1" | E40: 460 | F40: mt. | I40: 650 | J40: =SUM(E40*I40) -> 299000 | K40: =SUM(G40+I40) -> 650 | L40: =IF(OR(H40<>"",J40<>""),SUM(H40,J40),"") -> 299000
C41: 1 ¼" | E41: 1580 | F41: mt. | I41: 700 | J41: =SUM(E41*I41) -> 1106000 | K41: =SUM(G41+I41) -> 700 | L41: =IF(OR(H41<>"",J41<>""),SUM(H41,J41),"") -> 1106000
...

Sheet VRV-VRF
B2: FIRMA-A FABRİKA Vrv-Vrf Tesisatı Keşif Özeti
B3: SIRA NO | C3: CİNSİ TANIMI | D3: MARKASI | E3: MİKTAR | F3: BİRİM | G3: MALZEME | I3: İŞÇİLİK | K3: TOPLAM
G4: BİRİM FİYAT | H4: TUTAR | I4: BİRİM FİYAT | J4: TUTAR | K4: BİRİM FİYAT | L4: TUTAR
B5: 1 | C5: VRF- VRV-VRS SİSTEM İÇ ÜNİTELER MONTAJ BEDELİ
B6: 1.1 | C6: VRF İÇ ÜNİTE (KOMPAKT DÖRT YÖNE ÜFLEMELİ) | L6: =IF(OR(H6<>"",J6<>""),SUM(H6,J6),"")
C7: Nominal Soğutma kapasitesi :2,2 Kw | L7: =IF(OR(H7<>"",J7<>""),SUM(H7,J7),"")
C8: NominaI Isıtma kapasitesi :2,5 Kw | E8: 2 | F8: Adet | L8: =IF(OR(H8<>"",J8<>""),SUM(H8,J8),"")
B9: 1.2 | C9: VRF İÇ ÜNİTE (KOMPAKT DÖRT YÖNE ÜFLEMELİ) | L9: =IF(OR(H9<>"",J9<>""),SUM(H9,J9),"")
C10: Nominal Soğutma kapasitesi :3,6 Kw | L10: =IF(OR(H10<>"",J10<>""),SUM(H10,J10),"")
C11: NominaI Isıtma kapasitesi :4,0 Kw | E11: 1 | F11: Adet | L11: =IF(OR(H11<>"",J11<>""),SUM(H11,J11),"")
B12: 1.3 | C12: VRF İÇ ÜNİTE (DÖRT YÖNE ÜFLEMELİ) | L12: =IF(OR(H12<>"",J12<>""),SUM(H12,J12),"")
C13: Nominal Soğutma kapasitesi :2,8 Kw | L13: =IF(OR(H13<>"",J13<>""),SUM(H13,J13),"")
C14: NominaI Isıtma kapasitesi :3,2 Kw | E14: 1 | F14: Adet | L14: =IF(OR(H14<>"",J14<>""),SUM(H14,J14),"")
B15: 1.4 | C15: VRF İÇ ÜNİTE (DÖRT YÖNE ÜFLEMELİ) | L15: =IF(OR(H15<>"",J15<>""),SUM(H15,J15),"")
C16: Nominal Soğutma kapasitesi :3,6 Kw | L16: =IF(OR(H16<>"",J16<>""),SUM(H16,J16),"")
C17: NominaI Isıtma kapasitesi :4,0 Kw | E17: 7 | F17: Adet | L17: =IF(OR(H17<>"",J17<>""),SUM(H17,J17),"")
B18: 1.5 | C18: VRF İÇ ÜNİTE (DÖRT YÖNE ÜFLEMELİ) | L18: =IF(OR(H18<>"",J18<>""),SUM(H18,J18),"")
C19: Nominal Soğutma kapasitesi :4,5 Kw | L19: =IF(OR(H19<>"",J19<>""),SUM(H19,J19),"")
C20: NominaI Isıtma kapasitesi :5,0 Kw | E20: 3 | F20: Adet | L20: =IF(OR(H20<>"",J20<>""),SUM(H20,J20),"")
B21: 1.6 | C21: VRF İÇ ÜNİTE (DÖRT YÖNE ÜFLEMELİ) | L21: =IF(OR(H21<>"",J21<>""),SUM(H21,J21),"")
C22: Nominal Soğutma kapasitesi :7,1 Kw | L22: =IF(OR(H22<>"",J22<>""),SUM(H22,J22),"")
C23: NominaI Isıtma kapasitesi :8,0 Kw | E23: 3 | F23: Adet | L23: =IF(OR(H23<>"",J23<>""),SUM(H23,J23),"")
B24: 1.7 | C24: VRF İÇ ÜNİTE (DÖRT YÖNE ÜFLEMELİ) | L24: =IF(OR(H24<>"",J24<>""),SUM(H24,J24),"")
C25: Nominal Soğutma kapasitesi :11,2 Kw | L25: =IF(OR(H25<>"",J25<>""),SUM(H25,J25),"")
C26: NominaI Isıtma kapasitesi :12,5 Kw | E26: 1 | F26: Adet | L26: =IF(OR(H26<>"",J26<>""),SUM(H26,J26),"")
B27: 2 | C27: DIŞ ÜNİTELER VRF- VRV SİSTEM | L27: =IF(OR(H27<>"",J27<>""),SUM(H27,J27),"")
B28: 2.1 | C28: DIŞ ÜNİTE – HAVA SOĞUTMALI VRV-VRF ( HEAT PUMP ) MONTAJ BEDELİ | L28: =IF(OR(H28<>"",J28<>""),SUM(H28,J28),"")
C29: Nominal Soğutma kapasitesi :28,0 Kw | L29: =IF(OR(H29<>"",J29<>""),SUM(H29,J29),"")
C30: NominaI Isıtma kapasitesi :31,5 Kw | E30: 1 | F30: Adet | L30: =IF(OR(H30<>"",J30<>""),SUM(H30,J30),"")
B31: 2.2 | C31: DIŞ ÜNİTE – HAVA SOĞUTMALI VRV-VRF ( HEAT PUMP ) MONTAJ BEDELİ | L31: =IF(OR(H31<>"",J31<>""),SUM(H31,J31),"")
C32: Nominal Soğutma kapasitesi :33,5 Kw | L32: =IF(OR(H32<>"",J32<>""),SUM(H32,J32),"")
C33: NominaI Isıtma kapasitesi :37,5 Kw | E33: 1 | F33: Adet | L33: =IF(OR(H33<>"",J33<>""),SUM(H33,J33),"")
B34: =MAX(INDIRECT(CONCATENATE(ADDRESS(4,2,1,1),":",ADDRESS(ROW()-1,2,4,1))))+1 -> 3.2 | C34: BAĞLANTI ELEMANI (JOİNT) MONTAJ BEDELİ | L34: =IF(OR(H34<>"",J34<>""),SUM(H34,J34),"")
C35: 20 kW Altı Kapasiteler (2 Çıkışlı) | E35: 10 | F35: Adet | L35: =IF(OR(H35<>"",J35<>""),SUM(H35,J35),"")
C36: 20-29 kW Arası Kapasiteler (2 Çıkışlı) | E36: 5 | F36: Adet | L36: =IF(OR(H36<>"",J36<>""),SUM(H36,J36),"")
C37: 29-64 kW Arası Kapasiteler (2 Çıkışlı) | E37: 1 | F37: Adet | L37: =IF(OR(H37<>"",J37<>""),SUM(H37,J37),"")
B38: =MAX(INDIRECT(CONCATENATE(ADDRESS(4,2,1,1),":",ADDRESS(ROW()-1,2,4,1))))+1 -> 4.2 | C38: KABLOLU UZAKTAN KUMANDA MONTAJ BEDELİ | E38: =E8+E11+E14+E17+E20+E23+E26 -> 18 | F38: Adet | L38: =IF(OR(H38<>"",J38<>""),SUM(H38,J38),"")
B39: =MAX(INDIRECT(CONCATENATE(ADDRESS(4,2,1,1),":",ADDRESS(ROW()-1,2,4,1))))+1 -> 5.2 | C39: MERKEZİ KUMANDA MONTAJ BEDELİ | L39: =IF(OR(H39<>"",J39<>""),SUM(H39,J39),"")
C40: (64 iç üniteyi kontrol edebilen kumanda) | E40: 2 | F40: Adet | L40: =IF(OR(H40<>"",J40<>""),SUM(H40,J40),"")
B41: =MAX(INDIRECT(CONCATENATE(ADDRESS(4,2,1,1),":",ADDRESS(ROW()-1,2,4,1))))+1 -> 6.2 | C41: BAKIR BORULAMA ve İZOLASYONU | L41: =IF(OR(H41<>"",J41<>""),SUM(H41,J41),"")
...

Sheet SIFONIK YAĞMUR
B2: FIRMA-A FABRİKA SİFONİK YAĞMUR TESİSATI KEŞİF ÖZETİ
B3: SIRA NO | C3: CİNSİ TANIMI | D3: MARKASI | E3: MİKTAR | F3: BİRİM | G3: MALZEME | I3: İŞÇİLİK | K3: TOPLAM
G4: BİRİM FİYAT | H4: TUTAR | I4: BİRİM FİYAT | J4: TUTAR | K4: BİRİM FİYAT | L4: TUTAR
B5: =MAX(INDIRECT(CONCATENATE(ADDRESS(4,2,1,1),":",ADDRESS(ROW()-1,2,4,1))))+1 -> 1 | C5: SİFONİK YAĞMUR SÜZGECİ | L5: =IF(OR(H5<>"",J5<>""),SUM(H5,J5),"")
C6: 12 l/s paslanmaz Flanşlı-Contalı-Elektrikli ısıtıcılı | E6: 16 | F6: Adet | L6: =IF(OR(H6<>"",J6<>""),SUM(H6,J6),"")
C7: 25 l/s paslanmaz Flanşlı-Contalı Elektrikli ısıtıcılı | E7: 8 | F7: Adet | L7: =IF(OR(H7<>"",J7<>""),SUM(H7,J7),"")
B8: =MAX(INDIRECT(CONCATENATE(ADDRESS(4,2,1,1),":",ADDRESS(ROW()-1,2,4,1))))+1 -> 2 | C8: HDPE BORU | L8: =IF(OR(H8<>"",J8<>""),SUM(H8,J8),"")
C9: 50 mm | E9: 6 | F9: mt. | L9: =IF(OR(H9<>"",J9<>""),SUM(H9,J9),"")
C10: 56 mm | E10: 6 | F10: mt. | L10: =IF(OR(H10<>"",J10<>""),SUM(H10,J10),"")
C11: 63 mm | E11: 12 | F11: mt. | L11: =IF(OR(H11<>"",J11<>""),SUM(H11,J11),"")
C12: 75 mm | E12: 90 | F12: mt. | L12: =IF(OR(H12<>"",J12<>""),SUM(H12,J12),"")
C13: 90 mm | E13: 48 | F13: mt. | L13: =IF(OR(H13<>"",J13<>""),SUM(H13,J13),"")
C14: 110 mm | E14: 114 | F14: mt. | L14: =IF(OR(H14<>"",J14<>""),SUM(H14,J14),"")
C15: 125 mm | E15: 138 | F15: mt. | L15: =IF(OR(H15<>"",J15<>""),SUM(H15,J15),"")
C16: 160 mm | E16: 252 | F16: mt. | L16: =IF(OR(H16<>"",J16<>""),SUM(H16,J16),"")
C17: 200 mm | E17: 138 | F17: mt. | L17: =IF(OR(H17<>"",J17<>""),SUM(H17,J17),"")
B18: =MAX(INDIRECT(CONCATENATE(ADDRESS(4,2,1,1),":",ADDRESS(ROW()-1,2,4,1))))+1 -> 3 | C18: BORULARIN KAUÇUK ESASLI PREFABRİK MALZEME | L18: =IF(OR(H18<>"",J18<>""),SUM(H18,J18),"")
C19: İLE İZOLASYONUN YAPILMASI
C20: Tüm borular alimünyum folyo kaplanacaktır.
C21: 50 mm - 13 mm | F21: mt. | L21: =IF(OR(H21<>"",J21<>""),SUM(H21,J21),"")
C22: 56 mm - 13 mm | E22: 6 | F22: mt. | L22: =IF(OR(H22<>"",J22<>""),SUM(H22,J22),"")
C23: 63 mm - 13 mm | E23: 12 | F23: mt. | L23: =IF(OR(H23<>"",J23<>""),SUM(H23,J23),"")
C24: 75 mm - 13 mm | E24: 90 | F24: mt. | L24: =IF(OR(H24<>"",J24<>""),SUM(H24,J24),"")
C25: 90 mm - 13 mm | E25: 48 | F25: mt. | L25: =IF(OR(H25<>"",J25<>""),SUM(H25,J25),"")
C26: 110 mm - 13 mm | E26: 114 | F26: mt. | L26: =IF(OR(H26<>"",J26<>""),SUM(H26,J26),"")
C27: 125 mm - 13 mm | E27: 138 | F27: mt. | L27: =IF(OR(H27<>"",J27<>""),SUM(H27,J27),"")
C28: 160 mm - 13 mm | E28: 252 | F28: mt. | L28: =IF(OR(H28<>"",J28<>""),SUM(H28,J28),"")
C29: 200 mm - 13 mm | E29: 138 | F29: mt. | L29: =IF(OR(H29<>"",J29<>""),SUM(H29,J29),"")
B30: =MAX(INDIRECT(CONCATENATE(ADDRESS(4,2,1,1),":",ADDRESS(ROW()-1,2,4,1))))+1 -> 4 | C30: GOFRAJLI ALUMİNYUM SAC İLE KAPLANMASI | L30: =IF(OR(H30<>"",J30<>""),SUM(H30,J30),"")
C31: Özel parçalar (dirsek,tee,redüksiyün v.s.) net ölçüsünün 1,35 katı olarak ölçülülendirilip, fiyatlandırılacaktır. | L31: =IF(OR(H31<>"",J31<>""),SUM(H31,J31),"")
C32: s : 0,8 mm. | E32: 500 | F32: m² | L32: =IF(OR(H32<>"",J32<>""),SUM(H32,J32),"")
B33: =MAX(INDIRECT(CONCATENATE(ADDRESS(4,2,1,1),":",ADDRESS(ROW()-1,2,4,1))))+1 -> 5 | C33: HDPE BORU MONTAJ MALZEME BEDELİ | F33: % | L33: =IF(OR(H33<>"",J33<>""),SUM(H33,J33),"")
C34: Dirsek ,Çatal Rediksüyon, flanşlar, Vidalar ve konsol .Askı ... vb montaj elamanları | L34: =IF(OR(H34<>"",J34<>""),SUM(H34,J34),"")
C35: Boru montaj malzeme bedeli oranları, Yüklenici tarafından tespit edilip, teklif edilecektir. | L35: =IF(OR(H35<>"",J35<>""),SUM(H35,J35),"")
B36: =MAX(INDIRECT(CONCATENATE(ADDRESS(4,2,1,1),":",ADDRESS(ROW()-1,2,4,1))))+1 -> 6 | C36: BORU SABİTLEME MALZELERİ | F36: % | L36: =IF(OR(H36<>"",J36<>""),SUM(H36,J36),"")
C37: Rrofil,levha,vida,kelepce,ayarlama aparatları…. Vb | L37: =IF(OR(H37<>"",J37<>""),SUM(H37,J37),"")
C38: Malzeme bedeli oranları, Yüklenici tarafından tespit edilip, teklif edilecektir. | L38: =IF(OR(H38<>"",J38<>""),SUM(H38,J38),"")
B39: =MAX(INDIRECT(CONCATENATE(ADDRESS(4,2,1,1),":",ADDRESS(ROW()-1,2,4,1))))+1 -> 7 | C39: SİSMİK SINIRLAYICI | F39: % | L39: =IF(OR(H39<>"",J39<>""),SUM(H39,J39),"")
C40: Profil,halat… vb | L40: =IF(OR(H40<>"",J40<>""),SUM(H40,J40),"")
C41: Malzeme bedeli oranları, Yüklenici tarafından tespit edilip, teklif edilecektir. | L41: =IF(OR(H41<>"",J41<>""),SUM(H41,J41),"")
...
